[2025-08-31T04:30:50.654+0000] {taskinstance.py:1157} INFO - Dependencies all met for dep_context=non-requeueable deps ti=<TaskInstance: sparking_flow.python_job scheduled__2025-08-30T12:00:00+00:00 [queued]>
[2025-08-31T04:30:50.917+0000] {taskinstance.py:1157} INFO - Dependencies all met for dep_context=requeueable deps ti=<TaskInstance: sparking_flow.python_job scheduled__2025-08-30T12:00:00+00:00 [queued]>
[2025-08-31T04:30:50.921+0000] {taskinstance.py:1359} INFO - Starting attempt 1 of 1
[2025-08-31T04:30:50.982+0000] {taskinstance.py:1380} INFO - Executing <Task(SparkSubmitOperator): python_job> on 2025-08-30 12:00:00+00:00
[2025-08-31T04:30:51.021+0000] {standard_task_runner.py:57} INFO - Started process 487 to run task
[2025-08-31T04:30:51.059+0000] {standard_task_runner.py:84} INFO - Running: ['***', 'tasks', 'run', 'sparking_flow', 'python_job', 'scheduled__2025-08-30T12:00:00+00:00', '--job-id', '84', '--raw', '--subdir', 'DAGS_FOLDER/spark_***.py', '--cfg-path', '/tmp/tmps3g2gcv_']
[2025-08-31T04:30:51.079+0000] {standard_task_runner.py:85} INFO - Job 84: Subtask python_job
[2025-08-31T04:30:51.542+0000] {task_command.py:415} INFO - Running <TaskInstance: sparking_flow.python_job scheduled__2025-08-30T12:00:00+00:00 [running]> on host 81b7fe425a18
[2025-08-31T04:30:52.025+0000] {taskinstance.py:1660} INFO - Exporting env vars: AIRFLOW_CTX_DAG_OWNER='Kudzaishe Manyanya' AIRFLOW_CTX_DAG_ID='sparking_flow' AIRFLOW_CTX_TASK_ID='python_job' AIRFLOW_CTX_EXECUTION_DATE='2025-08-30T12:00:00+00:00' AIRFLOW_CTX_TRY_NUMBER='1' AIRFLOW_CTX_DAG_RUN_ID='scheduled__2025-08-30T12:00:00+00:00'
[2025-08-31T04:30:52.095+0000] {base.py:73} INFO - Using connection ID 'spark-conn' for task execution.
[2025-08-31T04:30:52.106+0000] {spark_submit.py:403} INFO - Spark-Submit cmd: spark-submit --master spark://spark-master:7077 --jars /opt/spark/external-jars/apache-spark-sql-connector.jar --name arrow-spark --deploy-mode client jobs/python/wordcountjob.py
[2025-08-31T04:31:10.950+0000] {spark_submit.py:579} INFO - WARNING: Using incubator modules: jdk.incubator.vector
[2025-08-31T04:31:52.172+0000] {spark_submit.py:579} INFO - 25/08/31 04:31:52 WARN NativeCodeLoader: Unable to load native-hadoop library for your platform... using builtin-java classes where applicable
[2025-08-31T04:32:28.937+0000] {job.py:219} ERROR - Job heartbeat got an exception
Traceback (most recent call last):
  File "/home/airflow/.local/lib/python3.10/site-packages/sqlalchemy/engine/base.py", line 3371, in _wrap_pool_connect
    return fn()
  File "/home/airflow/.local/lib/python3.10/site-packages/sqlalchemy/pool/base.py", line 327, in connect
    return _ConnectionFairy._checkout(self)
  File "/home/airflow/.local/lib/python3.10/site-packages/sqlalchemy/pool/base.py", line 894, in _checkout
    fairy = _ConnectionRecord.checkout(pool)
  File "/home/airflow/.local/lib/python3.10/site-packages/sqlalchemy/pool/base.py", line 493, in checkout
    rec = pool._do_get()
  File "/home/airflow/.local/lib/python3.10/site-packages/sqlalchemy/pool/impl.py", line 256, in _do_get
    return self._create_connection()
  File "/home/airflow/.local/lib/python3.10/site-packages/sqlalchemy/pool/base.py", line 273, in _create_connection
    return _ConnectionRecord(self)
  File "/home/airflow/.local/lib/python3.10/site-packages/sqlalchemy/pool/base.py", line 388, in __init__
    self.__connect()
  File "/home/airflow/.local/lib/python3.10/site-packages/sqlalchemy/pool/base.py", line 690, in __connect
    with util.safe_reraise():
  File "/home/airflow/.local/lib/python3.10/site-packages/sqlalchemy/util/langhelpers.py", line 70, in __exit__
    compat.raise_(
  File "/home/airflow/.local/lib/python3.10/site-packages/sqlalchemy/util/compat.py", line 211, in raise_
    raise exception
  File "/home/airflow/.local/lib/python3.10/site-packages/sqlalchemy/pool/base.py", line 686, in __connect
    self.dbapi_connection = connection = pool._invoke_creator(self)
  File "/home/airflow/.local/lib/python3.10/site-packages/sqlalchemy/engine/create.py", line 574, in connect
    return dialect.connect(*cargs, **cparams)
  File "/home/airflow/.local/lib/python3.10/site-packages/sqlalchemy/engine/default.py", line 598, in connect
    return self.dbapi.connect(*cargs, **cparams)
  File "/home/airflow/.local/lib/python3.10/site-packages/psycopg2/__init__.py", line 122, in connect
    conn = _connect(dsn, connection_factory=connection_factory, **kwasync)
psycopg2.OperationalError: could not translate host name "postgres" to address: Temporary failure in name resolution


The above exception was the direct cause of the following exception:

Traceback (most recent call last):
  File "/home/airflow/.local/lib/python3.10/site-packages/airflow/jobs/job.py", line 190, in heartbeat
    session.merge(self)
  File "/home/airflow/.local/lib/python3.10/site-packages/sqlalchemy/orm/session.py", line 3056, in merge
    return self._merge(
  File "/home/airflow/.local/lib/python3.10/site-packages/sqlalchemy/orm/session.py", line 3136, in _merge
    merged = self.get(
  File "/home/airflow/.local/lib/python3.10/site-packages/sqlalchemy/orm/session.py", line 2853, in get
    return self._get_impl(
  File "/home/airflow/.local/lib/python3.10/site-packages/sqlalchemy/orm/session.py", line 2975, in _get_impl
    return db_load_fn(
  File "/home/airflow/.local/lib/python3.10/site-packages/sqlalchemy/orm/loading.py", line 530, in load_on_pk_identity
    session.execute(
  File "/home/airflow/.local/lib/python3.10/site-packages/sqlalchemy/orm/session.py", line 1716, in execute
    conn = self._connection_for_bind(bind)
  File "/home/airflow/.local/lib/python3.10/site-packages/sqlalchemy/orm/session.py", line 1555, in _connection_for_bind
    return self._transaction._connection_for_bind(
  File "/home/airflow/.local/lib/python3.10/site-packages/sqlalchemy/orm/session.py", line 750, in _connection_for_bind
    conn = bind.connect()
  File "/home/airflow/.local/lib/python3.10/site-packages/sqlalchemy/future/engine.py", line 406, in connect
    return super(Engine, self).connect()
  File "/home/airflow/.local/lib/python3.10/site-packages/sqlalchemy/engine/base.py", line 3325, in connect
    return self._connection_cls(self, close_with_result=close_with_result)
  File "/home/airflow/.local/lib/python3.10/site-packages/sqlalchemy/engine/base.py", line 96, in __init__
    else engine.raw_connection()
  File "/home/airflow/.local/lib/python3.10/site-packages/sqlalchemy/engine/base.py", line 3404, in raw_connection
    return self._wrap_pool_connect(self.pool.connect, _connection)
  File "/home/airflow/.local/lib/python3.10/site-packages/sqlalchemy/engine/base.py", line 3374, in _wrap_pool_connect
    Connection._handle_dbapi_exception_noconnection(
  File "/home/airflow/.local/lib/python3.10/site-packages/sqlalchemy/engine/base.py", line 2208, in _handle_dbapi_exception_noconnection
    util.raise_(
  File "/home/airflow/.local/lib/python3.10/site-packages/sqlalchemy/util/compat.py", line 211, in raise_
    raise exception
  File "/home/airflow/.local/lib/python3.10/site-packages/sqlalchemy/engine/base.py", line 3371, in _wrap_pool_connect
    return fn()
  File "/home/airflow/.local/lib/python3.10/site-packages/sqlalchemy/pool/base.py", line 327, in connect
    return _ConnectionFairy._checkout(self)
  File "/home/airflow/.local/lib/python3.10/site-packages/sqlalchemy/pool/base.py", line 894, in _checkout
    fairy = _ConnectionRecord.checkout(pool)
  File "/home/airflow/.local/lib/python3.10/site-packages/sqlalchemy/pool/base.py", line 493, in checkout
    rec = pool._do_get()
  File "/home/airflow/.local/lib/python3.10/site-packages/sqlalchemy/pool/impl.py", line 256, in _do_get
    return self._create_connection()
  File "/home/airflow/.local/lib/python3.10/site-packages/sqlalchemy/pool/base.py", line 273, in _create_connection
    return _ConnectionRecord(self)
  File "/home/airflow/.local/lib/python3.10/site-packages/sqlalchemy/pool/base.py", line 388, in __init__
    self.__connect()
  File "/home/airflow/.local/lib/python3.10/site-packages/sqlalchemy/pool/base.py", line 690, in __connect
    with util.safe_reraise():
  File "/home/airflow/.local/lib/python3.10/site-packages/sqlalchemy/util/langhelpers.py", line 70, in __exit__
    compat.raise_(
  File "/home/airflow/.local/lib/python3.10/site-packages/sqlalchemy/util/compat.py", line 211, in raise_
    raise exception
  File "/home/airflow/.local/lib/python3.10/site-packages/sqlalchemy/pool/base.py", line 686, in __connect
    self.dbapi_connection = connection = pool._invoke_creator(self)
  File "/home/airflow/.local/lib/python3.10/site-packages/sqlalchemy/engine/create.py", line 574, in connect
    return dialect.connect(*cargs, **cparams)
  File "/home/airflow/.local/lib/python3.10/site-packages/sqlalchemy/engine/default.py", line 598, in connect
    return self.dbapi.connect(*cargs, **cparams)
  File "/home/airflow/.local/lib/python3.10/site-packages/psycopg2/__init__.py", line 122, in connect
    conn = _connect(dsn, connection_factory=connection_factory, **kwasync)
sqlalchemy.exc.OperationalError: (psycopg2.OperationalError) could not translate host name "postgres" to address: Temporary failure in name resolution

(Background on this error at: https://sqlalche.me/e/14/e3q8)
[2025-08-31T04:33:09.738+0000] {spark_submit.py:579} INFO - Using Spark's default log4j profile: org/apache/spark/log4j2-defaults.properties
[2025-08-31T04:33:10.056+0000] {spark_submit.py:579} INFO - 25/08/31 04:33:10 INFO SparkContext: Running Spark version 4.0.0
[2025-08-31T04:33:10.075+0000] {spark_submit.py:579} INFO - 25/08/31 04:33:10 INFO SparkContext: OS info Linux, 6.6.87.2-microsoft-standard-WSL2, amd64
[2025-08-31T04:33:10.084+0000] {spark_submit.py:579} INFO - 25/08/31 04:33:10 INFO SparkContext: Java version 17.0.15
[2025-08-31T04:33:11.138+0000] {spark_submit.py:579} INFO - 25/08/31 04:33:11 INFO ResourceUtils: ==============================================================
[2025-08-31T04:33:11.181+0000] {spark_submit.py:579} INFO - 25/08/31 04:33:11 INFO ResourceUtils: No custom resources configured for spark.driver.
[2025-08-31T04:33:11.194+0000] {spark_submit.py:579} INFO - 25/08/31 04:33:11 INFO ResourceUtils: ==============================================================
[2025-08-31T04:33:11.196+0000] {spark_submit.py:579} INFO - 25/08/31 04:33:11 INFO SparkContext: Submitted application: PythonWordCount
[2025-08-31T04:33:11.971+0000] {spark_submit.py:579} INFO - 25/08/31 04:33:11 INFO ResourceProfile: Default ResourceProfile created, executor resources: Map(memory -> name: memory, amount: 1024, script: , vendor: , offHeap -> name: offHeap, amount: 0, script: , vendor: ), task resources: Map(cpus -> name: cpus, amount: 1.0)
[2025-08-31T04:33:12.060+0000] {spark_submit.py:579} INFO - 25/08/31 04:33:12 INFO ResourceProfile: Limiting resource is cpu
[2025-08-31T04:33:12.081+0000] {spark_submit.py:579} INFO - 25/08/31 04:33:12 INFO ResourceProfileManager: Added ResourceProfile id: 0
[2025-08-31T04:33:21.315+0000] {spark_submit.py:579} INFO - 25/08/31 04:33:21 INFO SecurityManager: Changing view acls to: ***
[2025-08-31T04:33:21.503+0000] {spark_submit.py:579} INFO - 25/08/31 04:33:21 INFO SecurityManager: Changing modify acls to: ***
[2025-08-31T04:33:21.507+0000] {spark_submit.py:579} INFO - 25/08/31 04:33:21 INFO SecurityManager: Changing view acls groups to: ***
[2025-08-31T04:33:21.512+0000] {spark_submit.py:579} INFO - 25/08/31 04:33:21 INFO SecurityManager: Changing modify acls groups to: ***
[2025-08-31T04:33:21.711+0000] {spark_submit.py:579} INFO - 25/08/31 04:33:21 INFO SecurityManager: SecurityManager: authentication disabled; ui acls disabled; users with view permissions: *** groups with view permissions: EMPTY; users with modify permissions: ***; groups with modify permissions: EMPTY; RPC SSL disabled
[2025-08-31T04:33:32.703+0000] {spark_submit.py:579} INFO - 25/08/31 04:33:32 INFO Utils: Successfully started service 'sparkDriver' on port 43369.
[2025-08-31T04:33:33.103+0000] {spark_submit.py:579} INFO - 25/08/31 04:33:33 INFO SparkEnv: Registering MapOutputTracker
[2025-08-31T04:33:33.292+0000] {spark_submit.py:579} INFO - 25/08/31 04:33:33 INFO SparkEnv: Registering BlockManagerMaster
[2025-08-31T04:33:33.405+0000] {spark_submit.py:579} INFO - 25/08/31 04:33:33 INFO BlockManagerMasterEndpoint: Using org.apache.spark.storage.DefaultTopologyMapper for getting topology information
[2025-08-31T04:33:33.409+0000] {spark_submit.py:579} INFO - 25/08/31 04:33:33 INFO BlockManagerMasterEndpoint: BlockManagerMasterEndpoint up
[2025-08-31T04:33:33.441+0000] {spark_submit.py:579} INFO - 25/08/31 04:33:33 INFO SparkEnv: Registering BlockManagerMasterHeartbeat
[2025-08-31T04:33:34.081+0000] {spark_submit.py:579} INFO - 25/08/31 04:33:34 INFO DiskBlockManager: Created local directory at /tmp/blockmgr-aa90ddbb-5019-47a2-84d0-49701f94e2ce
[2025-08-31T04:33:35.261+0000] {spark_submit.py:579} INFO - 25/08/31 04:33:35 INFO SparkEnv: Registering OutputCommitCoordinator
[2025-08-31T04:33:39.086+0000] {spark_submit.py:579} INFO - 25/08/31 04:33:38 INFO JettyUtils: Start Jetty 0.0.0.0:4040 for SparkUI
[2025-08-31T04:33:41.643+0000] {spark_submit.py:579} INFO - 25/08/31 04:33:41 WARN Utils: Service 'SparkUI' could not bind on port 4040. Attempting port 4041.
[2025-08-31T04:33:41.712+0000] {spark_submit.py:579} INFO - 25/08/31 04:33:41 WARN Utils: Service 'SparkUI' could not bind on port 4041. Attempting port 4042.
[2025-08-31T04:33:41.716+0000] {spark_submit.py:579} INFO - 25/08/31 04:33:41 WARN Utils: Service 'SparkUI' could not bind on port 4042. Attempting port 4043.
[2025-08-31T04:33:41.718+0000] {spark_submit.py:579} INFO - 25/08/31 04:33:41 WARN Utils: Service 'SparkUI' could not bind on port 4043. Attempting port 4044.
[2025-08-31T04:33:41.735+0000] {spark_submit.py:579} INFO - 25/08/31 04:33:41 WARN Utils: Service 'SparkUI' could not bind on port 4044. Attempting port 4045.
[2025-08-31T04:33:41.744+0000] {spark_submit.py:579} INFO - 25/08/31 04:33:41 WARN Utils: Service 'SparkUI' could not bind on port 4045. Attempting port 4046.
[2025-08-31T04:33:43.351+0000] {spark_submit.py:579} INFO - 25/08/31 04:33:43 INFO Utils: Successfully started service 'SparkUI' on port 4046.
[2025-08-31T04:33:49.900+0000] {spark_submit.py:579} INFO - 25/08/31 04:33:49 INFO SparkContext: Added JAR file:///opt/spark/external-jars/apache-spark-sql-connector.jar at spark://81b7fe425a18:43369/jars/apache-spark-sql-connector.jar with timestamp 1756614786216
[2025-08-31T04:33:50.884+0000] {spark_submit.py:579} INFO - 25/08/31 04:33:50 INFO SecurityManager: Changing view acls to: ***
[2025-08-31T04:33:50.913+0000] {spark_submit.py:579} INFO - 25/08/31 04:33:50 INFO SecurityManager: Changing modify acls to: ***
[2025-08-31T04:33:50.914+0000] {spark_submit.py:579} INFO - 25/08/31 04:33:50 INFO SecurityManager: Changing view acls groups to: ***
[2025-08-31T04:33:50.939+0000] {spark_submit.py:579} INFO - 25/08/31 04:33:50 INFO SecurityManager: Changing modify acls groups to: ***
[2025-08-31T04:33:50.941+0000] {spark_submit.py:579} INFO - 25/08/31 04:33:50 INFO SecurityManager: SecurityManager: authentication disabled; ui acls disabled; users with view permissions: *** groups with view permissions: EMPTY; users with modify permissions: ***; groups with modify permissions: EMPTY; RPC SSL disabled
[2025-08-31T04:33:59.748+0000] {spark_submit.py:579} INFO - 25/08/31 04:33:59 INFO StandaloneAppClient$ClientEndpoint: Connecting to master spark://spark-master:7077...
[2025-08-31T04:34:03.848+0000] {spark_submit.py:579} INFO - 25/08/31 04:34:03 INFO TransportClientFactory: Successfully created connection to spark-master/172.18.0.2:7077 after 2120 ms (0 ms spent in bootstraps)
[2025-08-31T04:34:08.304+0000] {spark_submit.py:579} INFO - 25/08/31 04:34:08 INFO StandaloneSchedulerBackend: Connected to Spark cluster with app ID app-20250831043408-0010
[2025-08-31T04:34:08.520+0000] {spark_submit.py:579} INFO - 25/08/31 04:34:08 INFO Utils: Successfully started service 'org.apache.spark.network.netty.NettyBlockTransferService' on port 38431.
[2025-08-31T04:34:08.527+0000] {spark_submit.py:579} INFO - 25/08/31 04:34:08 INFO NettyBlockTransferService: Server created on 81b7fe425a18:38431
[2025-08-31T04:34:08.553+0000] {spark_submit.py:579} INFO - 25/08/31 04:34:08 INFO BlockManager: Using org.apache.spark.storage.RandomBlockReplicationPolicy for block replication policy
[2025-08-31T04:34:08.889+0000] {spark_submit.py:579} INFO - 25/08/31 04:34:08 INFO BlockManagerMaster: Registering BlockManager BlockManagerId(driver, 81b7fe425a18, 38431, None)
[2025-08-31T04:34:09.039+0000] {spark_submit.py:579} INFO - 25/08/31 04:34:09 INFO BlockManagerMasterEndpoint: Registering block manager 81b7fe425a18:38431 with 434.4 MiB RAM, BlockManagerId(driver, 81b7fe425a18, 38431, None)
[2025-08-31T04:34:09.054+0000] {spark_submit.py:579} INFO - 25/08/31 04:34:09 INFO BlockManagerMaster: Registered BlockManager BlockManagerId(driver, 81b7fe425a18, 38431, None)
[2025-08-31T04:34:09.080+0000] {spark_submit.py:579} INFO - 25/08/31 04:34:09 INFO BlockManager: Initialized BlockManager: BlockManagerId(driver, 81b7fe425a18, 38431, None)
[2025-08-31T04:34:31.736+0000] {job.py:219} ERROR - Job heartbeat got an exception
Traceback (most recent call last):
  File "/home/airflow/.local/lib/python3.10/site-packages/sqlalchemy/engine/base.py", line 3371, in _wrap_pool_connect
    return fn()
  File "/home/airflow/.local/lib/python3.10/site-packages/sqlalchemy/pool/base.py", line 327, in connect
    return _ConnectionFairy._checkout(self)
  File "/home/airflow/.local/lib/python3.10/site-packages/sqlalchemy/pool/base.py", line 894, in _checkout
    fairy = _ConnectionRecord.checkout(pool)
  File "/home/airflow/.local/lib/python3.10/site-packages/sqlalchemy/pool/base.py", line 493, in checkout
    rec = pool._do_get()
  File "/home/airflow/.local/lib/python3.10/site-packages/sqlalchemy/pool/impl.py", line 256, in _do_get
    return self._create_connection()
  File "/home/airflow/.local/lib/python3.10/site-packages/sqlalchemy/pool/base.py", line 273, in _create_connection
    return _ConnectionRecord(self)
  File "/home/airflow/.local/lib/python3.10/site-packages/sqlalchemy/pool/base.py", line 388, in __init__
    self.__connect()
  File "/home/airflow/.local/lib/python3.10/site-packages/sqlalchemy/pool/base.py", line 690, in __connect
    with util.safe_reraise():
  File "/home/airflow/.local/lib/python3.10/site-packages/sqlalchemy/util/langhelpers.py", line 70, in __exit__
    compat.raise_(
  File "/home/airflow/.local/lib/python3.10/site-packages/sqlalchemy/util/compat.py", line 211, in raise_
    raise exception
  File "/home/airflow/.local/lib/python3.10/site-packages/sqlalchemy/pool/base.py", line 686, in __connect
    self.dbapi_connection = connection = pool._invoke_creator(self)
  File "/home/airflow/.local/lib/python3.10/site-packages/sqlalchemy/engine/create.py", line 574, in connect
    return dialect.connect(*cargs, **cparams)
  File "/home/airflow/.local/lib/python3.10/site-packages/sqlalchemy/engine/default.py", line 598, in connect
    return self.dbapi.connect(*cargs, **cparams)
  File "/home/airflow/.local/lib/python3.10/site-packages/psycopg2/__init__.py", line 122, in connect
    conn = _connect(dsn, connection_factory=connection_factory, **kwasync)
psycopg2.OperationalError: could not translate host name "postgres" to address: Temporary failure in name resolution


The above exception was the direct cause of the following exception:

Traceback (most recent call last):
  File "/home/airflow/.local/lib/python3.10/site-packages/airflow/jobs/job.py", line 190, in heartbeat
    session.merge(self)
  File "/home/airflow/.local/lib/python3.10/site-packages/sqlalchemy/orm/session.py", line 3056, in merge
    return self._merge(
  File "/home/airflow/.local/lib/python3.10/site-packages/sqlalchemy/orm/session.py", line 3136, in _merge
    merged = self.get(
  File "/home/airflow/.local/lib/python3.10/site-packages/sqlalchemy/orm/session.py", line 2853, in get
    return self._get_impl(
  File "/home/airflow/.local/lib/python3.10/site-packages/sqlalchemy/orm/session.py", line 2975, in _get_impl
    return db_load_fn(
  File "/home/airflow/.local/lib/python3.10/site-packages/sqlalchemy/orm/loading.py", line 530, in load_on_pk_identity
    session.execute(
  File "/home/airflow/.local/lib/python3.10/site-packages/sqlalchemy/orm/session.py", line 1716, in execute
    conn = self._connection_for_bind(bind)
  File "/home/airflow/.local/lib/python3.10/site-packages/sqlalchemy/orm/session.py", line 1555, in _connection_for_bind
    return self._transaction._connection_for_bind(
  File "/home/airflow/.local/lib/python3.10/site-packages/sqlalchemy/orm/session.py", line 750, in _connection_for_bind
    conn = bind.connect()
  File "/home/airflow/.local/lib/python3.10/site-packages/sqlalchemy/future/engine.py", line 406, in connect
    return super(Engine, self).connect()
  File "/home/airflow/.local/lib/python3.10/site-packages/sqlalchemy/engine/base.py", line 3325, in connect
    return self._connection_cls(self, close_with_result=close_with_result)
  File "/home/airflow/.local/lib/python3.10/site-packages/sqlalchemy/engine/base.py", line 96, in __init__
    else engine.raw_connection()
  File "/home/airflow/.local/lib/python3.10/site-packages/sqlalchemy/engine/base.py", line 3404, in raw_connection
    return self._wrap_pool_connect(self.pool.connect, _connection)
  File "/home/airflow/.local/lib/python3.10/site-packages/sqlalchemy/engine/base.py", line 3374, in _wrap_pool_connect
    Connection._handle_dbapi_exception_noconnection(
  File "/home/airflow/.local/lib/python3.10/site-packages/sqlalchemy/engine/base.py", line 2208, in _handle_dbapi_exception_noconnection
    util.raise_(
  File "/home/airflow/.local/lib/python3.10/site-packages/sqlalchemy/util/compat.py", line 211, in raise_
    raise exception
  File "/home/airflow/.local/lib/python3.10/site-packages/sqlalchemy/engine/base.py", line 3371, in _wrap_pool_connect
    return fn()
  File "/home/airflow/.local/lib/python3.10/site-packages/sqlalchemy/pool/base.py", line 327, in connect
    return _ConnectionFairy._checkout(self)
  File "/home/airflow/.local/lib/python3.10/site-packages/sqlalchemy/pool/base.py", line 894, in _checkout
    fairy = _ConnectionRecord.checkout(pool)
  File "/home/airflow/.local/lib/python3.10/site-packages/sqlalchemy/pool/base.py", line 493, in checkout
    rec = pool._do_get()
  File "/home/airflow/.local/lib/python3.10/site-packages/sqlalchemy/pool/impl.py", line 256, in _do_get
    return self._create_connection()
  File "/home/airflow/.local/lib/python3.10/site-packages/sqlalchemy/pool/base.py", line 273, in _create_connection
    return _ConnectionRecord(self)
  File "/home/airflow/.local/lib/python3.10/site-packages/sqlalchemy/pool/base.py", line 388, in __init__
    self.__connect()
  File "/home/airflow/.local/lib/python3.10/site-packages/sqlalchemy/pool/base.py", line 690, in __connect
    with util.safe_reraise():
  File "/home/airflow/.local/lib/python3.10/site-packages/sqlalchemy/util/langhelpers.py", line 70, in __exit__
    compat.raise_(
  File "/home/airflow/.local/lib/python3.10/site-packages/sqlalchemy/util/compat.py", line 211, in raise_
    raise exception
  File "/home/airflow/.local/lib/python3.10/site-packages/sqlalchemy/pool/base.py", line 686, in __connect
    self.dbapi_connection = connection = pool._invoke_creator(self)
  File "/home/airflow/.local/lib/python3.10/site-packages/sqlalchemy/engine/create.py", line 574, in connect
    return dialect.connect(*cargs, **cparams)
  File "/home/airflow/.local/lib/python3.10/site-packages/sqlalchemy/engine/default.py", line 598, in connect
    return self.dbapi.connect(*cargs, **cparams)
  File "/home/airflow/.local/lib/python3.10/site-packages/psycopg2/__init__.py", line 122, in connect
    conn = _connect(dsn, connection_factory=connection_factory, **kwasync)
sqlalchemy.exc.OperationalError: (psycopg2.OperationalError) could not translate host name "postgres" to address: Temporary failure in name resolution

(Background on this error at: https://sqlalche.me/e/14/e3q8)
[2025-08-31T04:35:12.059+0000] {spark_submit.py:579} INFO - 25/08/31 04:35:12 INFO AsyncEventQueue: Process of event SparkListenerResourceProfileAdded(Profile: id = 0, executor resources: memory -> name: memory, amount: 1024, script: , vendor: ,offHeap -> name: offHeap, amount: 0, script: , vendor: , task resources: cpus -> name: cpus, amount: 1.0) bylistener HeartbeatReceiver took 1969.4407ms.
[2025-08-31T04:35:12.150+0000] {spark_submit.py:579} INFO - 25/08/31 04:35:12 INFO AsyncEventQueue: Process of event SparkListenerResourceProfileAdded(Profile: id = 0, executor resources: memory -> name: memory, amount: 1024, script: , vendor: ,offHeap -> name: offHeap, amount: 0, script: , vendor: , task resources: cpus -> name: cpus, amount: 1.0) bylistener AppStatusListener took 61436.377589ms.
[2025-08-31T04:35:38.212+0000] {job.py:219} ERROR - Job heartbeat got an exception
Traceback (most recent call last):
  File "/home/airflow/.local/lib/python3.10/site-packages/sqlalchemy/engine/base.py", line 3371, in _wrap_pool_connect
    return fn()
  File "/home/airflow/.local/lib/python3.10/site-packages/sqlalchemy/pool/base.py", line 327, in connect
    return _ConnectionFairy._checkout(self)
  File "/home/airflow/.local/lib/python3.10/site-packages/sqlalchemy/pool/base.py", line 894, in _checkout
    fairy = _ConnectionRecord.checkout(pool)
  File "/home/airflow/.local/lib/python3.10/site-packages/sqlalchemy/pool/base.py", line 493, in checkout
    rec = pool._do_get()
  File "/home/airflow/.local/lib/python3.10/site-packages/sqlalchemy/pool/impl.py", line 256, in _do_get
    return self._create_connection()
  File "/home/airflow/.local/lib/python3.10/site-packages/sqlalchemy/pool/base.py", line 273, in _create_connection
    return _ConnectionRecord(self)
  File "/home/airflow/.local/lib/python3.10/site-packages/sqlalchemy/pool/base.py", line 388, in __init__
    self.__connect()
  File "/home/airflow/.local/lib/python3.10/site-packages/sqlalchemy/pool/base.py", line 690, in __connect
    with util.safe_reraise():
  File "/home/airflow/.local/lib/python3.10/site-packages/sqlalchemy/util/langhelpers.py", line 70, in __exit__
    compat.raise_(
  File "/home/airflow/.local/lib/python3.10/site-packages/sqlalchemy/util/compat.py", line 211, in raise_
    raise exception
  File "/home/airflow/.local/lib/python3.10/site-packages/sqlalchemy/pool/base.py", line 686, in __connect
    self.dbapi_connection = connection = pool._invoke_creator(self)
  File "/home/airflow/.local/lib/python3.10/site-packages/sqlalchemy/engine/create.py", line 574, in connect
    return dialect.connect(*cargs, **cparams)
  File "/home/airflow/.local/lib/python3.10/site-packages/sqlalchemy/engine/default.py", line 598, in connect
    return self.dbapi.connect(*cargs, **cparams)
  File "/home/airflow/.local/lib/python3.10/site-packages/psycopg2/__init__.py", line 122, in connect
    conn = _connect(dsn, connection_factory=connection_factory, **kwasync)
psycopg2.OperationalError: could not translate host name "postgres" to address: Temporary failure in name resolution


The above exception was the direct cause of the following exception:

Traceback (most recent call last):
  File "/home/airflow/.local/lib/python3.10/site-packages/airflow/jobs/job.py", line 190, in heartbeat
    session.merge(self)
  File "/home/airflow/.local/lib/python3.10/site-packages/sqlalchemy/orm/session.py", line 3056, in merge
    return self._merge(
  File "/home/airflow/.local/lib/python3.10/site-packages/sqlalchemy/orm/session.py", line 3136, in _merge
    merged = self.get(
  File "/home/airflow/.local/lib/python3.10/site-packages/sqlalchemy/orm/session.py", line 2853, in get
    return self._get_impl(
  File "/home/airflow/.local/lib/python3.10/site-packages/sqlalchemy/orm/session.py", line 2975, in _get_impl
    return db_load_fn(
  File "/home/airflow/.local/lib/python3.10/site-packages/sqlalchemy/orm/loading.py", line 530, in load_on_pk_identity
    session.execute(
  File "/home/airflow/.local/lib/python3.10/site-packages/sqlalchemy/orm/session.py", line 1716, in execute
    conn = self._connection_for_bind(bind)
  File "/home/airflow/.local/lib/python3.10/site-packages/sqlalchemy/orm/session.py", line 1555, in _connection_for_bind
    return self._transaction._connection_for_bind(
  File "/home/airflow/.local/lib/python3.10/site-packages/sqlalchemy/orm/session.py", line 750, in _connection_for_bind
    conn = bind.connect()
  File "/home/airflow/.local/lib/python3.10/site-packages/sqlalchemy/future/engine.py", line 406, in connect
    return super(Engine, self).connect()
  File "/home/airflow/.local/lib/python3.10/site-packages/sqlalchemy/engine/base.py", line 3325, in connect
    return self._connection_cls(self, close_with_result=close_with_result)
  File "/home/airflow/.local/lib/python3.10/site-packages/sqlalchemy/engine/base.py", line 96, in __init__
    else engine.raw_connection()
  File "/home/airflow/.local/lib/python3.10/site-packages/sqlalchemy/engine/base.py", line 3404, in raw_connection
    return self._wrap_pool_connect(self.pool.connect, _connection)
  File "/home/airflow/.local/lib/python3.10/site-packages/sqlalchemy/engine/base.py", line 3374, in _wrap_pool_connect
    Connection._handle_dbapi_exception_noconnection(
  File "/home/airflow/.local/lib/python3.10/site-packages/sqlalchemy/engine/base.py", line 2208, in _handle_dbapi_exception_noconnection
    util.raise_(
  File "/home/airflow/.local/lib/python3.10/site-packages/sqlalchemy/util/compat.py", line 211, in raise_
    raise exception
  File "/home/airflow/.local/lib/python3.10/site-packages/sqlalchemy/engine/base.py", line 3371, in _wrap_pool_connect
    return fn()
  File "/home/airflow/.local/lib/python3.10/site-packages/sqlalchemy/pool/base.py", line 327, in connect
    return _ConnectionFairy._checkout(self)
  File "/home/airflow/.local/lib/python3.10/site-packages/sqlalchemy/pool/base.py", line 894, in _checkout
    fairy = _ConnectionRecord.checkout(pool)
  File "/home/airflow/.local/lib/python3.10/site-packages/sqlalchemy/pool/base.py", line 493, in checkout
    rec = pool._do_get()
  File "/home/airflow/.local/lib/python3.10/site-packages/sqlalchemy/pool/impl.py", line 256, in _do_get
    return self._create_connection()
  File "/home/airflow/.local/lib/python3.10/site-packages/sqlalchemy/pool/base.py", line 273, in _create_connection
    return _ConnectionRecord(self)
  File "/home/airflow/.local/lib/python3.10/site-packages/sqlalchemy/pool/base.py", line 388, in __init__
    self.__connect()
  File "/home/airflow/.local/lib/python3.10/site-packages/sqlalchemy/pool/base.py", line 690, in __connect
    with util.safe_reraise():
  File "/home/airflow/.local/lib/python3.10/site-packages/sqlalchemy/util/langhelpers.py", line 70, in __exit__
    compat.raise_(
  File "/home/airflow/.local/lib/python3.10/site-packages/sqlalchemy/util/compat.py", line 211, in raise_
    raise exception
  File "/home/airflow/.local/lib/python3.10/site-packages/sqlalchemy/pool/base.py", line 686, in __connect
    self.dbapi_connection = connection = pool._invoke_creator(self)
  File "/home/airflow/.local/lib/python3.10/site-packages/sqlalchemy/engine/create.py", line 574, in connect
    return dialect.connect(*cargs, **cparams)
  File "/home/airflow/.local/lib/python3.10/site-packages/sqlalchemy/engine/default.py", line 598, in connect
    return self.dbapi.connect(*cargs, **cparams)
  File "/home/airflow/.local/lib/python3.10/site-packages/psycopg2/__init__.py", line 122, in connect
    conn = _connect(dsn, connection_factory=connection_factory, **kwasync)
sqlalchemy.exc.OperationalError: (psycopg2.OperationalError) could not translate host name "postgres" to address: Temporary failure in name resolution

(Background on this error at: https://sqlalche.me/e/14/e3q8)
[2025-08-31T04:39:32.702+0000] {local_task_job_runner.py:205} ERROR - Heartbeat time limit exceeded!
[2025-08-31T04:39:39.093+0000] {process_utils.py:131} INFO - Sending 15 to group 487. PIDs of all processes in the group: [512, 1062, 487]
[2025-08-31T04:39:40.568+0000] {process_utils.py:86} INFO - Sending the signal 15 to group 487
[2025-08-31T04:39:41.349+0000] {process_utils.py:79} INFO - Process psutil.Process(pid=1062, status='terminated', started='04:31:53') (1062) terminated with exit code None
[2025-08-31T04:39:43.289+0000] {taskinstance.py:1630} ERROR - Received SIGTERM. Terminating subprocesses.
[2025-08-31T04:39:47.538+0000] {spark_submit.py:705} INFO - Sending kill signal to spark-submit
[2025-08-31T04:39:54.954+0000] {standard_task_runner.py:104} ERROR - Failed to execute job 84 for task python_job ((psycopg2.OperationalError) could not translate host name "postgres" to address: Temporary failure in name resolution

(Background on this error at: https://sqlalche.me/e/14/e3q8); 487)
[2025-08-31T04:39:55.274+0000] {process_utils.py:79} INFO - Process psutil.Process(pid=487, status='terminated', exitcode=1, started='04:30:50') (487) terminated with exit code 1
[2025-08-31T04:39:55.324+0000] {process_utils.py:79} INFO - Process psutil.Process(pid=512, status='terminated', started='04:30:51') (512) terminated with exit code None
[2025-08-31T05:06:41.145+0000] {taskinstance.py:1157} INFO - Dependencies all met for dep_context=non-requeueable deps ti=<TaskInstance: sparking_flow.python_job scheduled__2025-08-30T12:00:00+00:00 [queued]>
[2025-08-31T05:06:41.164+0000] {taskinstance.py:1157} INFO - Dependencies all met for dep_context=requeueable deps ti=<TaskInstance: sparking_flow.python_job scheduled__2025-08-30T12:00:00+00:00 [queued]>
[2025-08-31T05:06:41.164+0000] {taskinstance.py:1359} INFO - Starting attempt 1 of 1
[2025-08-31T05:06:41.204+0000] {taskinstance.py:1380} INFO - Executing <Task(SparkSubmitOperator): python_job> on 2025-08-30 12:00:00+00:00
[2025-08-31T05:06:41.221+0000] {standard_task_runner.py:57} INFO - Started process 367 to run task
[2025-08-31T05:06:41.236+0000] {standard_task_runner.py:84} INFO - Running: ['***', 'tasks', 'run', 'sparking_flow', 'python_job', 'scheduled__2025-08-30T12:00:00+00:00', '--job-id', '28', '--raw', '--subdir', 'DAGS_FOLDER/spark_***.py', '--cfg-path', '/tmp/tmpxlod14lc']
[2025-08-31T05:06:41.240+0000] {standard_task_runner.py:85} INFO - Job 28: Subtask python_job
[2025-08-31T05:06:42.674+0000] {task_command.py:415} INFO - Running <TaskInstance: sparking_flow.python_job scheduled__2025-08-30T12:00:00+00:00 [running]> on host 80647ef95998
[2025-08-31T05:06:43.782+0000] {taskinstance.py:1660} INFO - Exporting env vars: AIRFLOW_CTX_DAG_OWNER='Kudzaishe Manyanya' AIRFLOW_CTX_DAG_ID='sparking_flow' AIRFLOW_CTX_TASK_ID='python_job' AIRFLOW_CTX_EXECUTION_DATE='2025-08-30T12:00:00+00:00' AIRFLOW_CTX_TRY_NUMBER='1' AIRFLOW_CTX_DAG_RUN_ID='scheduled__2025-08-30T12:00:00+00:00'
[2025-08-31T05:06:43.849+0000] {spark_submit.py:273} INFO - Could not load connection string spark-conn, defaulting to yarn
[2025-08-31T05:06:43.853+0000] {spark_submit.py:403} INFO - Spark-Submit cmd: spark-submit --master yarn --jars /opt/spark/external-jars/apache-spark-sql-connector.jar --name arrow-spark jobs/python/wordcountjob.py
[2025-08-31T05:06:46.337+0000] {spark_submit.py:579} INFO - WARNING: Using incubator modules: jdk.incubator.vector
[2025-08-31T05:06:55.046+0000] {spark_submit.py:579} INFO - Exception in thread "main" org.apache.spark.SparkException: When running with master 'yarn' either HADOOP_CONF_DIR or YARN_CONF_DIR must be set in the environment.
[2025-08-31T05:06:55.058+0000] {spark_submit.py:579} INFO - at org.apache.spark.deploy.SparkSubmitArguments.error(SparkSubmitArguments.scala:640)
[2025-08-31T05:06:55.063+0000] {spark_submit.py:579} INFO - at org.apache.spark.deploy.SparkSubmitArguments.validateSubmitArguments(SparkSubmitArguments.scala:287)
[2025-08-31T05:06:55.064+0000] {spark_submit.py:579} INFO - at org.apache.spark.deploy.SparkSubmitArguments.validateArguments(SparkSubmitArguments.scala:245)
[2025-08-31T05:06:55.065+0000] {spark_submit.py:579} INFO - at org.apache.spark.deploy.SparkSubmitArguments.<init>(SparkSubmitArguments.scala:104)
[2025-08-31T05:06:55.066+0000] {spark_submit.py:579} INFO - at org.apache.spark.deploy.SparkSubmit$$anon$2$$anon$3.<init>(SparkSubmit.scala:1101)
[2025-08-31T05:06:55.067+0000] {spark_submit.py:579} INFO - at org.apache.spark.deploy.SparkSubmit$$anon$2.parseArguments(SparkSubmit.scala:1101)
[2025-08-31T05:06:55.068+0000] {spark_submit.py:579} INFO - at org.apache.spark.deploy.SparkSubmit.doSubmit(SparkSubmit.scala:72)
[2025-08-31T05:06:55.069+0000] {spark_submit.py:579} INFO - at org.apache.spark.deploy.SparkSubmit$$anon$2.doSubmit(SparkSubmit.scala:1132)
[2025-08-31T05:06:55.070+0000] {spark_submit.py:579} INFO - at org.apache.spark.deploy.SparkSubmit$.main(SparkSubmit.scala:1141)
[2025-08-31T05:06:55.071+0000] {spark_submit.py:579} INFO - at org.apache.spark.deploy.SparkSubmit.main(SparkSubmit.scala)
[2025-08-31T05:06:55.235+0000] {taskinstance.py:1935} ERROR - Task failed with exception
Traceback (most recent call last):
  File "/home/airflow/.local/lib/python3.10/site-packages/airflow/providers/apache/spark/operators/spark_submit.py", line 174, in execute
    self._hook.submit(self.application)
  File "/home/airflow/.local/lib/python3.10/site-packages/airflow/providers/apache/spark/hooks/spark_submit.py", line 505, in submit
    raise AirflowException(
airflow.exceptions.AirflowException: Cannot execute: spark-submit --master yarn --jars /opt/spark/external-jars/apache-spark-sql-connector.jar --name arrow-spark jobs/python/wordcountjob.py. Error code is: 1.
[2025-08-31T05:06:55.281+0000] {taskinstance.py:1398} INFO - Marking task as FAILED. dag_id=sparking_flow, task_id=python_job, execution_date=20250830T120000, start_date=20250831T050641, end_date=20250831T050655
[2025-08-31T05:06:55.459+0000] {standard_task_runner.py:104} ERROR - Failed to execute job 28 for task python_job (Cannot execute: spark-submit --master yarn --jars /opt/spark/external-jars/apache-spark-sql-connector.jar --name arrow-spark jobs/python/wordcountjob.py. Error code is: 1.; 367)
[2025-08-31T05:06:55.528+0000] {local_task_job_runner.py:228} INFO - Task exited with return code 1
[2025-08-31T05:06:55.665+0000] {taskinstance.py:2776} INFO - 0 downstream tasks scheduled from follow-on schedule check
[2025-08-31T12:53:21.470+0000] {taskinstance.py:1157} INFO - Dependencies all met for dep_context=non-requeueable deps ti=<TaskInstance: sparking_flow.python_job scheduled__2025-08-30T12:00:00+00:00 [queued]>
[2025-08-31T12:53:21.497+0000] {taskinstance.py:1157} INFO - Dependencies all met for dep_context=requeueable deps ti=<TaskInstance: sparking_flow.python_job scheduled__2025-08-30T12:00:00+00:00 [queued]>
[2025-08-31T12:53:21.502+0000] {taskinstance.py:1359} INFO - Starting attempt 1 of 1
[2025-08-31T12:53:21.535+0000] {taskinstance.py:1380} INFO - Executing <Task(SparkSubmitOperator): python_job> on 2025-08-30 12:00:00+00:00
[2025-08-31T12:53:21.552+0000] {standard_task_runner.py:57} INFO - Started process 395 to run task
[2025-08-31T12:53:21.559+0000] {standard_task_runner.py:84} INFO - Running: ['***', 'tasks', 'run', 'sparking_flow', 'python_job', 'scheduled__2025-08-30T12:00:00+00:00', '--job-id', '19', '--raw', '--subdir', 'DAGS_FOLDER/spark_***.py', '--cfg-path', '/tmp/tmpfahvbplf']
[2025-08-31T12:53:21.568+0000] {standard_task_runner.py:85} INFO - Job 19: Subtask python_job
[2025-08-31T12:53:21.760+0000] {task_command.py:415} INFO - Running <TaskInstance: sparking_flow.python_job scheduled__2025-08-30T12:00:00+00:00 [running]> on host f7da00c682c4
[2025-08-31T12:53:22.134+0000] {taskinstance.py:1660} INFO - Exporting env vars: AIRFLOW_CTX_DAG_OWNER='Kudzaishe Manyanya' AIRFLOW_CTX_DAG_ID='sparking_flow' AIRFLOW_CTX_TASK_ID='python_job' AIRFLOW_CTX_EXECUTION_DATE='2025-08-30T12:00:00+00:00' AIRFLOW_CTX_TRY_NUMBER='1' AIRFLOW_CTX_DAG_RUN_ID='scheduled__2025-08-30T12:00:00+00:00'
[2025-08-31T12:53:22.201+0000] {base.py:73} INFO - Using connection ID 'spark-conn' for task execution.
[2025-08-31T12:53:22.207+0000] {spark_submit.py:403} INFO - Spark-Submit cmd: spark-submit --master spark://spark-master:7077 --jars /opt/spark/external-jars/apache-spark-sql-connector.jar --name arrow-spark --deploy-mode client jobs/python/wordcountjob.py
[2025-08-31T12:53:26.349+0000] {spark_submit.py:579} INFO - WARNING: Using incubator modules: jdk.incubator.vector
[2025-08-31T12:53:43.009+0000] {spark_submit.py:579} INFO - 25/08/31 12:53:42 WARN NativeCodeLoader: Unable to load native-hadoop library for your platform... using builtin-java classes where applicable
[2025-08-31T12:54:30.009+0000] {job.py:219} ERROR - Job heartbeat got an exception
Traceback (most recent call last):
  File "/home/airflow/.local/lib/python3.10/site-packages/sqlalchemy/engine/base.py", line 3371, in _wrap_pool_connect
    return fn()
  File "/home/airflow/.local/lib/python3.10/site-packages/sqlalchemy/pool/base.py", line 327, in connect
    return _ConnectionFairy._checkout(self)
  File "/home/airflow/.local/lib/python3.10/site-packages/sqlalchemy/pool/base.py", line 894, in _checkout
    fairy = _ConnectionRecord.checkout(pool)
  File "/home/airflow/.local/lib/python3.10/site-packages/sqlalchemy/pool/base.py", line 493, in checkout
    rec = pool._do_get()
  File "/home/airflow/.local/lib/python3.10/site-packages/sqlalchemy/pool/impl.py", line 256, in _do_get
    return self._create_connection()
  File "/home/airflow/.local/lib/python3.10/site-packages/sqlalchemy/pool/base.py", line 273, in _create_connection
    return _ConnectionRecord(self)
  File "/home/airflow/.local/lib/python3.10/site-packages/sqlalchemy/pool/base.py", line 388, in __init__
    self.__connect()
  File "/home/airflow/.local/lib/python3.10/site-packages/sqlalchemy/pool/base.py", line 690, in __connect
    with util.safe_reraise():
  File "/home/airflow/.local/lib/python3.10/site-packages/sqlalchemy/util/langhelpers.py", line 70, in __exit__
    compat.raise_(
  File "/home/airflow/.local/lib/python3.10/site-packages/sqlalchemy/util/compat.py", line 211, in raise_
    raise exception
  File "/home/airflow/.local/lib/python3.10/site-packages/sqlalchemy/pool/base.py", line 686, in __connect
    self.dbapi_connection = connection = pool._invoke_creator(self)
  File "/home/airflow/.local/lib/python3.10/site-packages/sqlalchemy/engine/create.py", line 574, in connect
    return dialect.connect(*cargs, **cparams)
  File "/home/airflow/.local/lib/python3.10/site-packages/sqlalchemy/engine/default.py", line 598, in connect
    return self.dbapi.connect(*cargs, **cparams)
  File "/home/airflow/.local/lib/python3.10/site-packages/psycopg2/__init__.py", line 122, in connect
    conn = _connect(dsn, connection_factory=connection_factory, **kwasync)
psycopg2.OperationalError: could not translate host name "postgres" to address: Temporary failure in name resolution


The above exception was the direct cause of the following exception:

Traceback (most recent call last):
  File "/home/airflow/.local/lib/python3.10/site-packages/airflow/jobs/job.py", line 190, in heartbeat
    session.merge(self)
  File "/home/airflow/.local/lib/python3.10/site-packages/sqlalchemy/orm/session.py", line 3056, in merge
    return self._merge(
  File "/home/airflow/.local/lib/python3.10/site-packages/sqlalchemy/orm/session.py", line 3136, in _merge
    merged = self.get(
  File "/home/airflow/.local/lib/python3.10/site-packages/sqlalchemy/orm/session.py", line 2853, in get
    return self._get_impl(
  File "/home/airflow/.local/lib/python3.10/site-packages/sqlalchemy/orm/session.py", line 2975, in _get_impl
    return db_load_fn(
  File "/home/airflow/.local/lib/python3.10/site-packages/sqlalchemy/orm/loading.py", line 530, in load_on_pk_identity
    session.execute(
  File "/home/airflow/.local/lib/python3.10/site-packages/sqlalchemy/orm/session.py", line 1716, in execute
    conn = self._connection_for_bind(bind)
  File "/home/airflow/.local/lib/python3.10/site-packages/sqlalchemy/orm/session.py", line 1555, in _connection_for_bind
    return self._transaction._connection_for_bind(
  File "/home/airflow/.local/lib/python3.10/site-packages/sqlalchemy/orm/session.py", line 750, in _connection_for_bind
    conn = bind.connect()
  File "/home/airflow/.local/lib/python3.10/site-packages/sqlalchemy/future/engine.py", line 406, in connect
    return super(Engine, self).connect()
  File "/home/airflow/.local/lib/python3.10/site-packages/sqlalchemy/engine/base.py", line 3325, in connect
    return self._connection_cls(self, close_with_result=close_with_result)
  File "/home/airflow/.local/lib/python3.10/site-packages/sqlalchemy/engine/base.py", line 96, in __init__
    else engine.raw_connection()
  File "/home/airflow/.local/lib/python3.10/site-packages/sqlalchemy/engine/base.py", line 3404, in raw_connection
    return self._wrap_pool_connect(self.pool.connect, _connection)
  File "/home/airflow/.local/lib/python3.10/site-packages/sqlalchemy/engine/base.py", line 3374, in _wrap_pool_connect
    Connection._handle_dbapi_exception_noconnection(
  File "/home/airflow/.local/lib/python3.10/site-packages/sqlalchemy/engine/base.py", line 2208, in _handle_dbapi_exception_noconnection
    util.raise_(
  File "/home/airflow/.local/lib/python3.10/site-packages/sqlalchemy/util/compat.py", line 211, in raise_
    raise exception
  File "/home/airflow/.local/lib/python3.10/site-packages/sqlalchemy/engine/base.py", line 3371, in _wrap_pool_connect
    return fn()
  File "/home/airflow/.local/lib/python3.10/site-packages/sqlalchemy/pool/base.py", line 327, in connect
    return _ConnectionFairy._checkout(self)
  File "/home/airflow/.local/lib/python3.10/site-packages/sqlalchemy/pool/base.py", line 894, in _checkout
    fairy = _ConnectionRecord.checkout(pool)
  File "/home/airflow/.local/lib/python3.10/site-packages/sqlalchemy/pool/base.py", line 493, in checkout
    rec = pool._do_get()
  File "/home/airflow/.local/lib/python3.10/site-packages/sqlalchemy/pool/impl.py", line 256, in _do_get
    return self._create_connection()
  File "/home/airflow/.local/lib/python3.10/site-packages/sqlalchemy/pool/base.py", line 273, in _create_connection
    return _ConnectionRecord(self)
  File "/home/airflow/.local/lib/python3.10/site-packages/sqlalchemy/pool/base.py", line 388, in __init__
    self.__connect()
  File "/home/airflow/.local/lib/python3.10/site-packages/sqlalchemy/pool/base.py", line 690, in __connect
    with util.safe_reraise():
  File "/home/airflow/.local/lib/python3.10/site-packages/sqlalchemy/util/langhelpers.py", line 70, in __exit__
    compat.raise_(
  File "/home/airflow/.local/lib/python3.10/site-packages/sqlalchemy/util/compat.py", line 211, in raise_
    raise exception
  File "/home/airflow/.local/lib/python3.10/site-packages/sqlalchemy/pool/base.py", line 686, in __connect
    self.dbapi_connection = connection = pool._invoke_creator(self)
  File "/home/airflow/.local/lib/python3.10/site-packages/sqlalchemy/engine/create.py", line 574, in connect
    return dialect.connect(*cargs, **cparams)
  File "/home/airflow/.local/lib/python3.10/site-packages/sqlalchemy/engine/default.py", line 598, in connect
    return self.dbapi.connect(*cargs, **cparams)
  File "/home/airflow/.local/lib/python3.10/site-packages/psycopg2/__init__.py", line 122, in connect
    conn = _connect(dsn, connection_factory=connection_factory, **kwasync)
sqlalchemy.exc.OperationalError: (psycopg2.OperationalError) could not translate host name "postgres" to address: Temporary failure in name resolution

(Background on this error at: https://sqlalche.me/e/14/e3q8)
[2025-08-31T12:57:06.119+0000] {job.py:219} ERROR - Job heartbeat got an exception
Traceback (most recent call last):
  File "/home/airflow/.local/lib/python3.10/site-packages/sqlalchemy/engine/base.py", line 3371, in _wrap_pool_connect
    return fn()
  File "/home/airflow/.local/lib/python3.10/site-packages/sqlalchemy/pool/base.py", line 327, in connect
    return _ConnectionFairy._checkout(self)
  File "/home/airflow/.local/lib/python3.10/site-packages/sqlalchemy/pool/base.py", line 894, in _checkout
    fairy = _ConnectionRecord.checkout(pool)
  File "/home/airflow/.local/lib/python3.10/site-packages/sqlalchemy/pool/base.py", line 493, in checkout
    rec = pool._do_get()
  File "/home/airflow/.local/lib/python3.10/site-packages/sqlalchemy/pool/impl.py", line 256, in _do_get
    return self._create_connection()
  File "/home/airflow/.local/lib/python3.10/site-packages/sqlalchemy/pool/base.py", line 273, in _create_connection
    return _ConnectionRecord(self)
  File "/home/airflow/.local/lib/python3.10/site-packages/sqlalchemy/pool/base.py", line 388, in __init__
    self.__connect()
  File "/home/airflow/.local/lib/python3.10/site-packages/sqlalchemy/pool/base.py", line 690, in __connect
    with util.safe_reraise():
  File "/home/airflow/.local/lib/python3.10/site-packages/sqlalchemy/util/langhelpers.py", line 70, in __exit__
    compat.raise_(
  File "/home/airflow/.local/lib/python3.10/site-packages/sqlalchemy/util/compat.py", line 211, in raise_
    raise exception
  File "/home/airflow/.local/lib/python3.10/site-packages/sqlalchemy/pool/base.py", line 686, in __connect
    self.dbapi_connection = connection = pool._invoke_creator(self)
  File "/home/airflow/.local/lib/python3.10/site-packages/sqlalchemy/engine/create.py", line 574, in connect
    return dialect.connect(*cargs, **cparams)
  File "/home/airflow/.local/lib/python3.10/site-packages/sqlalchemy/engine/default.py", line 598, in connect
    return self.dbapi.connect(*cargs, **cparams)
  File "/home/airflow/.local/lib/python3.10/site-packages/psycopg2/__init__.py", line 122, in connect
    conn = _connect(dsn, connection_factory=connection_factory, **kwasync)
psycopg2.OperationalError: could not translate host name "postgres" to address: Temporary failure in name resolution


The above exception was the direct cause of the following exception:

Traceback (most recent call last):
  File "/home/airflow/.local/lib/python3.10/site-packages/airflow/jobs/job.py", line 190, in heartbeat
    session.merge(self)
  File "/home/airflow/.local/lib/python3.10/site-packages/sqlalchemy/orm/session.py", line 3056, in merge
    return self._merge(
  File "/home/airflow/.local/lib/python3.10/site-packages/sqlalchemy/orm/session.py", line 3136, in _merge
    merged = self.get(
  File "/home/airflow/.local/lib/python3.10/site-packages/sqlalchemy/orm/session.py", line 2853, in get
    return self._get_impl(
  File "/home/airflow/.local/lib/python3.10/site-packages/sqlalchemy/orm/session.py", line 2975, in _get_impl
    return db_load_fn(
  File "/home/airflow/.local/lib/python3.10/site-packages/sqlalchemy/orm/loading.py", line 530, in load_on_pk_identity
    session.execute(
  File "/home/airflow/.local/lib/python3.10/site-packages/sqlalchemy/orm/session.py", line 1716, in execute
    conn = self._connection_for_bind(bind)
  File "/home/airflow/.local/lib/python3.10/site-packages/sqlalchemy/orm/session.py", line 1555, in _connection_for_bind
    return self._transaction._connection_for_bind(
  File "/home/airflow/.local/lib/python3.10/site-packages/sqlalchemy/orm/session.py", line 750, in _connection_for_bind
    conn = bind.connect()
  File "/home/airflow/.local/lib/python3.10/site-packages/sqlalchemy/future/engine.py", line 406, in connect
    return super(Engine, self).connect()
  File "/home/airflow/.local/lib/python3.10/site-packages/sqlalchemy/engine/base.py", line 3325, in connect
    return self._connection_cls(self, close_with_result=close_with_result)
  File "/home/airflow/.local/lib/python3.10/site-packages/sqlalchemy/engine/base.py", line 96, in __init__
    else engine.raw_connection()
  File "/home/airflow/.local/lib/python3.10/site-packages/sqlalchemy/engine/base.py", line 3404, in raw_connection
    return self._wrap_pool_connect(self.pool.connect, _connection)
  File "/home/airflow/.local/lib/python3.10/site-packages/sqlalchemy/engine/base.py", line 3374, in _wrap_pool_connect
    Connection._handle_dbapi_exception_noconnection(
  File "/home/airflow/.local/lib/python3.10/site-packages/sqlalchemy/engine/base.py", line 2208, in _handle_dbapi_exception_noconnection
    util.raise_(
  File "/home/airflow/.local/lib/python3.10/site-packages/sqlalchemy/util/compat.py", line 211, in raise_
    raise exception
  File "/home/airflow/.local/lib/python3.10/site-packages/sqlalchemy/engine/base.py", line 3371, in _wrap_pool_connect
    return fn()
  File "/home/airflow/.local/lib/python3.10/site-packages/sqlalchemy/pool/base.py", line 327, in connect
    return _ConnectionFairy._checkout(self)
  File "/home/airflow/.local/lib/python3.10/site-packages/sqlalchemy/pool/base.py", line 894, in _checkout
    fairy = _ConnectionRecord.checkout(pool)
  File "/home/airflow/.local/lib/python3.10/site-packages/sqlalchemy/pool/base.py", line 493, in checkout
    rec = pool._do_get()
  File "/home/airflow/.local/lib/python3.10/site-packages/sqlalchemy/pool/impl.py", line 256, in _do_get
    return self._create_connection()
  File "/home/airflow/.local/lib/python3.10/site-packages/sqlalchemy/pool/base.py", line 273, in _create_connection
    return _ConnectionRecord(self)
  File "/home/airflow/.local/lib/python3.10/site-packages/sqlalchemy/pool/base.py", line 388, in __init__
    self.__connect()
  File "/home/airflow/.local/lib/python3.10/site-packages/sqlalchemy/pool/base.py", line 690, in __connect
    with util.safe_reraise():
  File "/home/airflow/.local/lib/python3.10/site-packages/sqlalchemy/util/langhelpers.py", line 70, in __exit__
    compat.raise_(
  File "/home/airflow/.local/lib/python3.10/site-packages/sqlalchemy/util/compat.py", line 211, in raise_
    raise exception
  File "/home/airflow/.local/lib/python3.10/site-packages/sqlalchemy/pool/base.py", line 686, in __connect
    self.dbapi_connection = connection = pool._invoke_creator(self)
  File "/home/airflow/.local/lib/python3.10/site-packages/sqlalchemy/engine/create.py", line 574, in connect
    return dialect.connect(*cargs, **cparams)
  File "/home/airflow/.local/lib/python3.10/site-packages/sqlalchemy/engine/default.py", line 598, in connect
    return self.dbapi.connect(*cargs, **cparams)
  File "/home/airflow/.local/lib/python3.10/site-packages/psycopg2/__init__.py", line 122, in connect
    conn = _connect(dsn, connection_factory=connection_factory, **kwasync)
sqlalchemy.exc.OperationalError: (psycopg2.OperationalError) could not translate host name "postgres" to address: Temporary failure in name resolution

(Background on this error at: https://sqlalche.me/e/14/e3q8)
[2025-08-31T12:59:48.768+0000] {local_task_job_runner.py:205} ERROR - Heartbeat time limit exceeded!
[2025-08-31T13:01:34.230+0000] {process_utils.py:131} INFO - Sending 15 to group 395. PIDs of all processes in the group: [415, 1422, 395]
[2025-08-31T13:01:34.306+0000] {process_utils.py:86} INFO - Sending the signal 15 to group 395
[2025-08-31T13:01:34.537+0000] {taskinstance.py:1630} ERROR - Received SIGTERM. Terminating subprocesses.
[2025-08-31T13:01:34.592+0000] {spark_submit.py:705} INFO - Sending kill signal to spark-submit
[2025-08-31T13:01:35.050+0000] {process_utils.py:79} INFO - Process psutil.Process(pid=1422, status='terminated', started='12:53:45') (1422) terminated with exit code None
[2025-08-31T13:01:35.500+0000] {taskinstance.py:1935} ERROR - Task failed with exception
Traceback (most recent call last):
  File "/home/airflow/.local/lib/python3.10/site-packages/airflow/providers/apache/spark/operators/spark_submit.py", line 174, in execute
    self._hook.submit(self.application)
  File "/home/airflow/.local/lib/python3.10/site-packages/airflow/providers/apache/spark/hooks/spark_submit.py", line 493, in submit
    self._process_spark_submit_log(iter(self._submit_sp.stdout))  # type: ignore
  File "/home/airflow/.local/lib/python3.10/site-packages/airflow/providers/apache/spark/hooks/spark_submit.py", line 542, in _process_spark_submit_log
    for line in itr:
  File "/home/airflow/.local/lib/python3.10/site-packages/airflow/models/taskinstance.py", line 1632, in signal_handler
    raise AirflowException("Task received SIGTERM signal")
airflow.exceptions.AirflowException: Task received SIGTERM signal
[2025-08-31T13:01:35.859+0000] {taskinstance.py:1398} INFO - Marking task as FAILED. dag_id=sparking_flow, task_id=python_job, execution_date=20250830T120000, start_date=20250831T125321, end_date=20250831T130135
[2025-08-31T13:01:36.118+0000] {standard_task_runner.py:104} ERROR - Failed to execute job 19 for task python_job (Task received SIGTERM signal; 395)
[2025-08-31T13:01:36.211+0000] {process_utils.py:79} INFO - Process psutil.Process(pid=395, status='terminated', exitcode=1, started='12:53:21') (395) terminated with exit code 1
[2025-08-31T13:01:36.212+0000] {process_utils.py:79} INFO - Process psutil.Process(pid=415, status='terminated', started='12:53:22') (415) terminated with exit code None
