[2025-08-31T04:30:59.718+0000] {taskinstance.py:1157} INFO - Dependencies all met for dep_context=non-requeueable deps ti=<TaskInstance: sparking_flow.python_job scheduled__2025-08-31T02:00:00+00:00 [queued]>
[2025-08-31T04:31:00.281+0000] {taskinstance.py:1157} INFO - Dependencies all met for dep_context=requeueable deps ti=<TaskInstance: sparking_flow.python_job scheduled__2025-08-31T02:00:00+00:00 [queued]>
[2025-08-31T04:31:00.316+0000] {taskinstance.py:1359} INFO - Starting attempt 1 of 1
[2025-08-31T04:31:03.621+0000] {taskinstance.py:1380} INFO - Executing <Task(SparkSubmitOperator): python_job> on 2025-08-31 02:00:00+00:00
[2025-08-31T04:31:04.649+0000] {standard_task_runner.py:57} INFO - Started process 598 to run task
[2025-08-31T04:31:05.158+0000] {standard_task_runner.py:84} INFO - Running: ['***', 'tasks', 'run', 'sparking_flow', 'python_job', 'scheduled__2025-08-31T02:00:00+00:00', '--job-id', '90', '--raw', '--subdir', 'DAGS_FOLDER/spark_***.py', '--cfg-path', '/tmp/tmpugzp0evp']
[2025-08-31T04:31:05.236+0000] {standard_task_runner.py:85} INFO - Job 90: Subtask python_job
[2025-08-31T04:31:09.532+0000] {task_command.py:415} INFO - Running <TaskInstance: sparking_flow.python_job scheduled__2025-08-31T02:00:00+00:00 [running]> on host 81b7fe425a18
[2025-08-31T04:31:31.955+0000] {taskinstance.py:1660} INFO - Exporting env vars: AIRFLOW_CTX_DAG_OWNER='Kudzaishe Manyanya' AIRFLOW_CTX_DAG_ID='sparking_flow' AIRFLOW_CTX_TASK_ID='python_job' AIRFLOW_CTX_EXECUTION_DATE='2025-08-31T02:00:00+00:00' AIRFLOW_CTX_TRY_NUMBER='1' AIRFLOW_CTX_DAG_RUN_ID='scheduled__2025-08-31T02:00:00+00:00'
[2025-08-31T04:31:32.217+0000] {base.py:73} INFO - Using connection ID 'spark-conn' for task execution.
[2025-08-31T04:31:32.247+0000] {spark_submit.py:403} INFO - Spark-Submit cmd: spark-submit --master spark://spark-master:7077 --jars /opt/spark/external-jars/apache-spark-sql-connector.jar --name arrow-spark --deploy-mode client jobs/python/wordcountjob.py
[2025-08-31T04:31:37.580+0000] {spark_submit.py:579} INFO - WARNING: Using incubator modules: jdk.incubator.vector
[2025-08-31T04:32:01.086+0000] {spark_submit.py:579} INFO - 25/08/31 04:32:01 WARN NativeCodeLoader: Unable to load native-hadoop library for your platform... using builtin-java classes where applicable
[2025-08-31T04:33:08.208+0000] {spark_submit.py:579} INFO - Using Spark's default log4j profile: org/apache/spark/log4j2-defaults.properties
[2025-08-31T04:33:08.659+0000] {spark_submit.py:579} INFO - 25/08/31 04:33:08 INFO SparkContext: Running Spark version 4.0.0
[2025-08-31T04:33:09.651+0000] {spark_submit.py:579} INFO - 25/08/31 04:33:09 INFO SparkContext: OS info Linux, 6.6.87.2-microsoft-standard-WSL2, amd64
[2025-08-31T04:33:09.726+0000] {spark_submit.py:579} INFO - 25/08/31 04:33:09 INFO SparkContext: Java version 17.0.15
[2025-08-31T04:33:11.069+0000] {spark_submit.py:579} INFO - 25/08/31 04:33:11 INFO ResourceUtils: ==============================================================
[2025-08-31T04:33:11.178+0000] {spark_submit.py:579} INFO - 25/08/31 04:33:11 INFO ResourceUtils: No custom resources configured for spark.driver.
[2025-08-31T04:33:11.187+0000] {spark_submit.py:579} INFO - 25/08/31 04:33:11 INFO ResourceUtils: ==============================================================
[2025-08-31T04:33:11.192+0000] {spark_submit.py:579} INFO - 25/08/31 04:33:11 INFO SparkContext: Submitted application: PythonWordCount
[2025-08-31T04:33:11.765+0000] {spark_submit.py:579} INFO - 25/08/31 04:33:11 INFO ResourceProfile: Default ResourceProfile created, executor resources: Map(memory -> name: memory, amount: 1024, script: , vendor: , offHeap -> name: offHeap, amount: 0, script: , vendor: ), task resources: Map(cpus -> name: cpus, amount: 1.0)
[2025-08-31T04:33:11.819+0000] {spark_submit.py:579} INFO - 25/08/31 04:33:11 INFO ResourceProfile: Limiting resource is cpu
[2025-08-31T04:33:11.852+0000] {spark_submit.py:579} INFO - 25/08/31 04:33:11 INFO ResourceProfileManager: Added ResourceProfile id: 0
[2025-08-31T04:33:19.851+0000] {spark_submit.py:579} INFO - 25/08/31 04:33:19 INFO SecurityManager: Changing view acls to: ***
[2025-08-31T04:33:20.534+0000] {spark_submit.py:579} INFO - 25/08/31 04:33:19 INFO SecurityManager: Changing modify acls to: ***
[2025-08-31T04:33:20.545+0000] {spark_submit.py:579} INFO - 25/08/31 04:33:19 INFO SecurityManager: Changing view acls groups to: ***
[2025-08-31T04:33:20.551+0000] {spark_submit.py:579} INFO - 25/08/31 04:33:19 INFO SecurityManager: Changing modify acls groups to: ***
[2025-08-31T04:33:20.555+0000] {spark_submit.py:579} INFO - 25/08/31 04:33:19 INFO SecurityManager: SecurityManager: authentication disabled; ui acls disabled; users with view permissions: *** groups with view permissions: EMPTY; users with modify permissions: ***; groups with modify permissions: EMPTY; RPC SSL disabled
[2025-08-31T04:33:32.385+0000] {spark_submit.py:579} INFO - 25/08/31 04:33:32 INFO Utils: Successfully started service 'sparkDriver' on port 43653.
[2025-08-31T04:33:32.958+0000] {spark_submit.py:579} INFO - 25/08/31 04:33:32 INFO SparkEnv: Registering MapOutputTracker
[2025-08-31T04:33:33.107+0000] {spark_submit.py:579} INFO - 25/08/31 04:33:33 INFO SparkEnv: Registering BlockManagerMaster
[2025-08-31T04:33:33.633+0000] {spark_submit.py:579} INFO - 25/08/31 04:33:33 INFO BlockManagerMasterEndpoint: Using org.apache.spark.storage.DefaultTopologyMapper for getting topology information
[2025-08-31T04:33:33.665+0000] {spark_submit.py:579} INFO - 25/08/31 04:33:33 INFO BlockManagerMasterEndpoint: BlockManagerMasterEndpoint up
[2025-08-31T04:33:33.720+0000] {spark_submit.py:579} INFO - 25/08/31 04:33:33 INFO SparkEnv: Registering BlockManagerMasterHeartbeat
[2025-08-31T04:33:34.038+0000] {spark_submit.py:579} INFO - 25/08/31 04:33:34 INFO DiskBlockManager: Created local directory at /tmp/blockmgr-6f52d7f1-bcf8-4a41-bc88-954a5675c48c
[2025-08-31T04:33:34.369+0000] {spark_submit.py:579} INFO - 25/08/31 04:33:34 INFO SparkEnv: Registering OutputCommitCoordinator
[2025-08-31T04:33:37.244+0000] {spark_submit.py:579} INFO - 25/08/31 04:33:37 INFO JettyUtils: Start Jetty 0.0.0.0:4040 for SparkUI
[2025-08-31T04:33:42.300+0000] {spark_submit.py:579} INFO - 25/08/31 04:33:42 WARN Utils: Service 'SparkUI' could not bind on port 4040. Attempting port 4041.
[2025-08-31T04:33:42.476+0000] {spark_submit.py:579} INFO - 25/08/31 04:33:42 WARN Utils: Service 'SparkUI' could not bind on port 4041. Attempting port 4042.
[2025-08-31T04:33:42.480+0000] {spark_submit.py:579} INFO - 25/08/31 04:33:42 WARN Utils: Service 'SparkUI' could not bind on port 4042. Attempting port 4043.
[2025-08-31T04:33:42.487+0000] {spark_submit.py:579} INFO - 25/08/31 04:33:42 WARN Utils: Service 'SparkUI' could not bind on port 4043. Attempting port 4044.
[2025-08-31T04:33:42.490+0000] {spark_submit.py:579} INFO - 25/08/31 04:33:42 WARN Utils: Service 'SparkUI' could not bind on port 4044. Attempting port 4045.
[2025-08-31T04:33:42.492+0000] {spark_submit.py:579} INFO - 25/08/31 04:33:42 WARN Utils: Service 'SparkUI' could not bind on port 4045. Attempting port 4046.
[2025-08-31T04:33:42.495+0000] {spark_submit.py:579} INFO - 25/08/31 04:33:42 WARN Utils: Service 'SparkUI' could not bind on port 4046. Attempting port 4047.
[2025-08-31T04:33:42.496+0000] {spark_submit.py:579} INFO - 25/08/31 04:33:42 WARN Utils: Service 'SparkUI' could not bind on port 4047. Attempting port 4048.
[2025-08-31T04:33:42.496+0000] {spark_submit.py:579} INFO - 25/08/31 04:33:42 WARN Utils: Service 'SparkUI' could not bind on port 4048. Attempting port 4049.
[2025-08-31T04:33:43.660+0000] {spark_submit.py:579} INFO - 25/08/31 04:33:43 INFO Utils: Successfully started service 'SparkUI' on port 4049.
[2025-08-31T04:33:49.661+0000] {spark_submit.py:579} INFO - 25/08/31 04:33:49 INFO SparkContext: Added JAR file:///opt/spark/external-jars/apache-spark-sql-connector.jar at spark://81b7fe425a18:43653/jars/apache-spark-sql-connector.jar with timestamp 1756614786520
[2025-08-31T04:33:50.711+0000] {spark_submit.py:579} INFO - 25/08/31 04:33:50 INFO SecurityManager: Changing view acls to: ***
[2025-08-31T04:33:50.870+0000] {spark_submit.py:579} INFO - 25/08/31 04:33:50 INFO SecurityManager: Changing modify acls to: ***
[2025-08-31T04:33:50.874+0000] {spark_submit.py:579} INFO - 25/08/31 04:33:50 INFO SecurityManager: Changing view acls groups to: ***
[2025-08-31T04:33:50.883+0000] {spark_submit.py:579} INFO - 25/08/31 04:33:50 INFO SecurityManager: Changing modify acls groups to: ***
[2025-08-31T04:33:50.886+0000] {spark_submit.py:579} INFO - 25/08/31 04:33:50 INFO SecurityManager: SecurityManager: authentication disabled; ui acls disabled; users with view permissions: *** groups with view permissions: EMPTY; users with modify permissions: ***; groups with modify permissions: EMPTY; RPC SSL disabled
[2025-08-31T04:33:59.600+0000] {spark_submit.py:579} INFO - 25/08/31 04:33:59 INFO StandaloneAppClient$ClientEndpoint: Connecting to master spark://spark-master:7077...
[2025-08-31T04:34:03.844+0000] {spark_submit.py:579} INFO - 25/08/31 04:34:03 INFO TransportClientFactory: Successfully created connection to spark-master/172.18.0.2:7077 after 1610 ms (1 ms spent in bootstraps)
[2025-08-31T04:34:08.231+0000] {spark_submit.py:579} INFO - 25/08/31 04:34:08 INFO StandaloneSchedulerBackend: Connected to Spark cluster with app ID app-20250831043407-0001
[2025-08-31T04:34:08.599+0000] {spark_submit.py:579} INFO - 25/08/31 04:34:08 INFO Utils: Successfully started service 'org.apache.spark.network.netty.NettyBlockTransferService' on port 46509.
[2025-08-31T04:34:08.615+0000] {spark_submit.py:579} INFO - 25/08/31 04:34:08 INFO NettyBlockTransferService: Server created on 81b7fe425a18:46509
[2025-08-31T04:34:08.644+0000] {spark_submit.py:579} INFO - 25/08/31 04:34:08 INFO BlockManager: Using org.apache.spark.storage.RandomBlockReplicationPolicy for block replication policy
[2025-08-31T04:34:08.832+0000] {spark_submit.py:579} INFO - 25/08/31 04:34:08 INFO BlockManagerMaster: Registering BlockManager BlockManagerId(driver, 81b7fe425a18, 46509, None)
[2025-08-31T04:34:09.024+0000] {spark_submit.py:579} INFO - 25/08/31 04:34:09 INFO BlockManagerMasterEndpoint: Registering block manager 81b7fe425a18:46509 with 434.4 MiB RAM, BlockManagerId(driver, 81b7fe425a18, 46509, None)
[2025-08-31T04:34:09.037+0000] {spark_submit.py:579} INFO - 25/08/31 04:34:09 INFO BlockManagerMaster: Registered BlockManager BlockManagerId(driver, 81b7fe425a18, 46509, None)
[2025-08-31T04:34:09.046+0000] {spark_submit.py:579} INFO - 25/08/31 04:34:09 INFO BlockManager: Initialized BlockManager: BlockManagerId(driver, 81b7fe425a18, 46509, None)
[2025-08-31T04:35:11.864+0000] {spark_submit.py:579} INFO - 25/08/31 04:35:11 INFO AsyncEventQueue: Process of event SparkListenerResourceProfileAdded(Profile: id = 0, executor resources: memory -> name: memory, amount: 1024, script: , vendor: ,offHeap -> name: offHeap, amount: 0, script: , vendor: , task resources: cpus -> name: cpus, amount: 1.0) bylistener AppStatusListener took 61436.703956ms.
[2025-08-31T04:35:12.097+0000] {spark_submit.py:579} INFO - 25/08/31 04:35:11 INFO AsyncEventQueue: Process of event SparkListenerResourceProfileAdded(Profile: id = 0, executor resources: memory -> name: memory, amount: 1024, script: , vendor: ,offHeap -> name: offHeap, amount: 0, script: , vendor: , task resources: cpus -> name: cpus, amount: 1.0) bylistener HeartbeatReceiver took 2423.837086ms.
[2025-08-31T04:39:44.005+0000] {spark_submit.py:579} INFO - 25/08/31 04:39:38 INFO AsyncEventQueue: Process of event SparkListenerApplicationStart(PythonWordCount,Some(app-20250831043407-0001),1756614786520,***,None,None,None) bylistener AppStatusListener took 264616.250706ms.
[2025-08-31T04:39:47.536+0000] {spark_submit.py:579} INFO - 25/08/31 04:39:47 INFO StandaloneAppClient$ClientEndpoint: Master removed worker worker-20250831043001-172.18.0.4-33111: Not receiving heartbeat for 60 seconds
[2025-08-31T04:39:47.651+0000] {spark_submit.py:579} INFO - 25/08/31 04:39:47 INFO StandaloneSchedulerBackend: Worker worker-20250831043001-172.18.0.4-33111 removed: Not receiving heartbeat for 60 seconds
[2025-08-31T04:39:47.993+0000] {spark_submit.py:579} INFO - 25/08/31 04:39:47 INFO StandaloneSchedulerBackend: SchedulerBackend is ready for scheduling beginning after reached minRegisteredResourcesRatio: 0.0
[2025-08-31T04:39:48.206+0000] {spark_submit.py:579} INFO - 25/08/31 04:39:48 INFO TaskSchedulerImpl: Handle removed worker worker-20250831043001-172.18.0.4-33111: Not receiving heartbeat for 60 seconds
[2025-08-31T04:39:48.930+0000] {spark_submit.py:579} INFO - 25/08/31 04:39:48 INFO DAGScheduler: Shuffle files lost for worker worker-20250831043001-172.18.0.4-33111 on host 172.18.0.4
[2025-08-31T04:39:47.344+0000] {job.py:219} ERROR - Job heartbeat got an exception
Traceback (most recent call last):
  File "/home/airflow/.local/lib/python3.10/site-packages/sqlalchemy/engine/base.py", line 3371, in _wrap_pool_connect
    return fn()
  File "/home/airflow/.local/lib/python3.10/site-packages/sqlalchemy/pool/base.py", line 327, in connect
    return _ConnectionFairy._checkout(self)
  File "/home/airflow/.local/lib/python3.10/site-packages/sqlalchemy/pool/base.py", line 894, in _checkout
    fairy = _ConnectionRecord.checkout(pool)
  File "/home/airflow/.local/lib/python3.10/site-packages/sqlalchemy/pool/base.py", line 493, in checkout
    rec = pool._do_get()
  File "/home/airflow/.local/lib/python3.10/site-packages/sqlalchemy/pool/impl.py", line 256, in _do_get
    return self._create_connection()
  File "/home/airflow/.local/lib/python3.10/site-packages/sqlalchemy/pool/base.py", line 273, in _create_connection
    return _ConnectionRecord(self)
  File "/home/airflow/.local/lib/python3.10/site-packages/sqlalchemy/pool/base.py", line 388, in __init__
    self.__connect()
  File "/home/airflow/.local/lib/python3.10/site-packages/sqlalchemy/pool/base.py", line 690, in __connect
    with util.safe_reraise():
  File "/home/airflow/.local/lib/python3.10/site-packages/sqlalchemy/util/langhelpers.py", line 70, in __exit__
    compat.raise_(
  File "/home/airflow/.local/lib/python3.10/site-packages/sqlalchemy/util/compat.py", line 211, in raise_
    raise exception
  File "/home/airflow/.local/lib/python3.10/site-packages/sqlalchemy/pool/base.py", line 686, in __connect
    self.dbapi_connection = connection = pool._invoke_creator(self)
  File "/home/airflow/.local/lib/python3.10/site-packages/sqlalchemy/engine/create.py", line 574, in connect
    return dialect.connect(*cargs, **cparams)
  File "/home/airflow/.local/lib/python3.10/site-packages/sqlalchemy/engine/default.py", line 598, in connect
    return self.dbapi.connect(*cargs, **cparams)
  File "/home/airflow/.local/lib/python3.10/site-packages/psycopg2/__init__.py", line 122, in connect
    conn = _connect(dsn, connection_factory=connection_factory, **kwasync)
psycopg2.OperationalError: could not translate host name "postgres" to address: Temporary failure in name resolution


The above exception was the direct cause of the following exception:

Traceback (most recent call last):
  File "/home/airflow/.local/lib/python3.10/site-packages/airflow/jobs/job.py", line 215, in heartbeat
    heartbeat_callback(session)
  File "/home/airflow/.local/lib/python3.10/site-packages/airflow/utils/session.py", line 74, in wrapper
    return func(*args, **kwargs)
  File "/home/airflow/.local/lib/python3.10/site-packages/airflow/jobs/local_task_job_runner.py", line 246, in heartbeat_callback
    self.task_instance.refresh_from_db()
  File "/home/airflow/.local/lib/python3.10/site-packages/airflow/utils/session.py", line 77, in wrapper
    return func(*args, session=session, **kwargs)
  File "/home/airflow/.local/lib/python3.10/site-packages/airflow/models/taskinstance.py", line 864, in refresh_from_db
    ti = qry.one_or_none()
  File "/home/airflow/.local/lib/python3.10/site-packages/sqlalchemy/orm/query.py", line 2850, in one_or_none
    return self._iter().one_or_none()
  File "/home/airflow/.local/lib/python3.10/site-packages/sqlalchemy/orm/query.py", line 2916, in _iter
    result = self.session.execute(
  File "/home/airflow/.local/lib/python3.10/site-packages/sqlalchemy/orm/session.py", line 1716, in execute
    conn = self._connection_for_bind(bind)
  File "/home/airflow/.local/lib/python3.10/site-packages/sqlalchemy/orm/session.py", line 1555, in _connection_for_bind
    return self._transaction._connection_for_bind(
  File "/home/airflow/.local/lib/python3.10/site-packages/sqlalchemy/orm/session.py", line 750, in _connection_for_bind
    conn = bind.connect()
  File "/home/airflow/.local/lib/python3.10/site-packages/sqlalchemy/future/engine.py", line 406, in connect
    return super(Engine, self).connect()
  File "/home/airflow/.local/lib/python3.10/site-packages/sqlalchemy/engine/base.py", line 3325, in connect
    return self._connection_cls(self, close_with_result=close_with_result)
  File "/home/airflow/.local/lib/python3.10/site-packages/sqlalchemy/engine/base.py", line 96, in __init__
    else engine.raw_connection()
  File "/home/airflow/.local/lib/python3.10/site-packages/sqlalchemy/engine/base.py", line 3404, in raw_connection
    return self._wrap_pool_connect(self.pool.connect, _connection)
  File "/home/airflow/.local/lib/python3.10/site-packages/sqlalchemy/engine/base.py", line 3374, in _wrap_pool_connect
    Connection._handle_dbapi_exception_noconnection(
  File "/home/airflow/.local/lib/python3.10/site-packages/sqlalchemy/engine/base.py", line 2208, in _handle_dbapi_exception_noconnection
    util.raise_(
  File "/home/airflow/.local/lib/python3.10/site-packages/sqlalchemy/util/compat.py", line 211, in raise_
    raise exception
  File "/home/airflow/.local/lib/python3.10/site-packages/sqlalchemy/engine/base.py", line 3371, in _wrap_pool_connect
    return fn()
  File "/home/airflow/.local/lib/python3.10/site-packages/sqlalchemy/pool/base.py", line 327, in connect
    return _ConnectionFairy._checkout(self)
  File "/home/airflow/.local/lib/python3.10/site-packages/sqlalchemy/pool/base.py", line 894, in _checkout
    fairy = _ConnectionRecord.checkout(pool)
  File "/home/airflow/.local/lib/python3.10/site-packages/sqlalchemy/pool/base.py", line 493, in checkout
    rec = pool._do_get()
  File "/home/airflow/.local/lib/python3.10/site-packages/sqlalchemy/pool/impl.py", line 256, in _do_get
    return self._create_connection()
  File "/home/airflow/.local/lib/python3.10/site-packages/sqlalchemy/pool/base.py", line 273, in _create_connection
    return _ConnectionRecord(self)
  File "/home/airflow/.local/lib/python3.10/site-packages/sqlalchemy/pool/base.py", line 388, in __init__
    self.__connect()
  File "/home/airflow/.local/lib/python3.10/site-packages/sqlalchemy/pool/base.py", line 690, in __connect
    with util.safe_reraise():
  File "/home/airflow/.local/lib/python3.10/site-packages/sqlalchemy/util/langhelpers.py", line 70, in __exit__
    compat.raise_(
  File "/home/airflow/.local/lib/python3.10/site-packages/sqlalchemy/util/compat.py", line 211, in raise_
    raise exception
  File "/home/airflow/.local/lib/python3.10/site-packages/sqlalchemy/pool/base.py", line 686, in __connect
    self.dbapi_connection = connection = pool._invoke_creator(self)
  File "/home/airflow/.local/lib/python3.10/site-packages/sqlalchemy/engine/create.py", line 574, in connect
    return dialect.connect(*cargs, **cparams)
  File "/home/airflow/.local/lib/python3.10/site-packages/sqlalchemy/engine/default.py", line 598, in connect
    return self.dbapi.connect(*cargs, **cparams)
  File "/home/airflow/.local/lib/python3.10/site-packages/psycopg2/__init__.py", line 122, in connect
    conn = _connect(dsn, connection_factory=connection_factory, **kwasync)
sqlalchemy.exc.OperationalError: (psycopg2.OperationalError) could not translate host name "postgres" to address: Temporary failure in name resolution

(Background on this error at: https://sqlalche.me/e/14/e3q8)
[2025-08-31T04:39:54.603+0000] {spark_submit.py:579} INFO - 25/08/31 04:39:54 INFO StandaloneAppClient$ClientEndpoint: Executor added: app-20250831043407-0001/0 on worker-20250831043001-172.18.0.4-33111 (172.18.0.4:33111) with 2 core(s)
[2025-08-31T04:39:54.660+0000] {spark_submit.py:579} INFO - 25/08/31 04:39:54 INFO StandaloneSchedulerBackend: Granted executor ID app-20250831043407-0001/0 on hostPort 172.18.0.4:33111 with 2 core(s), 1024.0 MiB RAM
[2025-08-31T04:39:55.223+0000] {spark_submit.py:579} INFO - 25/08/31 04:39:55 INFO StandaloneAppClient$ClientEndpoint: Executor updated: app-20250831043407-0001/0 is now RUNNING
[2025-08-31T04:39:57.908+0000] {job.py:219} ERROR - Job heartbeat got an exception
Traceback (most recent call last):
  File "/home/airflow/.local/lib/python3.10/site-packages/sqlalchemy/engine/base.py", line 3371, in _wrap_pool_connect
    return fn()
  File "/home/airflow/.local/lib/python3.10/site-packages/sqlalchemy/pool/base.py", line 327, in connect
    return _ConnectionFairy._checkout(self)
  File "/home/airflow/.local/lib/python3.10/site-packages/sqlalchemy/pool/base.py", line 894, in _checkout
    fairy = _ConnectionRecord.checkout(pool)
  File "/home/airflow/.local/lib/python3.10/site-packages/sqlalchemy/pool/base.py", line 493, in checkout
    rec = pool._do_get()
  File "/home/airflow/.local/lib/python3.10/site-packages/sqlalchemy/pool/impl.py", line 256, in _do_get
    return self._create_connection()
  File "/home/airflow/.local/lib/python3.10/site-packages/sqlalchemy/pool/base.py", line 273, in _create_connection
    return _ConnectionRecord(self)
  File "/home/airflow/.local/lib/python3.10/site-packages/sqlalchemy/pool/base.py", line 388, in __init__
    self.__connect()
  File "/home/airflow/.local/lib/python3.10/site-packages/sqlalchemy/pool/base.py", line 690, in __connect
    with util.safe_reraise():
  File "/home/airflow/.local/lib/python3.10/site-packages/sqlalchemy/util/langhelpers.py", line 70, in __exit__
    compat.raise_(
  File "/home/airflow/.local/lib/python3.10/site-packages/sqlalchemy/util/compat.py", line 211, in raise_
    raise exception
  File "/home/airflow/.local/lib/python3.10/site-packages/sqlalchemy/pool/base.py", line 686, in __connect
    self.dbapi_connection = connection = pool._invoke_creator(self)
  File "/home/airflow/.local/lib/python3.10/site-packages/sqlalchemy/engine/create.py", line 574, in connect
    return dialect.connect(*cargs, **cparams)
  File "/home/airflow/.local/lib/python3.10/site-packages/sqlalchemy/engine/default.py", line 598, in connect
    return self.dbapi.connect(*cargs, **cparams)
  File "/home/airflow/.local/lib/python3.10/site-packages/psycopg2/__init__.py", line 122, in connect
    conn = _connect(dsn, connection_factory=connection_factory, **kwasync)
psycopg2.OperationalError: could not translate host name "postgres" to address: Temporary failure in name resolution


The above exception was the direct cause of the following exception:

Traceback (most recent call last):
  File "/home/airflow/.local/lib/python3.10/site-packages/airflow/jobs/job.py", line 190, in heartbeat
    session.merge(self)
  File "/home/airflow/.local/lib/python3.10/site-packages/sqlalchemy/orm/session.py", line 3056, in merge
    return self._merge(
  File "/home/airflow/.local/lib/python3.10/site-packages/sqlalchemy/orm/session.py", line 3136, in _merge
    merged = self.get(
  File "/home/airflow/.local/lib/python3.10/site-packages/sqlalchemy/orm/session.py", line 2853, in get
    return self._get_impl(
  File "/home/airflow/.local/lib/python3.10/site-packages/sqlalchemy/orm/session.py", line 2975, in _get_impl
    return db_load_fn(
  File "/home/airflow/.local/lib/python3.10/site-packages/sqlalchemy/orm/loading.py", line 530, in load_on_pk_identity
    session.execute(
  File "/home/airflow/.local/lib/python3.10/site-packages/sqlalchemy/orm/session.py", line 1716, in execute
    conn = self._connection_for_bind(bind)
  File "/home/airflow/.local/lib/python3.10/site-packages/sqlalchemy/orm/session.py", line 1555, in _connection_for_bind
    return self._transaction._connection_for_bind(
  File "/home/airflow/.local/lib/python3.10/site-packages/sqlalchemy/orm/session.py", line 750, in _connection_for_bind
    conn = bind.connect()
  File "/home/airflow/.local/lib/python3.10/site-packages/sqlalchemy/future/engine.py", line 406, in connect
    return super(Engine, self).connect()
  File "/home/airflow/.local/lib/python3.10/site-packages/sqlalchemy/engine/base.py", line 3325, in connect
    return self._connection_cls(self, close_with_result=close_with_result)
  File "/home/airflow/.local/lib/python3.10/site-packages/sqlalchemy/engine/base.py", line 96, in __init__
    else engine.raw_connection()
  File "/home/airflow/.local/lib/python3.10/site-packages/sqlalchemy/engine/base.py", line 3404, in raw_connection
    return self._wrap_pool_connect(self.pool.connect, _connection)
  File "/home/airflow/.local/lib/python3.10/site-packages/sqlalchemy/engine/base.py", line 3374, in _wrap_pool_connect
    Connection._handle_dbapi_exception_noconnection(
  File "/home/airflow/.local/lib/python3.10/site-packages/sqlalchemy/engine/base.py", line 2208, in _handle_dbapi_exception_noconnection
    util.raise_(
  File "/home/airflow/.local/lib/python3.10/site-packages/sqlalchemy/util/compat.py", line 211, in raise_
    raise exception
  File "/home/airflow/.local/lib/python3.10/site-packages/sqlalchemy/engine/base.py", line 3371, in _wrap_pool_connect
    return fn()
  File "/home/airflow/.local/lib/python3.10/site-packages/sqlalchemy/pool/base.py", line 327, in connect
    return _ConnectionFairy._checkout(self)
  File "/home/airflow/.local/lib/python3.10/site-packages/sqlalchemy/pool/base.py", line 894, in _checkout
    fairy = _ConnectionRecord.checkout(pool)
  File "/home/airflow/.local/lib/python3.10/site-packages/sqlalchemy/pool/base.py", line 493, in checkout
    rec = pool._do_get()
  File "/home/airflow/.local/lib/python3.10/site-packages/sqlalchemy/pool/impl.py", line 256, in _do_get
    return self._create_connection()
  File "/home/airflow/.local/lib/python3.10/site-packages/sqlalchemy/pool/base.py", line 273, in _create_connection
    return _ConnectionRecord(self)
  File "/home/airflow/.local/lib/python3.10/site-packages/sqlalchemy/pool/base.py", line 388, in __init__
    self.__connect()
  File "/home/airflow/.local/lib/python3.10/site-packages/sqlalchemy/pool/base.py", line 690, in __connect
    with util.safe_reraise():
  File "/home/airflow/.local/lib/python3.10/site-packages/sqlalchemy/util/langhelpers.py", line 70, in __exit__
    compat.raise_(
  File "/home/airflow/.local/lib/python3.10/site-packages/sqlalchemy/util/compat.py", line 211, in raise_
    raise exception
  File "/home/airflow/.local/lib/python3.10/site-packages/sqlalchemy/pool/base.py", line 686, in __connect
    self.dbapi_connection = connection = pool._invoke_creator(self)
  File "/home/airflow/.local/lib/python3.10/site-packages/sqlalchemy/engine/create.py", line 574, in connect
    return dialect.connect(*cargs, **cparams)
  File "/home/airflow/.local/lib/python3.10/site-packages/sqlalchemy/engine/default.py", line 598, in connect
    return self.dbapi.connect(*cargs, **cparams)
  File "/home/airflow/.local/lib/python3.10/site-packages/psycopg2/__init__.py", line 122, in connect
    conn = _connect(dsn, connection_factory=connection_factory, **kwasync)
sqlalchemy.exc.OperationalError: (psycopg2.OperationalError) could not translate host name "postgres" to address: Temporary failure in name resolution

(Background on this error at: https://sqlalche.me/e/14/e3q8)
[2025-08-31T04:40:03.019+0000] {job.py:219} ERROR - Job heartbeat got an exception
Traceback (most recent call last):
  File "/home/airflow/.local/lib/python3.10/site-packages/sqlalchemy/engine/base.py", line 3371, in _wrap_pool_connect
    return fn()
  File "/home/airflow/.local/lib/python3.10/site-packages/sqlalchemy/pool/base.py", line 327, in connect
    return _ConnectionFairy._checkout(self)
  File "/home/airflow/.local/lib/python3.10/site-packages/sqlalchemy/pool/base.py", line 894, in _checkout
    fairy = _ConnectionRecord.checkout(pool)
  File "/home/airflow/.local/lib/python3.10/site-packages/sqlalchemy/pool/base.py", line 493, in checkout
    rec = pool._do_get()
  File "/home/airflow/.local/lib/python3.10/site-packages/sqlalchemy/pool/impl.py", line 256, in _do_get
    return self._create_connection()
  File "/home/airflow/.local/lib/python3.10/site-packages/sqlalchemy/pool/base.py", line 273, in _create_connection
    return _ConnectionRecord(self)
  File "/home/airflow/.local/lib/python3.10/site-packages/sqlalchemy/pool/base.py", line 388, in __init__
    self.__connect()
  File "/home/airflow/.local/lib/python3.10/site-packages/sqlalchemy/pool/base.py", line 690, in __connect
    with util.safe_reraise():
  File "/home/airflow/.local/lib/python3.10/site-packages/sqlalchemy/util/langhelpers.py", line 70, in __exit__
    compat.raise_(
  File "/home/airflow/.local/lib/python3.10/site-packages/sqlalchemy/util/compat.py", line 211, in raise_
    raise exception
  File "/home/airflow/.local/lib/python3.10/site-packages/sqlalchemy/pool/base.py", line 686, in __connect
    self.dbapi_connection = connection = pool._invoke_creator(self)
  File "/home/airflow/.local/lib/python3.10/site-packages/sqlalchemy/engine/create.py", line 574, in connect
    return dialect.connect(*cargs, **cparams)
  File "/home/airflow/.local/lib/python3.10/site-packages/sqlalchemy/engine/default.py", line 598, in connect
    return self.dbapi.connect(*cargs, **cparams)
  File "/home/airflow/.local/lib/python3.10/site-packages/psycopg2/__init__.py", line 122, in connect
    conn = _connect(dsn, connection_factory=connection_factory, **kwasync)
psycopg2.OperationalError: could not translate host name "postgres" to address: Temporary failure in name resolution


The above exception was the direct cause of the following exception:

Traceback (most recent call last):
  File "/home/airflow/.local/lib/python3.10/site-packages/airflow/jobs/job.py", line 190, in heartbeat
    session.merge(self)
  File "/home/airflow/.local/lib/python3.10/site-packages/sqlalchemy/orm/session.py", line 3056, in merge
    return self._merge(
  File "/home/airflow/.local/lib/python3.10/site-packages/sqlalchemy/orm/session.py", line 3136, in _merge
    merged = self.get(
  File "/home/airflow/.local/lib/python3.10/site-packages/sqlalchemy/orm/session.py", line 2853, in get
    return self._get_impl(
  File "/home/airflow/.local/lib/python3.10/site-packages/sqlalchemy/orm/session.py", line 2975, in _get_impl
    return db_load_fn(
  File "/home/airflow/.local/lib/python3.10/site-packages/sqlalchemy/orm/loading.py", line 530, in load_on_pk_identity
    session.execute(
  File "/home/airflow/.local/lib/python3.10/site-packages/sqlalchemy/orm/session.py", line 1716, in execute
    conn = self._connection_for_bind(bind)
  File "/home/airflow/.local/lib/python3.10/site-packages/sqlalchemy/orm/session.py", line 1555, in _connection_for_bind
    return self._transaction._connection_for_bind(
  File "/home/airflow/.local/lib/python3.10/site-packages/sqlalchemy/orm/session.py", line 750, in _connection_for_bind
    conn = bind.connect()
  File "/home/airflow/.local/lib/python3.10/site-packages/sqlalchemy/future/engine.py", line 406, in connect
    return super(Engine, self).connect()
  File "/home/airflow/.local/lib/python3.10/site-packages/sqlalchemy/engine/base.py", line 3325, in connect
    return self._connection_cls(self, close_with_result=close_with_result)
  File "/home/airflow/.local/lib/python3.10/site-packages/sqlalchemy/engine/base.py", line 96, in __init__
    else engine.raw_connection()
  File "/home/airflow/.local/lib/python3.10/site-packages/sqlalchemy/engine/base.py", line 3404, in raw_connection
    return self._wrap_pool_connect(self.pool.connect, _connection)
  File "/home/airflow/.local/lib/python3.10/site-packages/sqlalchemy/engine/base.py", line 3374, in _wrap_pool_connect
    Connection._handle_dbapi_exception_noconnection(
  File "/home/airflow/.local/lib/python3.10/site-packages/sqlalchemy/engine/base.py", line 2208, in _handle_dbapi_exception_noconnection
    util.raise_(
  File "/home/airflow/.local/lib/python3.10/site-packages/sqlalchemy/util/compat.py", line 211, in raise_
    raise exception
  File "/home/airflow/.local/lib/python3.10/site-packages/sqlalchemy/engine/base.py", line 3371, in _wrap_pool_connect
    return fn()
  File "/home/airflow/.local/lib/python3.10/site-packages/sqlalchemy/pool/base.py", line 327, in connect
    return _ConnectionFairy._checkout(self)
  File "/home/airflow/.local/lib/python3.10/site-packages/sqlalchemy/pool/base.py", line 894, in _checkout
    fairy = _ConnectionRecord.checkout(pool)
  File "/home/airflow/.local/lib/python3.10/site-packages/sqlalchemy/pool/base.py", line 493, in checkout
    rec = pool._do_get()
  File "/home/airflow/.local/lib/python3.10/site-packages/sqlalchemy/pool/impl.py", line 256, in _do_get
    return self._create_connection()
  File "/home/airflow/.local/lib/python3.10/site-packages/sqlalchemy/pool/base.py", line 273, in _create_connection
    return _ConnectionRecord(self)
  File "/home/airflow/.local/lib/python3.10/site-packages/sqlalchemy/pool/base.py", line 388, in __init__
    self.__connect()
  File "/home/airflow/.local/lib/python3.10/site-packages/sqlalchemy/pool/base.py", line 690, in __connect
    with util.safe_reraise():
  File "/home/airflow/.local/lib/python3.10/site-packages/sqlalchemy/util/langhelpers.py", line 70, in __exit__
    compat.raise_(
  File "/home/airflow/.local/lib/python3.10/site-packages/sqlalchemy/util/compat.py", line 211, in raise_
    raise exception
  File "/home/airflow/.local/lib/python3.10/site-packages/sqlalchemy/pool/base.py", line 686, in __connect
    self.dbapi_connection = connection = pool._invoke_creator(self)
  File "/home/airflow/.local/lib/python3.10/site-packages/sqlalchemy/engine/create.py", line 574, in connect
    return dialect.connect(*cargs, **cparams)
  File "/home/airflow/.local/lib/python3.10/site-packages/sqlalchemy/engine/default.py", line 598, in connect
    return self.dbapi.connect(*cargs, **cparams)
  File "/home/airflow/.local/lib/python3.10/site-packages/psycopg2/__init__.py", line 122, in connect
    conn = _connect(dsn, connection_factory=connection_factory, **kwasync)
sqlalchemy.exc.OperationalError: (psycopg2.OperationalError) could not translate host name "postgres" to address: Temporary failure in name resolution

(Background on this error at: https://sqlalche.me/e/14/e3q8)
[2025-08-31T04:40:03.246+0000] {spark_submit.py:579} INFO - Traceback (most recent call last):
[2025-08-31T04:40:03.277+0000] {spark_submit.py:579} INFO - File "/home/***/.local/lib/python3.10/site-packages/urllib3/connection.py", line 174, in _new_conn
[2025-08-31T04:40:03.287+0000] {spark_submit.py:579} INFO - conn = connection.create_connection(
[2025-08-31T04:40:03.287+0000] {spark_submit.py:579} INFO - File "/home/***/.local/lib/python3.10/site-packages/urllib3/util/connection.py", line 72, in create_connection
[2025-08-31T04:40:03.288+0000] {spark_submit.py:579} INFO - for res in socket.getaddrinfo(host, port, family, socket.SOCK_STREAM):
[2025-08-31T04:40:03.288+0000] {spark_submit.py:579} INFO - File "/usr/local/lib/python3.10/socket.py", line 955, in getaddrinfo
[2025-08-31T04:40:03.288+0000] {spark_submit.py:579} INFO - for res in _socket.getaddrinfo(host, port, family, type, proto, flags):
[2025-08-31T04:40:03.289+0000] {spark_submit.py:579} INFO - socket.gaierror: [Errno -3] Temporary failure in name resolution
[2025-08-31T04:40:03.289+0000] {spark_submit.py:579} INFO - 
[2025-08-31T04:40:03.289+0000] {spark_submit.py:579} INFO - During handling of the above exception, another exception occurred:
[2025-08-31T04:40:03.290+0000] {spark_submit.py:579} INFO - 
[2025-08-31T04:40:03.290+0000] {spark_submit.py:579} INFO - Traceback (most recent call last):
[2025-08-31T04:40:03.290+0000] {spark_submit.py:579} INFO - File "/home/***/.local/lib/python3.10/site-packages/urllib3/connectionpool.py", line 714, in urlopen
[2025-08-31T04:40:03.290+0000] {spark_submit.py:579} INFO - httplib_response = self._make_request(
[2025-08-31T04:40:03.291+0000] {spark_submit.py:579} INFO - File "/home/***/.local/lib/python3.10/site-packages/urllib3/connectionpool.py", line 403, in _make_request
[2025-08-31T04:40:03.291+0000] {spark_submit.py:579} INFO - self._validate_conn(conn)
[2025-08-31T04:40:03.292+0000] {spark_submit.py:579} INFO - File "/home/***/.local/lib/python3.10/site-packages/urllib3/connectionpool.py", line 1053, in _validate_conn
[2025-08-31T04:40:03.292+0000] {spark_submit.py:579} INFO - conn.connect()
[2025-08-31T04:40:03.292+0000] {spark_submit.py:579} INFO - File "/home/***/.local/lib/python3.10/site-packages/urllib3/connection.py", line 363, in connect
[2025-08-31T04:40:03.293+0000] {spark_submit.py:579} INFO - self.sock = conn = self._new_conn()
[2025-08-31T04:40:03.296+0000] {spark_submit.py:579} INFO - File "/home/***/.local/lib/python3.10/site-packages/urllib3/connection.py", line 186, in _new_conn
[2025-08-31T04:40:03.296+0000] {spark_submit.py:579} INFO - raise NewConnectionError(
[2025-08-31T04:40:03.297+0000] {spark_submit.py:579} INFO - urllib3.exceptions.NewConnectionError: <urllib3.connection.HTTPSConnection object at 0x76d7debda050>: Failed to establish a new connection: [Errno -3] Temporary failure in name resolution
[2025-08-31T04:40:03.297+0000] {spark_submit.py:579} INFO - 
[2025-08-31T04:40:03.298+0000] {spark_submit.py:579} INFO - During handling of the above exception, another exception occurred:
[2025-08-31T04:40:03.298+0000] {spark_submit.py:579} INFO - 
[2025-08-31T04:40:03.299+0000] {spark_submit.py:579} INFO - Traceback (most recent call last):
[2025-08-31T04:40:03.299+0000] {spark_submit.py:579} INFO - File "/home/***/.local/lib/python3.10/site-packages/requests/adapters.py", line 486, in send
[2025-08-31T04:40:03.300+0000] {spark_submit.py:579} INFO - resp = conn.urlopen(
[2025-08-31T04:40:03.300+0000] {spark_submit.py:579} INFO - File "/home/***/.local/lib/python3.10/site-packages/urllib3/connectionpool.py", line 798, in urlopen
[2025-08-31T04:40:03.300+0000] {spark_submit.py:579} INFO - retries = retries.increment(
[2025-08-31T04:40:03.301+0000] {spark_submit.py:579} INFO - File "/home/***/.local/lib/python3.10/site-packages/urllib3/util/retry.py", line 592, in increment
[2025-08-31T04:40:03.301+0000] {spark_submit.py:579} INFO - raise MaxRetryError(_pool, url, error or ResponseError(cause))
[2025-08-31T04:40:03.302+0000] {spark_submit.py:579} INFO - urllib3.exceptions.MaxRetryError: HTTPSConnectionPool(host='api.chess.com', port=443): Max retries exceeded with url: /pub/leaderboards (Caused by NewConnectionError('<urllib3.connection.HTTPSConnection object at 0x76d7debda050>: Failed to establish a new connection: [Errno -3] Temporary failure in name resolution'))
[2025-08-31T04:40:03.306+0000] {spark_submit.py:579} INFO - 
[2025-08-31T04:40:03.307+0000] {spark_submit.py:579} INFO - During handling of the above exception, another exception occurred:
[2025-08-31T04:40:03.307+0000] {spark_submit.py:579} INFO - 
[2025-08-31T04:40:03.308+0000] {spark_submit.py:579} INFO - Traceback (most recent call last):
[2025-08-31T04:40:03.308+0000] {spark_submit.py:579} INFO - File "/opt/***/jobs/python/wordcountjob.py", line 32, in <module>
[2025-08-31T04:40:03.309+0000] {spark_submit.py:579} INFO - response = requests.get(url, headers=headers)
[2025-08-31T04:40:03.309+0000] {spark_submit.py:579} INFO - File "/home/***/.local/lib/python3.10/site-packages/requests/api.py", line 73, in get
[2025-08-31T04:40:03.310+0000] {spark_submit.py:579} INFO - return request("get", url, params=params, **kwargs)
[2025-08-31T04:40:03.311+0000] {spark_submit.py:579} INFO - File "/home/***/.local/lib/python3.10/site-packages/requests/api.py", line 59, in request
[2025-08-31T04:40:03.311+0000] {spark_submit.py:579} INFO - return session.request(method=method, url=url, **kwargs)
[2025-08-31T04:40:03.311+0000] {spark_submit.py:579} INFO - File "/home/***/.local/lib/python3.10/site-packages/requests/sessions.py", line 589, in request
[2025-08-31T04:40:03.313+0000] {spark_submit.py:579} INFO - resp = self.send(prep, **send_kwargs)
[2025-08-31T04:40:03.313+0000] {spark_submit.py:579} INFO - File "/home/***/.local/lib/python3.10/site-packages/requests/sessions.py", line 703, in send
[2025-08-31T04:40:03.315+0000] {spark_submit.py:579} INFO - r = adapter.send(request, **kwargs)
[2025-08-31T04:40:03.317+0000] {spark_submit.py:579} INFO - File "/home/***/.local/lib/python3.10/site-packages/requests/adapters.py", line 519, in send
[2025-08-31T04:40:03.317+0000] {spark_submit.py:579} INFO - raise ConnectionError(e, request=request)
[2025-08-31T04:40:03.318+0000] {spark_submit.py:579} INFO - requests.exceptions.ConnectionError: HTTPSConnectionPool(host='api.chess.com', port=443): Max retries exceeded with url: /pub/leaderboards (Caused by NewConnectionError('<urllib3.connection.HTTPSConnection object at 0x76d7debda050>: Failed to establish a new connection: [Errno -3] Temporary failure in name resolution'))
[2025-08-31T04:40:03.835+0000] {spark_submit.py:579} INFO - 25/08/31 04:40:03 INFO StandaloneAppClient$ClientEndpoint: Executor updated: app-20250831043407-0001/0 is now EXITED (Command exited with code 1)
[2025-08-31T04:40:03.840+0000] {spark_submit.py:579} INFO - 25/08/31 04:40:03 INFO StandaloneSchedulerBackend: Executor app-20250831043407-0001/0 removed: Command exited with code 1
[2025-08-31T04:40:03.862+0000] {spark_submit.py:579} INFO - 25/08/31 04:40:03 INFO BlockManagerMaster: Removal of executor 0 requested
[2025-08-31T04:40:03.865+0000] {spark_submit.py:579} INFO - 25/08/31 04:40:03 INFO StandaloneSchedulerBackend$StandaloneDriverEndpoint: Asked to remove non-existent executor 0
[2025-08-31T04:40:03.867+0000] {spark_submit.py:579} INFO - 25/08/31 04:40:03 INFO StandaloneAppClient$ClientEndpoint: Executor added: app-20250831043407-0001/1 on worker-20250831043001-172.18.0.4-33111 (172.18.0.4:33111) with 2 core(s)
[2025-08-31T04:40:03.869+0000] {spark_submit.py:579} INFO - 25/08/31 04:40:03 INFO StandaloneSchedulerBackend: Granted executor ID app-20250831043407-0001/1 on hostPort 172.18.0.4:33111 with 2 core(s), 1024.0 MiB RAM
[2025-08-31T04:40:03.888+0000] {spark_submit.py:579} INFO - 25/08/31 04:40:03 INFO BlockManagerMasterEndpoint: Trying to remove executor 0 from BlockManagerMaster.
[2025-08-31T04:40:04.180+0000] {spark_submit.py:579} INFO - 25/08/31 04:40:04 INFO StandaloneAppClient$ClientEndpoint: Executor updated: app-20250831043407-0001/1 is now RUNNING
[2025-08-31T04:40:08.087+0000] {job.py:219} ERROR - Job heartbeat got an exception
Traceback (most recent call last):
  File "/home/airflow/.local/lib/python3.10/site-packages/sqlalchemy/engine/base.py", line 3371, in _wrap_pool_connect
    return fn()
  File "/home/airflow/.local/lib/python3.10/site-packages/sqlalchemy/pool/base.py", line 327, in connect
    return _ConnectionFairy._checkout(self)
  File "/home/airflow/.local/lib/python3.10/site-packages/sqlalchemy/pool/base.py", line 894, in _checkout
    fairy = _ConnectionRecord.checkout(pool)
  File "/home/airflow/.local/lib/python3.10/site-packages/sqlalchemy/pool/base.py", line 493, in checkout
    rec = pool._do_get()
  File "/home/airflow/.local/lib/python3.10/site-packages/sqlalchemy/pool/impl.py", line 256, in _do_get
    return self._create_connection()
  File "/home/airflow/.local/lib/python3.10/site-packages/sqlalchemy/pool/base.py", line 273, in _create_connection
    return _ConnectionRecord(self)
  File "/home/airflow/.local/lib/python3.10/site-packages/sqlalchemy/pool/base.py", line 388, in __init__
    self.__connect()
  File "/home/airflow/.local/lib/python3.10/site-packages/sqlalchemy/pool/base.py", line 690, in __connect
    with util.safe_reraise():
  File "/home/airflow/.local/lib/python3.10/site-packages/sqlalchemy/util/langhelpers.py", line 70, in __exit__
    compat.raise_(
  File "/home/airflow/.local/lib/python3.10/site-packages/sqlalchemy/util/compat.py", line 211, in raise_
    raise exception
  File "/home/airflow/.local/lib/python3.10/site-packages/sqlalchemy/pool/base.py", line 686, in __connect
    self.dbapi_connection = connection = pool._invoke_creator(self)
  File "/home/airflow/.local/lib/python3.10/site-packages/sqlalchemy/engine/create.py", line 574, in connect
    return dialect.connect(*cargs, **cparams)
  File "/home/airflow/.local/lib/python3.10/site-packages/sqlalchemy/engine/default.py", line 598, in connect
    return self.dbapi.connect(*cargs, **cparams)
  File "/home/airflow/.local/lib/python3.10/site-packages/psycopg2/__init__.py", line 122, in connect
    conn = _connect(dsn, connection_factory=connection_factory, **kwasync)
psycopg2.OperationalError: could not translate host name "postgres" to address: Temporary failure in name resolution


The above exception was the direct cause of the following exception:

Traceback (most recent call last):
  File "/home/airflow/.local/lib/python3.10/site-packages/airflow/jobs/job.py", line 190, in heartbeat
    session.merge(self)
  File "/home/airflow/.local/lib/python3.10/site-packages/sqlalchemy/orm/session.py", line 3056, in merge
    return self._merge(
  File "/home/airflow/.local/lib/python3.10/site-packages/sqlalchemy/orm/session.py", line 3136, in _merge
    merged = self.get(
  File "/home/airflow/.local/lib/python3.10/site-packages/sqlalchemy/orm/session.py", line 2853, in get
    return self._get_impl(
  File "/home/airflow/.local/lib/python3.10/site-packages/sqlalchemy/orm/session.py", line 2975, in _get_impl
    return db_load_fn(
  File "/home/airflow/.local/lib/python3.10/site-packages/sqlalchemy/orm/loading.py", line 530, in load_on_pk_identity
    session.execute(
  File "/home/airflow/.local/lib/python3.10/site-packages/sqlalchemy/orm/session.py", line 1716, in execute
    conn = self._connection_for_bind(bind)
  File "/home/airflow/.local/lib/python3.10/site-packages/sqlalchemy/orm/session.py", line 1555, in _connection_for_bind
    return self._transaction._connection_for_bind(
  File "/home/airflow/.local/lib/python3.10/site-packages/sqlalchemy/orm/session.py", line 750, in _connection_for_bind
    conn = bind.connect()
  File "/home/airflow/.local/lib/python3.10/site-packages/sqlalchemy/future/engine.py", line 406, in connect
    return super(Engine, self).connect()
  File "/home/airflow/.local/lib/python3.10/site-packages/sqlalchemy/engine/base.py", line 3325, in connect
    return self._connection_cls(self, close_with_result=close_with_result)
  File "/home/airflow/.local/lib/python3.10/site-packages/sqlalchemy/engine/base.py", line 96, in __init__
    else engine.raw_connection()
  File "/home/airflow/.local/lib/python3.10/site-packages/sqlalchemy/engine/base.py", line 3404, in raw_connection
    return self._wrap_pool_connect(self.pool.connect, _connection)
  File "/home/airflow/.local/lib/python3.10/site-packages/sqlalchemy/engine/base.py", line 3374, in _wrap_pool_connect
    Connection._handle_dbapi_exception_noconnection(
  File "/home/airflow/.local/lib/python3.10/site-packages/sqlalchemy/engine/base.py", line 2208, in _handle_dbapi_exception_noconnection
    util.raise_(
  File "/home/airflow/.local/lib/python3.10/site-packages/sqlalchemy/util/compat.py", line 211, in raise_
    raise exception
  File "/home/airflow/.local/lib/python3.10/site-packages/sqlalchemy/engine/base.py", line 3371, in _wrap_pool_connect
    return fn()
  File "/home/airflow/.local/lib/python3.10/site-packages/sqlalchemy/pool/base.py", line 327, in connect
    return _ConnectionFairy._checkout(self)
  File "/home/airflow/.local/lib/python3.10/site-packages/sqlalchemy/pool/base.py", line 894, in _checkout
    fairy = _ConnectionRecord.checkout(pool)
  File "/home/airflow/.local/lib/python3.10/site-packages/sqlalchemy/pool/base.py", line 493, in checkout
    rec = pool._do_get()
  File "/home/airflow/.local/lib/python3.10/site-packages/sqlalchemy/pool/impl.py", line 256, in _do_get
    return self._create_connection()
  File "/home/airflow/.local/lib/python3.10/site-packages/sqlalchemy/pool/base.py", line 273, in _create_connection
    return _ConnectionRecord(self)
  File "/home/airflow/.local/lib/python3.10/site-packages/sqlalchemy/pool/base.py", line 388, in __init__
    self.__connect()
  File "/home/airflow/.local/lib/python3.10/site-packages/sqlalchemy/pool/base.py", line 690, in __connect
    with util.safe_reraise():
  File "/home/airflow/.local/lib/python3.10/site-packages/sqlalchemy/util/langhelpers.py", line 70, in __exit__
    compat.raise_(
  File "/home/airflow/.local/lib/python3.10/site-packages/sqlalchemy/util/compat.py", line 211, in raise_
    raise exception
  File "/home/airflow/.local/lib/python3.10/site-packages/sqlalchemy/pool/base.py", line 686, in __connect
    self.dbapi_connection = connection = pool._invoke_creator(self)
  File "/home/airflow/.local/lib/python3.10/site-packages/sqlalchemy/engine/create.py", line 574, in connect
    return dialect.connect(*cargs, **cparams)
  File "/home/airflow/.local/lib/python3.10/site-packages/sqlalchemy/engine/default.py", line 598, in connect
    return self.dbapi.connect(*cargs, **cparams)
  File "/home/airflow/.local/lib/python3.10/site-packages/psycopg2/__init__.py", line 122, in connect
    conn = _connect(dsn, connection_factory=connection_factory, **kwasync)
sqlalchemy.exc.OperationalError: (psycopg2.OperationalError) could not translate host name "postgres" to address: Temporary failure in name resolution

(Background on this error at: https://sqlalche.me/e/14/e3q8)
[2025-08-31T04:40:08.324+0000] {spark_submit.py:579} INFO - 25/08/31 04:40:08 INFO StandaloneAppClient$ClientEndpoint: Executor updated: app-20250831043407-0001/1 is now EXITED (Command exited with code 1)
[2025-08-31T04:40:08.325+0000] {spark_submit.py:579} INFO - 25/08/31 04:40:08 INFO StandaloneSchedulerBackend: Executor app-20250831043407-0001/1 removed: Command exited with code 1
[2025-08-31T04:40:08.327+0000] {spark_submit.py:579} INFO - 25/08/31 04:40:08 INFO StandaloneAppClient$ClientEndpoint: Executor added: app-20250831043407-0001/2 on worker-20250831043001-172.18.0.4-33111 (172.18.0.4:33111) with 2 core(s)
[2025-08-31T04:40:08.327+0000] {spark_submit.py:579} INFO - 25/08/31 04:40:08 INFO BlockManagerMasterEndpoint: Trying to remove executor 1 from BlockManagerMaster.
[2025-08-31T04:40:08.328+0000] {spark_submit.py:579} INFO - 25/08/31 04:40:08 INFO BlockManagerMaster: Removal of executor 1 requested
[2025-08-31T04:40:08.328+0000] {spark_submit.py:579} INFO - 25/08/31 04:40:08 INFO StandaloneSchedulerBackend$StandaloneDriverEndpoint: Asked to remove non-existent executor 1
[2025-08-31T04:40:08.328+0000] {spark_submit.py:579} INFO - 25/08/31 04:40:08 INFO StandaloneSchedulerBackend: Granted executor ID app-20250831043407-0001/2 on hostPort 172.18.0.4:33111 with 2 core(s), 1024.0 MiB RAM
[2025-08-31T04:40:08.717+0000] {spark_submit.py:579} INFO - 25/08/31 04:40:08 INFO StandaloneAppClient$ClientEndpoint: Executor updated: app-20250831043407-0001/2 is now RUNNING
[2025-08-31T04:40:08.992+0000] {spark_submit.py:579} INFO - 25/08/31 04:40:08 INFO SparkContext: Invoking stop() from shutdown hook
[2025-08-31T04:40:09.019+0000] {spark_submit.py:579} INFO - 25/08/31 04:40:09 INFO SparkContext: SparkContext is stopping with exitCode 0 from run at Executors.java:539.
[2025-08-31T04:40:09.164+0000] {spark_submit.py:579} INFO - 25/08/31 04:40:09 INFO SparkUI: Stopped Spark web UI at http://81b7fe425a18:4049
[2025-08-31T04:40:09.194+0000] {spark_submit.py:579} INFO - 25/08/31 04:40:09 INFO StandaloneSchedulerBackend: Shutting down all executors
[2025-08-31T04:40:09.211+0000] {spark_submit.py:579} INFO - 25/08/31 04:40:09 INFO StandaloneSchedulerBackend$StandaloneDriverEndpoint: Asking each executor to shut down
[2025-08-31T04:40:09.285+0000] {spark_submit.py:579} INFO - 25/08/31 04:40:09 INFO MapOutputTrackerMasterEndpoint: MapOutputTrackerMasterEndpoint stopped!
[2025-08-31T04:40:09.400+0000] {spark_submit.py:579} INFO - 25/08/31 04:40:09 INFO MemoryStore: MemoryStore started with capacity 434.4 MiB
[2025-08-31T04:40:09.406+0000] {spark_submit.py:579} INFO - 25/08/31 04:40:09 INFO MemoryStore: MemoryStore cleared
[2025-08-31T04:40:09.406+0000] {spark_submit.py:579} INFO - 25/08/31 04:40:09 INFO BlockManager: BlockManager stopped
[2025-08-31T04:40:09.411+0000] {spark_submit.py:579} INFO - 25/08/31 04:40:09 INFO BlockManagerMaster: BlockManagerMaster stopped
[2025-08-31T04:40:09.417+0000] {spark_submit.py:579} INFO - 25/08/31 04:40:09 INFO OutputCommitCoordinator$OutputCommitCoordinatorEndpoint: OutputCommitCoordinator stopped!
[2025-08-31T04:40:09.460+0000] {spark_submit.py:579} INFO - 25/08/31 04:40:09 INFO SparkContext: Successfully stopped SparkContext
[2025-08-31T04:40:09.460+0000] {spark_submit.py:579} INFO - 25/08/31 04:40:09 INFO ShutdownHookManager: Shutdown hook called
[2025-08-31T04:40:09.462+0000] {spark_submit.py:579} INFO - 25/08/31 04:40:09 INFO ShutdownHookManager: Deleting directory /tmp/spark-fd9f44de-46ff-47f3-a652-52667773f597/pyspark-d312ee70-caf3-4e8c-811a-47069578351d
[2025-08-31T04:40:09.511+0000] {spark_submit.py:579} INFO - 25/08/31 04:40:09 INFO ShutdownHookManager: Deleting directory /tmp/spark-9cdbddc0-bada-4b1a-94c5-4c83609fa0c3
[2025-08-31T04:40:09.534+0000] {spark_submit.py:579} INFO - 25/08/31 04:40:09 INFO ShutdownHookManager: Deleting directory /tmp/spark-fd9f44de-46ff-47f3-a652-52667773f597
[2025-08-31T04:40:11.271+0000] {standard_task_runner.py:104} ERROR - Failed to execute job 90 for task python_job ((psycopg2.OperationalError) could not translate host name "postgres" to address: Temporary failure in name resolution

(Background on this error at: https://sqlalche.me/e/14/e3q8); 598)
[2025-08-31T04:40:11.418+0000] {local_task_job_runner.py:228} INFO - Task exited with return code 1
[2025-08-31T04:40:11.503+0000] {taskinstance.py:2782} INFO - Skipping mini scheduling run due to exception: None
Traceback (most recent call last):
  File "/home/airflow/.local/lib/python3.10/site-packages/sqlalchemy/engine/base.py", line 3371, in _wrap_pool_connect
    return fn()
  File "/home/airflow/.local/lib/python3.10/site-packages/sqlalchemy/pool/base.py", line 327, in connect
    return _ConnectionFairy._checkout(self)
  File "/home/airflow/.local/lib/python3.10/site-packages/sqlalchemy/pool/base.py", line 894, in _checkout
    fairy = _ConnectionRecord.checkout(pool)
  File "/home/airflow/.local/lib/python3.10/site-packages/sqlalchemy/pool/base.py", line 493, in checkout
    rec = pool._do_get()
  File "/home/airflow/.local/lib/python3.10/site-packages/sqlalchemy/pool/impl.py", line 256, in _do_get
    return self._create_connection()
  File "/home/airflow/.local/lib/python3.10/site-packages/sqlalchemy/pool/base.py", line 273, in _create_connection
    return _ConnectionRecord(self)
  File "/home/airflow/.local/lib/python3.10/site-packages/sqlalchemy/pool/base.py", line 388, in __init__
    self.__connect()
  File "/home/airflow/.local/lib/python3.10/site-packages/sqlalchemy/pool/base.py", line 690, in __connect
    with util.safe_reraise():
  File "/home/airflow/.local/lib/python3.10/site-packages/sqlalchemy/util/langhelpers.py", line 70, in __exit__
    compat.raise_(
  File "/home/airflow/.local/lib/python3.10/site-packages/sqlalchemy/util/compat.py", line 211, in raise_
    raise exception
  File "/home/airflow/.local/lib/python3.10/site-packages/sqlalchemy/pool/base.py", line 686, in __connect
    self.dbapi_connection = connection = pool._invoke_creator(self)
  File "/home/airflow/.local/lib/python3.10/site-packages/sqlalchemy/engine/create.py", line 574, in connect
    return dialect.connect(*cargs, **cparams)
  File "/home/airflow/.local/lib/python3.10/site-packages/sqlalchemy/engine/default.py", line 598, in connect
    return self.dbapi.connect(*cargs, **cparams)
  File "/home/airflow/.local/lib/python3.10/site-packages/psycopg2/__init__.py", line 122, in connect
    conn = _connect(dsn, connection_factory=connection_factory, **kwasync)
psycopg2.OperationalError: could not translate host name "postgres" to address: Temporary failure in name resolution


The above exception was the direct cause of the following exception:

Traceback (most recent call last):
  File "/home/airflow/.local/lib/python3.10/site-packages/airflow/models/taskinstance.py", line 2737, in schedule_downstream_tasks
    ).one()
  File "/home/airflow/.local/lib/python3.10/site-packages/sqlalchemy/orm/query.py", line 2870, in one
    return self._iter().one()
  File "/home/airflow/.local/lib/python3.10/site-packages/sqlalchemy/orm/query.py", line 2916, in _iter
    result = self.session.execute(
  File "/home/airflow/.local/lib/python3.10/site-packages/sqlalchemy/orm/session.py", line 1716, in execute
    conn = self._connection_for_bind(bind)
  File "/home/airflow/.local/lib/python3.10/site-packages/sqlalchemy/orm/session.py", line 1555, in _connection_for_bind
    return self._transaction._connection_for_bind(
  File "/home/airflow/.local/lib/python3.10/site-packages/sqlalchemy/orm/session.py", line 750, in _connection_for_bind
    conn = bind.connect()
  File "/home/airflow/.local/lib/python3.10/site-packages/sqlalchemy/future/engine.py", line 406, in connect
    return super(Engine, self).connect()
  File "/home/airflow/.local/lib/python3.10/site-packages/sqlalchemy/engine/base.py", line 3325, in connect
    return self._connection_cls(self, close_with_result=close_with_result)
  File "/home/airflow/.local/lib/python3.10/site-packages/sqlalchemy/engine/base.py", line 96, in __init__
    else engine.raw_connection()
  File "/home/airflow/.local/lib/python3.10/site-packages/sqlalchemy/engine/base.py", line 3404, in raw_connection
    return self._wrap_pool_connect(self.pool.connect, _connection)
  File "/home/airflow/.local/lib/python3.10/site-packages/sqlalchemy/engine/base.py", line 3374, in _wrap_pool_connect
    Connection._handle_dbapi_exception_noconnection(
  File "/home/airflow/.local/lib/python3.10/site-packages/sqlalchemy/engine/base.py", line 2208, in _handle_dbapi_exception_noconnection
    util.raise_(
  File "/home/airflow/.local/lib/python3.10/site-packages/sqlalchemy/util/compat.py", line 211, in raise_
    raise exception
  File "/home/airflow/.local/lib/python3.10/site-packages/sqlalchemy/engine/base.py", line 3371, in _wrap_pool_connect
    return fn()
  File "/home/airflow/.local/lib/python3.10/site-packages/sqlalchemy/pool/base.py", line 327, in connect
    return _ConnectionFairy._checkout(self)
  File "/home/airflow/.local/lib/python3.10/site-packages/sqlalchemy/pool/base.py", line 894, in _checkout
    fairy = _ConnectionRecord.checkout(pool)
  File "/home/airflow/.local/lib/python3.10/site-packages/sqlalchemy/pool/base.py", line 493, in checkout
    rec = pool._do_get()
  File "/home/airflow/.local/lib/python3.10/site-packages/sqlalchemy/pool/impl.py", line 256, in _do_get
    return self._create_connection()
  File "/home/airflow/.local/lib/python3.10/site-packages/sqlalchemy/pool/base.py", line 273, in _create_connection
    return _ConnectionRecord(self)
  File "/home/airflow/.local/lib/python3.10/site-packages/sqlalchemy/pool/base.py", line 388, in __init__
    self.__connect()
  File "/home/airflow/.local/lib/python3.10/site-packages/sqlalchemy/pool/base.py", line 690, in __connect
    with util.safe_reraise():
  File "/home/airflow/.local/lib/python3.10/site-packages/sqlalchemy/util/langhelpers.py", line 70, in __exit__
    compat.raise_(
  File "/home/airflow/.local/lib/python3.10/site-packages/sqlalchemy/util/compat.py", line 211, in raise_
    raise exception
  File "/home/airflow/.local/lib/python3.10/site-packages/sqlalchemy/pool/base.py", line 686, in __connect
    self.dbapi_connection = connection = pool._invoke_creator(self)
  File "/home/airflow/.local/lib/python3.10/site-packages/sqlalchemy/engine/create.py", line 574, in connect
    return dialect.connect(*cargs, **cparams)
  File "/home/airflow/.local/lib/python3.10/site-packages/sqlalchemy/engine/default.py", line 598, in connect
    return self.dbapi.connect(*cargs, **cparams)
  File "/home/airflow/.local/lib/python3.10/site-packages/psycopg2/__init__.py", line 122, in connect
    conn = _connect(dsn, connection_factory=connection_factory, **kwasync)
sqlalchemy.exc.OperationalError: (psycopg2.OperationalError) could not translate host name "postgres" to address: Temporary failure in name resolution

(Background on this error at: https://sqlalche.me/e/14/e3q8)
[2025-08-31T05:06:43.732+0000] {taskinstance.py:1157} INFO - Dependencies all met for dep_context=non-requeueable deps ti=<TaskInstance: sparking_flow.python_job scheduled__2025-08-31T02:00:00+00:00 [queued]>
[2025-08-31T05:06:43.783+0000] {taskinstance.py:1157} INFO - Dependencies all met for dep_context=requeueable deps ti=<TaskInstance: sparking_flow.python_job scheduled__2025-08-31T02:00:00+00:00 [queued]>
[2025-08-31T05:06:43.785+0000] {taskinstance.py:1359} INFO - Starting attempt 1 of 1
[2025-08-31T05:06:43.882+0000] {taskinstance.py:1380} INFO - Executing <Task(SparkSubmitOperator): python_job> on 2025-08-31 02:00:00+00:00
[2025-08-31T05:06:43.926+0000] {standard_task_runner.py:57} INFO - Started process 454 to run task
[2025-08-31T05:06:44.021+0000] {standard_task_runner.py:84} INFO - Running: ['***', 'tasks', 'run', 'sparking_flow', 'python_job', 'scheduled__2025-08-31T02:00:00+00:00', '--job-id', '30', '--raw', '--subdir', 'DAGS_FOLDER/spark_***.py', '--cfg-path', '/tmp/tmpywsxhugl']
[2025-08-31T05:06:44.064+0000] {standard_task_runner.py:85} INFO - Job 30: Subtask python_job
[2025-08-31T05:06:44.582+0000] {task_command.py:415} INFO - Running <TaskInstance: sparking_flow.python_job scheduled__2025-08-31T02:00:00+00:00 [running]> on host 80647ef95998
[2025-08-31T05:06:45.069+0000] {taskinstance.py:1660} INFO - Exporting env vars: AIRFLOW_CTX_DAG_OWNER='Kudzaishe Manyanya' AIRFLOW_CTX_DAG_ID='sparking_flow' AIRFLOW_CTX_TASK_ID='python_job' AIRFLOW_CTX_EXECUTION_DATE='2025-08-31T02:00:00+00:00' AIRFLOW_CTX_TRY_NUMBER='1' AIRFLOW_CTX_DAG_RUN_ID='scheduled__2025-08-31T02:00:00+00:00'
[2025-08-31T05:06:45.222+0000] {spark_submit.py:273} INFO - Could not load connection string spark-conn, defaulting to yarn
[2025-08-31T05:06:45.230+0000] {spark_submit.py:403} INFO - Spark-Submit cmd: spark-submit --master yarn --jars /opt/spark/external-jars/apache-spark-sql-connector.jar --name arrow-spark jobs/python/wordcountjob.py
[2025-08-31T05:06:48.793+0000] {spark_submit.py:579} INFO - WARNING: Using incubator modules: jdk.incubator.vector
[2025-08-31T05:06:56.321+0000] {spark_submit.py:579} INFO - Exception in thread "main" org.apache.spark.SparkException: When running with master 'yarn' either HADOOP_CONF_DIR or YARN_CONF_DIR must be set in the environment.
[2025-08-31T05:06:56.322+0000] {spark_submit.py:579} INFO - at org.apache.spark.deploy.SparkSubmitArguments.error(SparkSubmitArguments.scala:640)
[2025-08-31T05:06:56.322+0000] {spark_submit.py:579} INFO - at org.apache.spark.deploy.SparkSubmitArguments.validateSubmitArguments(SparkSubmitArguments.scala:287)
[2025-08-31T05:06:56.323+0000] {spark_submit.py:579} INFO - at org.apache.spark.deploy.SparkSubmitArguments.validateArguments(SparkSubmitArguments.scala:245)
[2025-08-31T05:06:56.323+0000] {spark_submit.py:579} INFO - at org.apache.spark.deploy.SparkSubmitArguments.<init>(SparkSubmitArguments.scala:104)
[2025-08-31T05:06:56.324+0000] {spark_submit.py:579} INFO - at org.apache.spark.deploy.SparkSubmit$$anon$2$$anon$3.<init>(SparkSubmit.scala:1101)
[2025-08-31T05:06:56.324+0000] {spark_submit.py:579} INFO - at org.apache.spark.deploy.SparkSubmit$$anon$2.parseArguments(SparkSubmit.scala:1101)
[2025-08-31T05:06:56.325+0000] {spark_submit.py:579} INFO - at org.apache.spark.deploy.SparkSubmit.doSubmit(SparkSubmit.scala:72)
[2025-08-31T05:06:56.326+0000] {spark_submit.py:579} INFO - at org.apache.spark.deploy.SparkSubmit$$anon$2.doSubmit(SparkSubmit.scala:1132)
[2025-08-31T05:06:56.327+0000] {spark_submit.py:579} INFO - at org.apache.spark.deploy.SparkSubmit$.main(SparkSubmit.scala:1141)
[2025-08-31T05:06:56.328+0000] {spark_submit.py:579} INFO - at org.apache.spark.deploy.SparkSubmit.main(SparkSubmit.scala)
[2025-08-31T05:06:56.356+0000] {taskinstance.py:1935} ERROR - Task failed with exception
Traceback (most recent call last):
  File "/home/airflow/.local/lib/python3.10/site-packages/airflow/providers/apache/spark/operators/spark_submit.py", line 174, in execute
    self._hook.submit(self.application)
  File "/home/airflow/.local/lib/python3.10/site-packages/airflow/providers/apache/spark/hooks/spark_submit.py", line 505, in submit
    raise AirflowException(
airflow.exceptions.AirflowException: Cannot execute: spark-submit --master yarn --jars /opt/spark/external-jars/apache-spark-sql-connector.jar --name arrow-spark jobs/python/wordcountjob.py. Error code is: 1.
[2025-08-31T05:06:56.363+0000] {taskinstance.py:1398} INFO - Marking task as FAILED. dag_id=sparking_flow, task_id=python_job, execution_date=20250831T020000, start_date=20250831T050643, end_date=20250831T050656
[2025-08-31T05:06:56.380+0000] {standard_task_runner.py:104} ERROR - Failed to execute job 30 for task python_job (Cannot execute: spark-submit --master yarn --jars /opt/spark/external-jars/apache-spark-sql-connector.jar --name arrow-spark jobs/python/wordcountjob.py. Error code is: 1.; 454)
[2025-08-31T05:06:56.415+0000] {local_task_job_runner.py:228} INFO - Task exited with return code 1
[2025-08-31T05:06:56.441+0000] {taskinstance.py:2776} INFO - 0 downstream tasks scheduled from follow-on schedule check
[2025-08-31T12:53:21.823+0000] {taskinstance.py:1157} INFO - Dependencies all met for dep_context=non-requeueable deps ti=<TaskInstance: sparking_flow.python_job scheduled__2025-08-31T02:00:00+00:00 [queued]>
[2025-08-31T12:53:21.839+0000] {taskinstance.py:1157} INFO - Dependencies all met for dep_context=requeueable deps ti=<TaskInstance: sparking_flow.python_job scheduled__2025-08-31T02:00:00+00:00 [queued]>
[2025-08-31T12:53:21.843+0000] {taskinstance.py:1359} INFO - Starting attempt 1 of 1
[2025-08-31T12:53:21.871+0000] {taskinstance.py:1380} INFO - Executing <Task(SparkSubmitOperator): python_job> on 2025-08-31 02:00:00+00:00
[2025-08-31T12:53:21.883+0000] {standard_task_runner.py:57} INFO - Started process 406 to run task
[2025-08-31T12:53:21.894+0000] {standard_task_runner.py:84} INFO - Running: ['***', 'tasks', 'run', 'sparking_flow', 'python_job', 'scheduled__2025-08-31T02:00:00+00:00', '--job-id', '30', '--raw', '--subdir', 'DAGS_FOLDER/spark_***.py', '--cfg-path', '/tmp/tmp1_vu2xc_']
[2025-08-31T12:53:21.902+0000] {standard_task_runner.py:85} INFO - Job 30: Subtask python_job
[2025-08-31T12:53:22.283+0000] {task_command.py:415} INFO - Running <TaskInstance: sparking_flow.python_job scheduled__2025-08-31T02:00:00+00:00 [running]> on host f7da00c682c4
[2025-08-31T12:53:22.789+0000] {taskinstance.py:1660} INFO - Exporting env vars: AIRFLOW_CTX_DAG_OWNER='Kudzaishe Manyanya' AIRFLOW_CTX_DAG_ID='sparking_flow' AIRFLOW_CTX_TASK_ID='python_job' AIRFLOW_CTX_EXECUTION_DATE='2025-08-31T02:00:00+00:00' AIRFLOW_CTX_TRY_NUMBER='1' AIRFLOW_CTX_DAG_RUN_ID='scheduled__2025-08-31T02:00:00+00:00'
[2025-08-31T12:53:23.068+0000] {base.py:73} INFO - Using connection ID 'spark-conn' for task execution.
[2025-08-31T12:53:23.085+0000] {spark_submit.py:403} INFO - Spark-Submit cmd: spark-submit --master spark://spark-master:7077 --jars /opt/spark/external-jars/apache-spark-sql-connector.jar --name arrow-spark --deploy-mode client jobs/python/wordcountjob.py
[2025-08-31T12:53:25.931+0000] {spark_submit.py:579} INFO - WARNING: Using incubator modules: jdk.incubator.vector
[2025-08-31T12:53:42.915+0000] {spark_submit.py:579} INFO - 25/08/31 12:53:42 WARN NativeCodeLoader: Unable to load native-hadoop library for your platform... using builtin-java classes where applicable
[2025-08-31T12:56:18.078+0000] {spark_submit.py:579} INFO - Using Spark's default log4j profile: org/apache/spark/log4j2-defaults.properties
[2025-08-31T12:54:11.866+0000] {job.py:219} ERROR - Job heartbeat got an exception
Traceback (most recent call last):
  File "/home/airflow/.local/lib/python3.10/site-packages/sqlalchemy/engine/base.py", line 3371, in _wrap_pool_connect
    return fn()
  File "/home/airflow/.local/lib/python3.10/site-packages/sqlalchemy/pool/base.py", line 327, in connect
    return _ConnectionFairy._checkout(self)
  File "/home/airflow/.local/lib/python3.10/site-packages/sqlalchemy/pool/base.py", line 894, in _checkout
    fairy = _ConnectionRecord.checkout(pool)
  File "/home/airflow/.local/lib/python3.10/site-packages/sqlalchemy/pool/base.py", line 493, in checkout
    rec = pool._do_get()
  File "/home/airflow/.local/lib/python3.10/site-packages/sqlalchemy/pool/impl.py", line 256, in _do_get
    return self._create_connection()
  File "/home/airflow/.local/lib/python3.10/site-packages/sqlalchemy/pool/base.py", line 273, in _create_connection
    return _ConnectionRecord(self)
  File "/home/airflow/.local/lib/python3.10/site-packages/sqlalchemy/pool/base.py", line 388, in __init__
    self.__connect()
  File "/home/airflow/.local/lib/python3.10/site-packages/sqlalchemy/pool/base.py", line 690, in __connect
    with util.safe_reraise():
  File "/home/airflow/.local/lib/python3.10/site-packages/sqlalchemy/util/langhelpers.py", line 70, in __exit__
    compat.raise_(
  File "/home/airflow/.local/lib/python3.10/site-packages/sqlalchemy/util/compat.py", line 211, in raise_
    raise exception
  File "/home/airflow/.local/lib/python3.10/site-packages/sqlalchemy/pool/base.py", line 686, in __connect
    self.dbapi_connection = connection = pool._invoke_creator(self)
  File "/home/airflow/.local/lib/python3.10/site-packages/sqlalchemy/engine/create.py", line 574, in connect
    return dialect.connect(*cargs, **cparams)
  File "/home/airflow/.local/lib/python3.10/site-packages/sqlalchemy/engine/default.py", line 598, in connect
    return self.dbapi.connect(*cargs, **cparams)
  File "/home/airflow/.local/lib/python3.10/site-packages/psycopg2/__init__.py", line 122, in connect
    conn = _connect(dsn, connection_factory=connection_factory, **kwasync)
psycopg2.OperationalError: could not translate host name "postgres" to address: Temporary failure in name resolution


The above exception was the direct cause of the following exception:

Traceback (most recent call last):
  File "/home/airflow/.local/lib/python3.10/site-packages/airflow/jobs/job.py", line 190, in heartbeat
    session.merge(self)
  File "/home/airflow/.local/lib/python3.10/site-packages/sqlalchemy/orm/session.py", line 3056, in merge
    return self._merge(
  File "/home/airflow/.local/lib/python3.10/site-packages/sqlalchemy/orm/session.py", line 3136, in _merge
    merged = self.get(
  File "/home/airflow/.local/lib/python3.10/site-packages/sqlalchemy/orm/session.py", line 2853, in get
    return self._get_impl(
  File "/home/airflow/.local/lib/python3.10/site-packages/sqlalchemy/orm/session.py", line 2975, in _get_impl
    return db_load_fn(
  File "/home/airflow/.local/lib/python3.10/site-packages/sqlalchemy/orm/loading.py", line 530, in load_on_pk_identity
    session.execute(
  File "/home/airflow/.local/lib/python3.10/site-packages/sqlalchemy/orm/session.py", line 1716, in execute
    conn = self._connection_for_bind(bind)
  File "/home/airflow/.local/lib/python3.10/site-packages/sqlalchemy/orm/session.py", line 1555, in _connection_for_bind
    return self._transaction._connection_for_bind(
  File "/home/airflow/.local/lib/python3.10/site-packages/sqlalchemy/orm/session.py", line 750, in _connection_for_bind
    conn = bind.connect()
  File "/home/airflow/.local/lib/python3.10/site-packages/sqlalchemy/future/engine.py", line 406, in connect
    return super(Engine, self).connect()
  File "/home/airflow/.local/lib/python3.10/site-packages/sqlalchemy/engine/base.py", line 3325, in connect
    return self._connection_cls(self, close_with_result=close_with_result)
  File "/home/airflow/.local/lib/python3.10/site-packages/sqlalchemy/engine/base.py", line 96, in __init__
    else engine.raw_connection()
  File "/home/airflow/.local/lib/python3.10/site-packages/sqlalchemy/engine/base.py", line 3404, in raw_connection
    return self._wrap_pool_connect(self.pool.connect, _connection)
  File "/home/airflow/.local/lib/python3.10/site-packages/sqlalchemy/engine/base.py", line 3374, in _wrap_pool_connect
    Connection._handle_dbapi_exception_noconnection(
  File "/home/airflow/.local/lib/python3.10/site-packages/sqlalchemy/engine/base.py", line 2208, in _handle_dbapi_exception_noconnection
    util.raise_(
  File "/home/airflow/.local/lib/python3.10/site-packages/sqlalchemy/util/compat.py", line 211, in raise_
    raise exception
  File "/home/airflow/.local/lib/python3.10/site-packages/sqlalchemy/engine/base.py", line 3371, in _wrap_pool_connect
    return fn()
  File "/home/airflow/.local/lib/python3.10/site-packages/sqlalchemy/pool/base.py", line 327, in connect
    return _ConnectionFairy._checkout(self)
  File "/home/airflow/.local/lib/python3.10/site-packages/sqlalchemy/pool/base.py", line 894, in _checkout
    fairy = _ConnectionRecord.checkout(pool)
  File "/home/airflow/.local/lib/python3.10/site-packages/sqlalchemy/pool/base.py", line 493, in checkout
    rec = pool._do_get()
  File "/home/airflow/.local/lib/python3.10/site-packages/sqlalchemy/pool/impl.py", line 256, in _do_get
    return self._create_connection()
  File "/home/airflow/.local/lib/python3.10/site-packages/sqlalchemy/pool/base.py", line 273, in _create_connection
    return _ConnectionRecord(self)
  File "/home/airflow/.local/lib/python3.10/site-packages/sqlalchemy/pool/base.py", line 388, in __init__
    self.__connect()
  File "/home/airflow/.local/lib/python3.10/site-packages/sqlalchemy/pool/base.py", line 690, in __connect
    with util.safe_reraise():
  File "/home/airflow/.local/lib/python3.10/site-packages/sqlalchemy/util/langhelpers.py", line 70, in __exit__
    compat.raise_(
  File "/home/airflow/.local/lib/python3.10/site-packages/sqlalchemy/util/compat.py", line 211, in raise_
    raise exception
  File "/home/airflow/.local/lib/python3.10/site-packages/sqlalchemy/pool/base.py", line 686, in __connect
    self.dbapi_connection = connection = pool._invoke_creator(self)
  File "/home/airflow/.local/lib/python3.10/site-packages/sqlalchemy/engine/create.py", line 574, in connect
    return dialect.connect(*cargs, **cparams)
  File "/home/airflow/.local/lib/python3.10/site-packages/sqlalchemy/engine/default.py", line 598, in connect
    return self.dbapi.connect(*cargs, **cparams)
  File "/home/airflow/.local/lib/python3.10/site-packages/psycopg2/__init__.py", line 122, in connect
    conn = _connect(dsn, connection_factory=connection_factory, **kwasync)
sqlalchemy.exc.OperationalError: (psycopg2.OperationalError) could not translate host name "postgres" to address: Temporary failure in name resolution

(Background on this error at: https://sqlalche.me/e/14/e3q8)
[2025-08-31T12:56:18.219+0000] {spark_submit.py:579} INFO - 25/08/31 12:56:18 INFO SparkContext: Running Spark version 4.0.0
[2025-08-31T12:56:18.247+0000] {spark_submit.py:579} INFO - 25/08/31 12:56:18 INFO SparkContext: OS info Linux, 6.6.87.2-microsoft-standard-WSL2, amd64
[2025-08-31T12:56:18.275+0000] {spark_submit.py:579} INFO - 25/08/31 12:56:18 INFO SparkContext: Java version 17.0.15
[2025-08-31T12:56:40.058+0000] {job.py:219} ERROR - Job heartbeat got an exception
Traceback (most recent call last):
  File "/home/airflow/.local/lib/python3.10/site-packages/sqlalchemy/engine/base.py", line 3371, in _wrap_pool_connect
    return fn()
  File "/home/airflow/.local/lib/python3.10/site-packages/sqlalchemy/pool/base.py", line 327, in connect
    return _ConnectionFairy._checkout(self)
  File "/home/airflow/.local/lib/python3.10/site-packages/sqlalchemy/pool/base.py", line 894, in _checkout
    fairy = _ConnectionRecord.checkout(pool)
  File "/home/airflow/.local/lib/python3.10/site-packages/sqlalchemy/pool/base.py", line 493, in checkout
    rec = pool._do_get()
  File "/home/airflow/.local/lib/python3.10/site-packages/sqlalchemy/pool/impl.py", line 256, in _do_get
    return self._create_connection()
  File "/home/airflow/.local/lib/python3.10/site-packages/sqlalchemy/pool/base.py", line 273, in _create_connection
    return _ConnectionRecord(self)
  File "/home/airflow/.local/lib/python3.10/site-packages/sqlalchemy/pool/base.py", line 388, in __init__
    self.__connect()
  File "/home/airflow/.local/lib/python3.10/site-packages/sqlalchemy/pool/base.py", line 690, in __connect
    with util.safe_reraise():
  File "/home/airflow/.local/lib/python3.10/site-packages/sqlalchemy/util/langhelpers.py", line 70, in __exit__
    compat.raise_(
  File "/home/airflow/.local/lib/python3.10/site-packages/sqlalchemy/util/compat.py", line 211, in raise_
    raise exception
  File "/home/airflow/.local/lib/python3.10/site-packages/sqlalchemy/pool/base.py", line 686, in __connect
    self.dbapi_connection = connection = pool._invoke_creator(self)
  File "/home/airflow/.local/lib/python3.10/site-packages/sqlalchemy/engine/create.py", line 574, in connect
    return dialect.connect(*cargs, **cparams)
  File "/home/airflow/.local/lib/python3.10/site-packages/sqlalchemy/engine/default.py", line 598, in connect
    return self.dbapi.connect(*cargs, **cparams)
  File "/home/airflow/.local/lib/python3.10/site-packages/psycopg2/__init__.py", line 122, in connect
    conn = _connect(dsn, connection_factory=connection_factory, **kwasync)
psycopg2.OperationalError: could not translate host name "postgres" to address: Temporary failure in name resolution


The above exception was the direct cause of the following exception:

Traceback (most recent call last):
  File "/home/airflow/.local/lib/python3.10/site-packages/airflow/jobs/job.py", line 190, in heartbeat
    session.merge(self)
  File "/home/airflow/.local/lib/python3.10/site-packages/sqlalchemy/orm/session.py", line 3056, in merge
    return self._merge(
  File "/home/airflow/.local/lib/python3.10/site-packages/sqlalchemy/orm/session.py", line 3136, in _merge
    merged = self.get(
  File "/home/airflow/.local/lib/python3.10/site-packages/sqlalchemy/orm/session.py", line 2853, in get
    return self._get_impl(
  File "/home/airflow/.local/lib/python3.10/site-packages/sqlalchemy/orm/session.py", line 2975, in _get_impl
    return db_load_fn(
  File "/home/airflow/.local/lib/python3.10/site-packages/sqlalchemy/orm/loading.py", line 530, in load_on_pk_identity
    session.execute(
  File "/home/airflow/.local/lib/python3.10/site-packages/sqlalchemy/orm/session.py", line 1716, in execute
    conn = self._connection_for_bind(bind)
  File "/home/airflow/.local/lib/python3.10/site-packages/sqlalchemy/orm/session.py", line 1555, in _connection_for_bind
    return self._transaction._connection_for_bind(
  File "/home/airflow/.local/lib/python3.10/site-packages/sqlalchemy/orm/session.py", line 750, in _connection_for_bind
    conn = bind.connect()
  File "/home/airflow/.local/lib/python3.10/site-packages/sqlalchemy/future/engine.py", line 406, in connect
    return super(Engine, self).connect()
  File "/home/airflow/.local/lib/python3.10/site-packages/sqlalchemy/engine/base.py", line 3325, in connect
    return self._connection_cls(self, close_with_result=close_with_result)
  File "/home/airflow/.local/lib/python3.10/site-packages/sqlalchemy/engine/base.py", line 96, in __init__
    else engine.raw_connection()
  File "/home/airflow/.local/lib/python3.10/site-packages/sqlalchemy/engine/base.py", line 3404, in raw_connection
    return self._wrap_pool_connect(self.pool.connect, _connection)
  File "/home/airflow/.local/lib/python3.10/site-packages/sqlalchemy/engine/base.py", line 3374, in _wrap_pool_connect
    Connection._handle_dbapi_exception_noconnection(
  File "/home/airflow/.local/lib/python3.10/site-packages/sqlalchemy/engine/base.py", line 2208, in _handle_dbapi_exception_noconnection
    util.raise_(
  File "/home/airflow/.local/lib/python3.10/site-packages/sqlalchemy/util/compat.py", line 211, in raise_
    raise exception
  File "/home/airflow/.local/lib/python3.10/site-packages/sqlalchemy/engine/base.py", line 3371, in _wrap_pool_connect
    return fn()
  File "/home/airflow/.local/lib/python3.10/site-packages/sqlalchemy/pool/base.py", line 327, in connect
    return _ConnectionFairy._checkout(self)
  File "/home/airflow/.local/lib/python3.10/site-packages/sqlalchemy/pool/base.py", line 894, in _checkout
    fairy = _ConnectionRecord.checkout(pool)
  File "/home/airflow/.local/lib/python3.10/site-packages/sqlalchemy/pool/base.py", line 493, in checkout
    rec = pool._do_get()
  File "/home/airflow/.local/lib/python3.10/site-packages/sqlalchemy/pool/impl.py", line 256, in _do_get
    return self._create_connection()
  File "/home/airflow/.local/lib/python3.10/site-packages/sqlalchemy/pool/base.py", line 273, in _create_connection
    return _ConnectionRecord(self)
  File "/home/airflow/.local/lib/python3.10/site-packages/sqlalchemy/pool/base.py", line 388, in __init__
    self.__connect()
  File "/home/airflow/.local/lib/python3.10/site-packages/sqlalchemy/pool/base.py", line 690, in __connect
    with util.safe_reraise():
  File "/home/airflow/.local/lib/python3.10/site-packages/sqlalchemy/util/langhelpers.py", line 70, in __exit__
    compat.raise_(
  File "/home/airflow/.local/lib/python3.10/site-packages/sqlalchemy/util/compat.py", line 211, in raise_
    raise exception
  File "/home/airflow/.local/lib/python3.10/site-packages/sqlalchemy/pool/base.py", line 686, in __connect
    self.dbapi_connection = connection = pool._invoke_creator(self)
  File "/home/airflow/.local/lib/python3.10/site-packages/sqlalchemy/engine/create.py", line 574, in connect
    return dialect.connect(*cargs, **cparams)
  File "/home/airflow/.local/lib/python3.10/site-packages/sqlalchemy/engine/default.py", line 598, in connect
    return self.dbapi.connect(*cargs, **cparams)
  File "/home/airflow/.local/lib/python3.10/site-packages/psycopg2/__init__.py", line 122, in connect
    conn = _connect(dsn, connection_factory=connection_factory, **kwasync)
sqlalchemy.exc.OperationalError: (psycopg2.OperationalError) could not translate host name "postgres" to address: Temporary failure in name resolution

(Background on this error at: https://sqlalche.me/e/14/e3q8)
[2025-08-31T12:57:05.076+0000] {job.py:219} ERROR - Job heartbeat got an exception
Traceback (most recent call last):
  File "/home/airflow/.local/lib/python3.10/site-packages/sqlalchemy/engine/base.py", line 3371, in _wrap_pool_connect
    return fn()
  File "/home/airflow/.local/lib/python3.10/site-packages/sqlalchemy/pool/base.py", line 327, in connect
    return _ConnectionFairy._checkout(self)
  File "/home/airflow/.local/lib/python3.10/site-packages/sqlalchemy/pool/base.py", line 894, in _checkout
    fairy = _ConnectionRecord.checkout(pool)
  File "/home/airflow/.local/lib/python3.10/site-packages/sqlalchemy/pool/base.py", line 493, in checkout
    rec = pool._do_get()
  File "/home/airflow/.local/lib/python3.10/site-packages/sqlalchemy/pool/impl.py", line 256, in _do_get
    return self._create_connection()
  File "/home/airflow/.local/lib/python3.10/site-packages/sqlalchemy/pool/base.py", line 273, in _create_connection
    return _ConnectionRecord(self)
  File "/home/airflow/.local/lib/python3.10/site-packages/sqlalchemy/pool/base.py", line 388, in __init__
    self.__connect()
  File "/home/airflow/.local/lib/python3.10/site-packages/sqlalchemy/pool/base.py", line 690, in __connect
    with util.safe_reraise():
  File "/home/airflow/.local/lib/python3.10/site-packages/sqlalchemy/util/langhelpers.py", line 70, in __exit__
    compat.raise_(
  File "/home/airflow/.local/lib/python3.10/site-packages/sqlalchemy/util/compat.py", line 211, in raise_
    raise exception
  File "/home/airflow/.local/lib/python3.10/site-packages/sqlalchemy/pool/base.py", line 686, in __connect
    self.dbapi_connection = connection = pool._invoke_creator(self)
  File "/home/airflow/.local/lib/python3.10/site-packages/sqlalchemy/engine/create.py", line 574, in connect
    return dialect.connect(*cargs, **cparams)
  File "/home/airflow/.local/lib/python3.10/site-packages/sqlalchemy/engine/default.py", line 598, in connect
    return self.dbapi.connect(*cargs, **cparams)
  File "/home/airflow/.local/lib/python3.10/site-packages/psycopg2/__init__.py", line 122, in connect
    conn = _connect(dsn, connection_factory=connection_factory, **kwasync)
psycopg2.OperationalError: could not translate host name "postgres" to address: Temporary failure in name resolution


The above exception was the direct cause of the following exception:

Traceback (most recent call last):
  File "/home/airflow/.local/lib/python3.10/site-packages/airflow/jobs/job.py", line 190, in heartbeat
    session.merge(self)
  File "/home/airflow/.local/lib/python3.10/site-packages/sqlalchemy/orm/session.py", line 3056, in merge
    return self._merge(
  File "/home/airflow/.local/lib/python3.10/site-packages/sqlalchemy/orm/session.py", line 3136, in _merge
    merged = self.get(
  File "/home/airflow/.local/lib/python3.10/site-packages/sqlalchemy/orm/session.py", line 2853, in get
    return self._get_impl(
  File "/home/airflow/.local/lib/python3.10/site-packages/sqlalchemy/orm/session.py", line 2975, in _get_impl
    return db_load_fn(
  File "/home/airflow/.local/lib/python3.10/site-packages/sqlalchemy/orm/loading.py", line 530, in load_on_pk_identity
    session.execute(
  File "/home/airflow/.local/lib/python3.10/site-packages/sqlalchemy/orm/session.py", line 1716, in execute
    conn = self._connection_for_bind(bind)
  File "/home/airflow/.local/lib/python3.10/site-packages/sqlalchemy/orm/session.py", line 1555, in _connection_for_bind
    return self._transaction._connection_for_bind(
  File "/home/airflow/.local/lib/python3.10/site-packages/sqlalchemy/orm/session.py", line 750, in _connection_for_bind
    conn = bind.connect()
  File "/home/airflow/.local/lib/python3.10/site-packages/sqlalchemy/future/engine.py", line 406, in connect
    return super(Engine, self).connect()
  File "/home/airflow/.local/lib/python3.10/site-packages/sqlalchemy/engine/base.py", line 3325, in connect
    return self._connection_cls(self, close_with_result=close_with_result)
  File "/home/airflow/.local/lib/python3.10/site-packages/sqlalchemy/engine/base.py", line 96, in __init__
    else engine.raw_connection()
  File "/home/airflow/.local/lib/python3.10/site-packages/sqlalchemy/engine/base.py", line 3404, in raw_connection
    return self._wrap_pool_connect(self.pool.connect, _connection)
  File "/home/airflow/.local/lib/python3.10/site-packages/sqlalchemy/engine/base.py", line 3374, in _wrap_pool_connect
    Connection._handle_dbapi_exception_noconnection(
  File "/home/airflow/.local/lib/python3.10/site-packages/sqlalchemy/engine/base.py", line 2208, in _handle_dbapi_exception_noconnection
    util.raise_(
  File "/home/airflow/.local/lib/python3.10/site-packages/sqlalchemy/util/compat.py", line 211, in raise_
    raise exception
  File "/home/airflow/.local/lib/python3.10/site-packages/sqlalchemy/engine/base.py", line 3371, in _wrap_pool_connect
    return fn()
  File "/home/airflow/.local/lib/python3.10/site-packages/sqlalchemy/pool/base.py", line 327, in connect
    return _ConnectionFairy._checkout(self)
  File "/home/airflow/.local/lib/python3.10/site-packages/sqlalchemy/pool/base.py", line 894, in _checkout
    fairy = _ConnectionRecord.checkout(pool)
  File "/home/airflow/.local/lib/python3.10/site-packages/sqlalchemy/pool/base.py", line 493, in checkout
    rec = pool._do_get()
  File "/home/airflow/.local/lib/python3.10/site-packages/sqlalchemy/pool/impl.py", line 256, in _do_get
    return self._create_connection()
  File "/home/airflow/.local/lib/python3.10/site-packages/sqlalchemy/pool/base.py", line 273, in _create_connection
    return _ConnectionRecord(self)
  File "/home/airflow/.local/lib/python3.10/site-packages/sqlalchemy/pool/base.py", line 388, in __init__
    self.__connect()
  File "/home/airflow/.local/lib/python3.10/site-packages/sqlalchemy/pool/base.py", line 690, in __connect
    with util.safe_reraise():
  File "/home/airflow/.local/lib/python3.10/site-packages/sqlalchemy/util/langhelpers.py", line 70, in __exit__
    compat.raise_(
  File "/home/airflow/.local/lib/python3.10/site-packages/sqlalchemy/util/compat.py", line 211, in raise_
    raise exception
  File "/home/airflow/.local/lib/python3.10/site-packages/sqlalchemy/pool/base.py", line 686, in __connect
    self.dbapi_connection = connection = pool._invoke_creator(self)
  File "/home/airflow/.local/lib/python3.10/site-packages/sqlalchemy/engine/create.py", line 574, in connect
    return dialect.connect(*cargs, **cparams)
  File "/home/airflow/.local/lib/python3.10/site-packages/sqlalchemy/engine/default.py", line 598, in connect
    return self.dbapi.connect(*cargs, **cparams)
  File "/home/airflow/.local/lib/python3.10/site-packages/psycopg2/__init__.py", line 122, in connect
    conn = _connect(dsn, connection_factory=connection_factory, **kwasync)
sqlalchemy.exc.OperationalError: (psycopg2.OperationalError) could not translate host name "postgres" to address: Temporary failure in name resolution

(Background on this error at: https://sqlalche.me/e/14/e3q8)
[2025-08-31T13:01:33.919+0000] {job.py:219} ERROR - Job heartbeat got an exception
Traceback (most recent call last):
  File "/home/airflow/.local/lib/python3.10/site-packages/sqlalchemy/engine/base.py", line 3371, in _wrap_pool_connect
    return fn()
  File "/home/airflow/.local/lib/python3.10/site-packages/sqlalchemy/pool/base.py", line 327, in connect
    return _ConnectionFairy._checkout(self)
  File "/home/airflow/.local/lib/python3.10/site-packages/sqlalchemy/pool/base.py", line 894, in _checkout
    fairy = _ConnectionRecord.checkout(pool)
  File "/home/airflow/.local/lib/python3.10/site-packages/sqlalchemy/pool/base.py", line 493, in checkout
    rec = pool._do_get()
  File "/home/airflow/.local/lib/python3.10/site-packages/sqlalchemy/pool/impl.py", line 256, in _do_get
    return self._create_connection()
  File "/home/airflow/.local/lib/python3.10/site-packages/sqlalchemy/pool/base.py", line 273, in _create_connection
    return _ConnectionRecord(self)
  File "/home/airflow/.local/lib/python3.10/site-packages/sqlalchemy/pool/base.py", line 388, in __init__
    self.__connect()
  File "/home/airflow/.local/lib/python3.10/site-packages/sqlalchemy/pool/base.py", line 690, in __connect
    with util.safe_reraise():
  File "/home/airflow/.local/lib/python3.10/site-packages/sqlalchemy/util/langhelpers.py", line 70, in __exit__
    compat.raise_(
  File "/home/airflow/.local/lib/python3.10/site-packages/sqlalchemy/util/compat.py", line 211, in raise_
    raise exception
  File "/home/airflow/.local/lib/python3.10/site-packages/sqlalchemy/pool/base.py", line 686, in __connect
    self.dbapi_connection = connection = pool._invoke_creator(self)
  File "/home/airflow/.local/lib/python3.10/site-packages/sqlalchemy/engine/create.py", line 574, in connect
    return dialect.connect(*cargs, **cparams)
  File "/home/airflow/.local/lib/python3.10/site-packages/sqlalchemy/engine/default.py", line 598, in connect
    return self.dbapi.connect(*cargs, **cparams)
  File "/home/airflow/.local/lib/python3.10/site-packages/psycopg2/__init__.py", line 122, in connect
    conn = _connect(dsn, connection_factory=connection_factory, **kwasync)
psycopg2.OperationalError: could not translate host name "postgres" to address: Temporary failure in name resolution


The above exception was the direct cause of the following exception:

Traceback (most recent call last):
  File "/home/airflow/.local/lib/python3.10/site-packages/airflow/jobs/job.py", line 190, in heartbeat
    session.merge(self)
  File "/home/airflow/.local/lib/python3.10/site-packages/sqlalchemy/orm/session.py", line 3056, in merge
    return self._merge(
  File "/home/airflow/.local/lib/python3.10/site-packages/sqlalchemy/orm/session.py", line 3136, in _merge
    merged = self.get(
  File "/home/airflow/.local/lib/python3.10/site-packages/sqlalchemy/orm/session.py", line 2853, in get
    return self._get_impl(
  File "/home/airflow/.local/lib/python3.10/site-packages/sqlalchemy/orm/session.py", line 2975, in _get_impl
    return db_load_fn(
  File "/home/airflow/.local/lib/python3.10/site-packages/sqlalchemy/orm/loading.py", line 530, in load_on_pk_identity
    session.execute(
  File "/home/airflow/.local/lib/python3.10/site-packages/sqlalchemy/orm/session.py", line 1716, in execute
    conn = self._connection_for_bind(bind)
  File "/home/airflow/.local/lib/python3.10/site-packages/sqlalchemy/orm/session.py", line 1555, in _connection_for_bind
    return self._transaction._connection_for_bind(
  File "/home/airflow/.local/lib/python3.10/site-packages/sqlalchemy/orm/session.py", line 750, in _connection_for_bind
    conn = bind.connect()
  File "/home/airflow/.local/lib/python3.10/site-packages/sqlalchemy/future/engine.py", line 406, in connect
    return super(Engine, self).connect()
  File "/home/airflow/.local/lib/python3.10/site-packages/sqlalchemy/engine/base.py", line 3325, in connect
    return self._connection_cls(self, close_with_result=close_with_result)
  File "/home/airflow/.local/lib/python3.10/site-packages/sqlalchemy/engine/base.py", line 96, in __init__
    else engine.raw_connection()
  File "/home/airflow/.local/lib/python3.10/site-packages/sqlalchemy/engine/base.py", line 3404, in raw_connection
    return self._wrap_pool_connect(self.pool.connect, _connection)
  File "/home/airflow/.local/lib/python3.10/site-packages/sqlalchemy/engine/base.py", line 3374, in _wrap_pool_connect
    Connection._handle_dbapi_exception_noconnection(
  File "/home/airflow/.local/lib/python3.10/site-packages/sqlalchemy/engine/base.py", line 2208, in _handle_dbapi_exception_noconnection
    util.raise_(
  File "/home/airflow/.local/lib/python3.10/site-packages/sqlalchemy/util/compat.py", line 211, in raise_
    raise exception
  File "/home/airflow/.local/lib/python3.10/site-packages/sqlalchemy/engine/base.py", line 3371, in _wrap_pool_connect
    return fn()
  File "/home/airflow/.local/lib/python3.10/site-packages/sqlalchemy/pool/base.py", line 327, in connect
    return _ConnectionFairy._checkout(self)
  File "/home/airflow/.local/lib/python3.10/site-packages/sqlalchemy/pool/base.py", line 894, in _checkout
    fairy = _ConnectionRecord.checkout(pool)
  File "/home/airflow/.local/lib/python3.10/site-packages/sqlalchemy/pool/base.py", line 493, in checkout
    rec = pool._do_get()
  File "/home/airflow/.local/lib/python3.10/site-packages/sqlalchemy/pool/impl.py", line 256, in _do_get
    return self._create_connection()
  File "/home/airflow/.local/lib/python3.10/site-packages/sqlalchemy/pool/base.py", line 273, in _create_connection
    return _ConnectionRecord(self)
  File "/home/airflow/.local/lib/python3.10/site-packages/sqlalchemy/pool/base.py", line 388, in __init__
    self.__connect()
  File "/home/airflow/.local/lib/python3.10/site-packages/sqlalchemy/pool/base.py", line 690, in __connect
    with util.safe_reraise():
  File "/home/airflow/.local/lib/python3.10/site-packages/sqlalchemy/util/langhelpers.py", line 70, in __exit__
    compat.raise_(
  File "/home/airflow/.local/lib/python3.10/site-packages/sqlalchemy/util/compat.py", line 211, in raise_
    raise exception
  File "/home/airflow/.local/lib/python3.10/site-packages/sqlalchemy/pool/base.py", line 686, in __connect
    self.dbapi_connection = connection = pool._invoke_creator(self)
  File "/home/airflow/.local/lib/python3.10/site-packages/sqlalchemy/engine/create.py", line 574, in connect
    return dialect.connect(*cargs, **cparams)
  File "/home/airflow/.local/lib/python3.10/site-packages/sqlalchemy/engine/default.py", line 598, in connect
    return self.dbapi.connect(*cargs, **cparams)
  File "/home/airflow/.local/lib/python3.10/site-packages/psycopg2/__init__.py", line 122, in connect
    conn = _connect(dsn, connection_factory=connection_factory, **kwasync)
sqlalchemy.exc.OperationalError: (psycopg2.OperationalError) could not translate host name "postgres" to address: Temporary failure in name resolution

(Background on this error at: https://sqlalche.me/e/14/e3q8)
[2025-08-31T13:01:34.245+0000] {local_task_job_runner.py:205} ERROR - Heartbeat time limit exceeded!
[2025-08-31T13:01:34.348+0000] {spark_submit.py:579} INFO - 25/08/31 13:01:34 INFO ResourceUtils: ==============================================================
[2025-08-31T13:01:34.377+0000] {spark_submit.py:579} INFO - 25/08/31 13:01:34 INFO ResourceUtils: No custom resources configured for spark.driver.
[2025-08-31T13:01:34.380+0000] {spark_submit.py:579} INFO - 25/08/31 13:01:34 INFO ResourceUtils: ==============================================================
[2025-08-31T13:01:34.391+0000] {spark_submit.py:579} INFO - 25/08/31 13:01:34 INFO SparkContext: Submitted application: PythonWordCount
[2025-08-31T13:01:34.617+0000] {process_utils.py:131} INFO - Sending 15 to group 406. PIDs of all processes in the group: [466, 1399, 406]
[2025-08-31T13:01:34.694+0000] {process_utils.py:86} INFO - Sending the signal 15 to group 406
[2025-08-31T13:01:34.739+0000] {taskinstance.py:1630} ERROR - Received SIGTERM. Terminating subprocesses.
[2025-08-31T13:01:34.756+0000] {process_utils.py:79} INFO - Process psutil.Process(pid=1399, status='terminated', started='12:53:45') (1399) terminated with exit code None
[2025-08-31T13:01:34.771+0000] {spark_submit.py:705} INFO - Sending kill signal to spark-submit
[2025-08-31T13:01:35.512+0000] {taskinstance.py:1935} ERROR - Task failed with exception
Traceback (most recent call last):
  File "/home/airflow/.local/lib/python3.10/site-packages/airflow/providers/apache/spark/operators/spark_submit.py", line 174, in execute
    self._hook.submit(self.application)
  File "/home/airflow/.local/lib/python3.10/site-packages/airflow/providers/apache/spark/hooks/spark_submit.py", line 493, in submit
    self._process_spark_submit_log(iter(self._submit_sp.stdout))  # type: ignore
  File "/home/airflow/.local/lib/python3.10/site-packages/airflow/providers/apache/spark/hooks/spark_submit.py", line 542, in _process_spark_submit_log
    for line in itr:
  File "/home/airflow/.local/lib/python3.10/site-packages/airflow/models/taskinstance.py", line 1632, in signal_handler
    raise AirflowException("Task received SIGTERM signal")
airflow.exceptions.AirflowException: Task received SIGTERM signal
[2025-08-31T13:01:35.890+0000] {taskinstance.py:1398} INFO - Marking task as FAILED. dag_id=sparking_flow, task_id=python_job, execution_date=20250831T020000, start_date=20250831T125321, end_date=20250831T130135
[2025-08-31T13:01:36.117+0000] {standard_task_runner.py:104} ERROR - Failed to execute job 30 for task python_job (Task received SIGTERM signal; 406)
[2025-08-31T13:01:36.216+0000] {process_utils.py:79} INFO - Process psutil.Process(pid=406, status='terminated', exitcode=1, started='12:53:21') (406) terminated with exit code 1
[2025-08-31T13:01:36.217+0000] {process_utils.py:79} INFO - Process psutil.Process(pid=466, status='terminated', started='12:53:22') (466) terminated with exit code None
[2025-09-01T18:54:19.439+0000] {taskinstance.py:1157} INFO - Dependencies all met for dep_context=non-requeueable deps ti=<TaskInstance: sparking_flow.python_job scheduled__2025-08-31T02:00:00+00:00 [queued]>
[2025-09-01T18:54:19.541+0000] {taskinstance.py:1157} INFO - Dependencies all met for dep_context=requeueable deps ti=<TaskInstance: sparking_flow.python_job scheduled__2025-08-31T02:00:00+00:00 [queued]>
[2025-09-01T18:54:19.541+0000] {taskinstance.py:1359} INFO - Starting attempt 1 of 1
[2025-09-01T18:54:20.413+0000] {taskinstance.py:1380} INFO - Executing <Task(SparkSubmitOperator): python_job> on 2025-08-31 02:00:00+00:00
[2025-09-01T18:54:20.498+0000] {standard_task_runner.py:57} INFO - Started process 242 to run task
[2025-09-01T18:54:20.826+0000] {standard_task_runner.py:84} INFO - Running: ['***', 'tasks', 'run', 'sparking_flow', 'python_job', 'scheduled__2025-08-31T02:00:00+00:00', '--job-id', '20', '--raw', '--subdir', 'DAGS_FOLDER/spark_***.py', '--cfg-path', '/tmp/tmp0k7k_7pl']
[2025-09-01T18:54:20.859+0000] {standard_task_runner.py:85} INFO - Job 20: Subtask python_job
[2025-09-01T18:54:21.216+0000] {task_command.py:415} INFO - Running <TaskInstance: sparking_flow.python_job scheduled__2025-08-31T02:00:00+00:00 [running]> on host 7b2a3a75c36f
[2025-09-01T18:54:21.504+0000] {taskinstance.py:1660} INFO - Exporting env vars: AIRFLOW_CTX_DAG_OWNER='Kudzaishe Manyanya' AIRFLOW_CTX_DAG_ID='sparking_flow' AIRFLOW_CTX_TASK_ID='python_job' AIRFLOW_CTX_EXECUTION_DATE='2025-08-31T02:00:00+00:00' AIRFLOW_CTX_TRY_NUMBER='1' AIRFLOW_CTX_DAG_RUN_ID='scheduled__2025-08-31T02:00:00+00:00'
[2025-09-01T18:54:21.547+0000] {spark_submit.py:273} INFO - Could not load connection string spark-conn, defaulting to yarn
[2025-09-01T18:54:21.552+0000] {spark_submit.py:403} INFO - Spark-Submit cmd: spark-submit --master yarn --jars /opt/spark/external-jars/apache-spark-sql-connector.jar --name arrow-spark jobs/python/wordcountjob.py
[2025-09-01T18:54:27.404+0000] {spark_submit.py:579} INFO - WARNING: Using incubator modules: jdk.incubator.vector
[2025-09-01T18:54:45.831+0000] {spark_submit.py:579} INFO - Exception in thread "main" org.apache.spark.SparkException: When running with master 'yarn' either HADOOP_CONF_DIR or YARN_CONF_DIR must be set in the environment.
[2025-09-01T18:54:45.912+0000] {spark_submit.py:579} INFO - at org.apache.spark.deploy.SparkSubmitArguments.error(SparkSubmitArguments.scala:640)
[2025-09-01T18:54:45.914+0000] {spark_submit.py:579} INFO - at org.apache.spark.deploy.SparkSubmitArguments.validateSubmitArguments(SparkSubmitArguments.scala:287)
[2025-09-01T18:54:45.915+0000] {spark_submit.py:579} INFO - at org.apache.spark.deploy.SparkSubmitArguments.validateArguments(SparkSubmitArguments.scala:245)
[2025-09-01T18:54:45.917+0000] {spark_submit.py:579} INFO - at org.apache.spark.deploy.SparkSubmitArguments.<init>(SparkSubmitArguments.scala:104)
[2025-09-01T18:54:45.921+0000] {spark_submit.py:579} INFO - at org.apache.spark.deploy.SparkSubmit$$anon$2$$anon$3.<init>(SparkSubmit.scala:1101)
[2025-09-01T18:54:45.929+0000] {spark_submit.py:579} INFO - at org.apache.spark.deploy.SparkSubmit$$anon$2.parseArguments(SparkSubmit.scala:1101)
[2025-09-01T18:54:45.930+0000] {spark_submit.py:579} INFO - at org.apache.spark.deploy.SparkSubmit.doSubmit(SparkSubmit.scala:72)
[2025-09-01T18:54:45.931+0000] {spark_submit.py:579} INFO - at org.apache.spark.deploy.SparkSubmit$$anon$2.doSubmit(SparkSubmit.scala:1132)
[2025-09-01T18:54:45.937+0000] {spark_submit.py:579} INFO - at org.apache.spark.deploy.SparkSubmit$.main(SparkSubmit.scala:1141)
[2025-09-01T18:54:45.942+0000] {spark_submit.py:579} INFO - at org.apache.spark.deploy.SparkSubmit.main(SparkSubmit.scala)
[2025-09-01T18:54:46.140+0000] {taskinstance.py:1935} ERROR - Task failed with exception
Traceback (most recent call last):
  File "/home/airflow/.local/lib/python3.10/site-packages/airflow/providers/apache/spark/operators/spark_submit.py", line 174, in execute
    self._hook.submit(self.application)
  File "/home/airflow/.local/lib/python3.10/site-packages/airflow/providers/apache/spark/hooks/spark_submit.py", line 505, in submit
    raise AirflowException(
airflow.exceptions.AirflowException: Cannot execute: spark-submit --master yarn --jars /opt/spark/external-jars/apache-spark-sql-connector.jar --name arrow-spark jobs/python/wordcountjob.py. Error code is: 1.
[2025-09-01T18:54:46.220+0000] {taskinstance.py:1398} INFO - Marking task as FAILED. dag_id=sparking_flow, task_id=python_job, execution_date=20250831T020000, start_date=20250901T185419, end_date=20250901T185446
[2025-09-01T18:54:46.840+0000] {standard_task_runner.py:104} ERROR - Failed to execute job 20 for task python_job (Cannot execute: spark-submit --master yarn --jars /opt/spark/external-jars/apache-spark-sql-connector.jar --name arrow-spark jobs/python/wordcountjob.py. Error code is: 1.; 242)
[2025-09-01T18:54:46.888+0000] {local_task_job_runner.py:228} INFO - Task exited with return code 1
[2025-09-01T18:54:47.032+0000] {taskinstance.py:2776} INFO - 0 downstream tasks scheduled from follow-on schedule check
