[2025-08-31T04:49:24.220+0000] {taskinstance.py:1157} INFO - Dependencies all met for dep_context=non-requeueable deps ti=<TaskInstance: sparking_flow.python_job scheduled__2025-08-30T14:00:00+00:00 [queued]>
[2025-08-31T04:49:24.252+0000] {taskinstance.py:1157} INFO - Dependencies all met for dep_context=requeueable deps ti=<TaskInstance: sparking_flow.python_job scheduled__2025-08-30T14:00:00+00:00 [queued]>
[2025-08-31T04:49:24.268+0000] {taskinstance.py:1359} INFO - Starting attempt 2 of 1
[2025-08-31T04:49:24.328+0000] {taskinstance.py:1380} INFO - Executing <Task(SparkSubmitOperator): python_job> on 2025-08-30 14:00:00+00:00
[2025-08-31T04:49:24.345+0000] {standard_task_runner.py:57} INFO - Started process 204 to run task
[2025-08-31T04:49:24.363+0000] {standard_task_runner.py:84} INFO - Running: ['***', 'tasks', 'run', 'sparking_flow', 'python_job', 'scheduled__2025-08-30T14:00:00+00:00', '--job-id', '93', '--raw', '--subdir', 'DAGS_FOLDER/spark_***.py', '--cfg-path', '/tmp/tmp__71b9e9']
[2025-08-31T04:49:24.376+0000] {standard_task_runner.py:85} INFO - Job 93: Subtask python_job
[2025-08-31T04:49:24.582+0000] {task_command.py:415} INFO - Running <TaskInstance: sparking_flow.python_job scheduled__2025-08-30T14:00:00+00:00 [running]> on host 81b7fe425a18
[2025-08-31T04:49:25.082+0000] {taskinstance.py:1660} INFO - Exporting env vars: AIRFLOW_CTX_DAG_OWNER='Kudzaishe Manyanya' AIRFLOW_CTX_DAG_ID='sparking_flow' AIRFLOW_CTX_TASK_ID='python_job' AIRFLOW_CTX_EXECUTION_DATE='2025-08-30T14:00:00+00:00' AIRFLOW_CTX_TRY_NUMBER='2' AIRFLOW_CTX_DAG_RUN_ID='scheduled__2025-08-30T14:00:00+00:00'
[2025-08-31T04:49:25.168+0000] {base.py:73} INFO - Using connection ID 'spark-conn' for task execution.
[2025-08-31T04:49:25.175+0000] {spark_submit.py:403} INFO - Spark-Submit cmd: spark-submit --master spark://spark-master:7077 --jars /opt/spark/external-jars/apache-spark-sql-connector.jar --name arrow-spark --deploy-mode client jobs/python/wordcountjob.py
[2025-08-31T04:49:27.563+0000] {spark_submit.py:579} INFO - WARNING: Using incubator modules: jdk.incubator.vector
[2025-08-31T04:49:41.361+0000] {spark_submit.py:579} INFO - 25/08/31 04:49:40 WARN NativeCodeLoader: Unable to load native-hadoop library for your platform... using builtin-java classes where applicable
[2025-08-31T04:49:58.470+0000] {spark_submit.py:579} INFO - Using Spark's default log4j profile: org/apache/spark/log4j2-defaults.properties
[2025-08-31T04:49:58.551+0000] {spark_submit.py:579} INFO - 25/08/31 04:49:58 INFO SparkContext: Running Spark version 4.0.0
[2025-08-31T04:49:58.631+0000] {spark_submit.py:579} INFO - 25/08/31 04:49:58 INFO SparkContext: OS info Linux, 6.6.87.2-microsoft-standard-WSL2, amd64
[2025-08-31T04:49:58.662+0000] {spark_submit.py:579} INFO - 25/08/31 04:49:58 INFO SparkContext: Java version 17.0.15
[2025-08-31T04:49:58.993+0000] {spark_submit.py:579} INFO - 25/08/31 04:49:58 INFO ResourceUtils: ==============================================================
[2025-08-31T04:49:59.003+0000] {spark_submit.py:579} INFO - 25/08/31 04:49:58 INFO ResourceUtils: No custom resources configured for spark.driver.
[2025-08-31T04:49:59.004+0000] {spark_submit.py:579} INFO - 25/08/31 04:49:58 INFO ResourceUtils: ==============================================================
[2025-08-31T04:49:59.005+0000] {spark_submit.py:579} INFO - 25/08/31 04:49:58 INFO SparkContext: Submitted application: PythonWordCount
[2025-08-31T04:49:59.525+0000] {spark_submit.py:579} INFO - 25/08/31 04:49:59 INFO ResourceProfile: Default ResourceProfile created, executor resources: Map(memory -> name: memory, amount: 1024, script: , vendor: , offHeap -> name: offHeap, amount: 0, script: , vendor: ), task resources: Map(cpus -> name: cpus, amount: 1.0)
[2025-08-31T04:49:59.616+0000] {spark_submit.py:579} INFO - 25/08/31 04:49:59 INFO ResourceProfile: Limiting resource is cpu
[2025-08-31T04:49:59.622+0000] {spark_submit.py:579} INFO - 25/08/31 04:49:59 INFO ResourceProfileManager: Added ResourceProfile id: 0
[2025-08-31T04:50:00.973+0000] {spark_submit.py:579} INFO - 25/08/31 04:50:00 INFO SecurityManager: Changing view acls to: ***
[2025-08-31T04:50:01.065+0000] {spark_submit.py:579} INFO - 25/08/31 04:50:00 INFO SecurityManager: Changing modify acls to: ***
[2025-08-31T04:50:01.067+0000] {spark_submit.py:579} INFO - 25/08/31 04:50:00 INFO SecurityManager: Changing view acls groups to: ***
[2025-08-31T04:50:01.068+0000] {spark_submit.py:579} INFO - 25/08/31 04:50:01 INFO SecurityManager: Changing modify acls groups to: ***
[2025-08-31T04:50:01.102+0000] {spark_submit.py:579} INFO - 25/08/31 04:50:01 INFO SecurityManager: SecurityManager: authentication disabled; ui acls disabled; users with view permissions: *** groups with view permissions: EMPTY; users with modify permissions: ***; groups with modify permissions: EMPTY; RPC SSL disabled
[2025-08-31T04:50:04.972+0000] {spark_submit.py:579} INFO - 25/08/31 04:50:04 INFO Utils: Successfully started service 'sparkDriver' on port 40185.
[2025-08-31T04:50:05.129+0000] {spark_submit.py:579} INFO - 25/08/31 04:50:05 INFO SparkEnv: Registering MapOutputTracker
[2025-08-31T04:50:05.154+0000] {spark_submit.py:579} INFO - 25/08/31 04:50:05 INFO SparkEnv: Registering BlockManagerMaster
[2025-08-31T04:50:05.195+0000] {spark_submit.py:579} INFO - 25/08/31 04:50:05 INFO BlockManagerMasterEndpoint: Using org.apache.spark.storage.DefaultTopologyMapper for getting topology information
[2025-08-31T04:50:05.196+0000] {spark_submit.py:579} INFO - 25/08/31 04:50:05 INFO BlockManagerMasterEndpoint: BlockManagerMasterEndpoint up
[2025-08-31T04:50:05.201+0000] {spark_submit.py:579} INFO - 25/08/31 04:50:05 INFO SparkEnv: Registering BlockManagerMasterHeartbeat
[2025-08-31T04:50:06.530+0000] {spark_submit.py:579} INFO - 25/08/31 04:50:06 INFO DiskBlockManager: Created local directory at /tmp/blockmgr-f0d3c81f-f2ec-4453-bde0-643e2c5b3cad
[2025-08-31T04:50:06.618+0000] {spark_submit.py:579} INFO - 25/08/31 04:50:06 INFO SparkEnv: Registering OutputCommitCoordinator
[2025-08-31T04:50:07.830+0000] {spark_submit.py:579} INFO - 25/08/31 04:50:07 INFO JettyUtils: Start Jetty 0.0.0.0:4040 for SparkUI
[2025-08-31T04:50:08.343+0000] {spark_submit.py:579} INFO - 25/08/31 04:50:08 WARN Utils: Service 'SparkUI' could not bind on port 4040. Attempting port 4041.
[2025-08-31T04:50:08.345+0000] {spark_submit.py:579} INFO - 25/08/31 04:50:08 WARN Utils: Service 'SparkUI' could not bind on port 4041. Attempting port 4042.
[2025-08-31T04:50:08.352+0000] {spark_submit.py:579} INFO - 25/08/31 04:50:08 WARN Utils: Service 'SparkUI' could not bind on port 4042. Attempting port 4043.
[2025-08-31T04:50:08.354+0000] {spark_submit.py:579} INFO - 25/08/31 04:50:08 WARN Utils: Service 'SparkUI' could not bind on port 4043. Attempting port 4044.
[2025-08-31T04:50:08.364+0000] {spark_submit.py:579} INFO - 25/08/31 04:50:08 WARN Utils: Service 'SparkUI' could not bind on port 4044. Attempting port 4045.
[2025-08-31T04:50:08.366+0000] {spark_submit.py:579} INFO - 25/08/31 04:50:08 WARN Utils: Service 'SparkUI' could not bind on port 4045. Attempting port 4046.
[2025-08-31T04:50:08.369+0000] {spark_submit.py:579} INFO - 25/08/31 04:50:08 WARN Utils: Service 'SparkUI' could not bind on port 4046. Attempting port 4047.
[2025-08-31T04:50:08.383+0000] {spark_submit.py:579} INFO - 25/08/31 04:50:08 WARN Utils: Service 'SparkUI' could not bind on port 4047. Attempting port 4048.
[2025-08-31T04:50:08.387+0000] {spark_submit.py:579} INFO - 25/08/31 04:50:08 WARN Utils: Service 'SparkUI' could not bind on port 4048. Attempting port 4049.
[2025-08-31T04:50:08.388+0000] {spark_submit.py:579} INFO - 25/08/31 04:50:08 WARN Utils: Service 'SparkUI' could not bind on port 4049. Attempting port 4050.
[2025-08-31T04:50:08.391+0000] {spark_submit.py:579} INFO - 25/08/31 04:50:08 WARN Utils: Service 'SparkUI' could not bind on port 4050. Attempting port 4051.
[2025-08-31T04:50:08.398+0000] {spark_submit.py:579} INFO - 25/08/31 04:50:08 WARN Utils: Service 'SparkUI' could not bind on port 4051. Attempting port 4052.
[2025-08-31T04:50:08.401+0000] {spark_submit.py:579} INFO - 25/08/31 04:50:08 WARN Utils: Service 'SparkUI' could not bind on port 4052. Attempting port 4053.
[2025-08-31T04:50:08.443+0000] {spark_submit.py:579} INFO - 25/08/31 04:50:08 INFO Utils: Successfully started service 'SparkUI' on port 4053.
[2025-08-31T04:50:08.658+0000] {spark_submit.py:579} INFO - 25/08/31 04:50:08 INFO SparkContext: Added JAR file:///opt/spark/external-jars/apache-spark-sql-connector.jar at spark://81b7fe425a18:40185/jars/apache-spark-sql-connector.jar with timestamp 1756615798351
[2025-08-31T04:50:08.740+0000] {spark_submit.py:579} INFO - 25/08/31 04:50:08 INFO SecurityManager: Changing view acls to: ***
[2025-08-31T04:50:08.741+0000] {spark_submit.py:579} INFO - 25/08/31 04:50:08 INFO SecurityManager: Changing modify acls to: ***
[2025-08-31T04:50:08.743+0000] {spark_submit.py:579} INFO - 25/08/31 04:50:08 INFO SecurityManager: Changing view acls groups to: ***
[2025-08-31T04:50:08.770+0000] {spark_submit.py:579} INFO - 25/08/31 04:50:08 INFO SecurityManager: Changing modify acls groups to: ***
[2025-08-31T04:50:08.781+0000] {spark_submit.py:579} INFO - 25/08/31 04:50:08 INFO SecurityManager: SecurityManager: authentication disabled; ui acls disabled; users with view permissions: *** groups with view permissions: EMPTY; users with modify permissions: ***; groups with modify permissions: EMPTY; RPC SSL disabled
[2025-08-31T04:50:09.692+0000] {spark_submit.py:579} INFO - 25/08/31 04:50:09 INFO StandaloneAppClient$ClientEndpoint: Connecting to master spark://spark-master:7077...
[2025-08-31T04:50:09.903+0000] {spark_submit.py:579} INFO - 25/08/31 04:50:09 INFO TransportClientFactory: Successfully created connection to spark-master/172.18.0.2:7077 after 64 ms (0 ms spent in bootstraps)
[2025-08-31T04:50:11.255+0000] {spark_submit.py:579} INFO - 25/08/31 04:50:11 INFO StandaloneSchedulerBackend: Connected to Spark cluster with app ID app-20250831045011-0000
[2025-08-31T04:50:11.265+0000] {spark_submit.py:579} INFO - 25/08/31 04:50:11 INFO Utils: Successfully started service 'org.apache.spark.network.netty.NettyBlockTransferService' on port 43151.
[2025-08-31T04:50:11.266+0000] {spark_submit.py:579} INFO - 25/08/31 04:50:11 INFO NettyBlockTransferService: Server created on 81b7fe425a18:43151
[2025-08-31T04:50:11.268+0000] {spark_submit.py:579} INFO - 25/08/31 04:50:11 INFO BlockManager: Using org.apache.spark.storage.RandomBlockReplicationPolicy for block replication policy
[2025-08-31T04:50:11.289+0000] {spark_submit.py:579} INFO - 25/08/31 04:50:11 INFO BlockManagerMaster: Registering BlockManager BlockManagerId(driver, 81b7fe425a18, 43151, None)
[2025-08-31T04:50:11.299+0000] {spark_submit.py:579} INFO - 25/08/31 04:50:11 INFO BlockManagerMasterEndpoint: Registering block manager 81b7fe425a18:43151 with 434.4 MiB RAM, BlockManagerId(driver, 81b7fe425a18, 43151, None)
[2025-08-31T04:50:11.301+0000] {spark_submit.py:579} INFO - 25/08/31 04:50:11 INFO BlockManagerMaster: Registered BlockManager BlockManagerId(driver, 81b7fe425a18, 43151, None)
[2025-08-31T04:50:11.303+0000] {spark_submit.py:579} INFO - 25/08/31 04:50:11 INFO BlockManager: Initialized BlockManager: BlockManagerId(driver, 81b7fe425a18, 43151, None)
[2025-08-31T04:50:11.485+0000] {spark_submit.py:579} INFO - 25/08/31 04:50:11 INFO StandaloneAppClient$ClientEndpoint: Executor added: app-20250831045011-0000/0 on worker-20250831044911-172.18.0.4-42379 (172.18.0.4:42379) with 2 core(s)
[2025-08-31T04:50:11.489+0000] {spark_submit.py:579} INFO - 25/08/31 04:50:11 INFO StandaloneSchedulerBackend: Granted executor ID app-20250831045011-0000/0 on hostPort 172.18.0.4:42379 with 2 core(s), 1024.0 MiB RAM
[2025-08-31T04:50:11.538+0000] {spark_submit.py:579} INFO - 25/08/31 04:50:11 INFO StandaloneSchedulerBackend: SchedulerBackend is ready for scheduling beginning after reached minRegisteredResourcesRatio: 0.0
[2025-08-31T04:50:24.675+0000] {job.py:219} ERROR - Job heartbeat got an exception
Traceback (most recent call last):
  File "/home/airflow/.local/lib/python3.10/site-packages/sqlalchemy/engine/base.py", line 3371, in _wrap_pool_connect
    return fn()
  File "/home/airflow/.local/lib/python3.10/site-packages/sqlalchemy/pool/base.py", line 327, in connect
    return _ConnectionFairy._checkout(self)
  File "/home/airflow/.local/lib/python3.10/site-packages/sqlalchemy/pool/base.py", line 894, in _checkout
    fairy = _ConnectionRecord.checkout(pool)
  File "/home/airflow/.local/lib/python3.10/site-packages/sqlalchemy/pool/base.py", line 493, in checkout
    rec = pool._do_get()
  File "/home/airflow/.local/lib/python3.10/site-packages/sqlalchemy/pool/impl.py", line 256, in _do_get
    return self._create_connection()
  File "/home/airflow/.local/lib/python3.10/site-packages/sqlalchemy/pool/base.py", line 273, in _create_connection
    return _ConnectionRecord(self)
  File "/home/airflow/.local/lib/python3.10/site-packages/sqlalchemy/pool/base.py", line 388, in __init__
    self.__connect()
  File "/home/airflow/.local/lib/python3.10/site-packages/sqlalchemy/pool/base.py", line 690, in __connect
    with util.safe_reraise():
  File "/home/airflow/.local/lib/python3.10/site-packages/sqlalchemy/util/langhelpers.py", line 70, in __exit__
    compat.raise_(
  File "/home/airflow/.local/lib/python3.10/site-packages/sqlalchemy/util/compat.py", line 211, in raise_
    raise exception
  File "/home/airflow/.local/lib/python3.10/site-packages/sqlalchemy/pool/base.py", line 686, in __connect
    self.dbapi_connection = connection = pool._invoke_creator(self)
  File "/home/airflow/.local/lib/python3.10/site-packages/sqlalchemy/engine/create.py", line 574, in connect
    return dialect.connect(*cargs, **cparams)
  File "/home/airflow/.local/lib/python3.10/site-packages/sqlalchemy/engine/default.py", line 598, in connect
    return self.dbapi.connect(*cargs, **cparams)
  File "/home/airflow/.local/lib/python3.10/site-packages/psycopg2/__init__.py", line 122, in connect
    conn = _connect(dsn, connection_factory=connection_factory, **kwasync)
psycopg2.OperationalError: could not translate host name "postgres" to address: Temporary failure in name resolution


The above exception was the direct cause of the following exception:

Traceback (most recent call last):
  File "/home/airflow/.local/lib/python3.10/site-packages/airflow/jobs/job.py", line 190, in heartbeat
    session.merge(self)
  File "/home/airflow/.local/lib/python3.10/site-packages/sqlalchemy/orm/session.py", line 3056, in merge
    return self._merge(
  File "/home/airflow/.local/lib/python3.10/site-packages/sqlalchemy/orm/session.py", line 3136, in _merge
    merged = self.get(
  File "/home/airflow/.local/lib/python3.10/site-packages/sqlalchemy/orm/session.py", line 2853, in get
    return self._get_impl(
  File "/home/airflow/.local/lib/python3.10/site-packages/sqlalchemy/orm/session.py", line 2975, in _get_impl
    return db_load_fn(
  File "/home/airflow/.local/lib/python3.10/site-packages/sqlalchemy/orm/loading.py", line 530, in load_on_pk_identity
    session.execute(
  File "/home/airflow/.local/lib/python3.10/site-packages/sqlalchemy/orm/session.py", line 1716, in execute
    conn = self._connection_for_bind(bind)
  File "/home/airflow/.local/lib/python3.10/site-packages/sqlalchemy/orm/session.py", line 1555, in _connection_for_bind
    return self._transaction._connection_for_bind(
  File "/home/airflow/.local/lib/python3.10/site-packages/sqlalchemy/orm/session.py", line 750, in _connection_for_bind
    conn = bind.connect()
  File "/home/airflow/.local/lib/python3.10/site-packages/sqlalchemy/future/engine.py", line 406, in connect
    return super(Engine, self).connect()
  File "/home/airflow/.local/lib/python3.10/site-packages/sqlalchemy/engine/base.py", line 3325, in connect
    return self._connection_cls(self, close_with_result=close_with_result)
  File "/home/airflow/.local/lib/python3.10/site-packages/sqlalchemy/engine/base.py", line 96, in __init__
    else engine.raw_connection()
  File "/home/airflow/.local/lib/python3.10/site-packages/sqlalchemy/engine/base.py", line 3404, in raw_connection
    return self._wrap_pool_connect(self.pool.connect, _connection)
  File "/home/airflow/.local/lib/python3.10/site-packages/sqlalchemy/engine/base.py", line 3374, in _wrap_pool_connect
    Connection._handle_dbapi_exception_noconnection(
  File "/home/airflow/.local/lib/python3.10/site-packages/sqlalchemy/engine/base.py", line 2208, in _handle_dbapi_exception_noconnection
    util.raise_(
  File "/home/airflow/.local/lib/python3.10/site-packages/sqlalchemy/util/compat.py", line 211, in raise_
    raise exception
  File "/home/airflow/.local/lib/python3.10/site-packages/sqlalchemy/engine/base.py", line 3371, in _wrap_pool_connect
    return fn()
  File "/home/airflow/.local/lib/python3.10/site-packages/sqlalchemy/pool/base.py", line 327, in connect
    return _ConnectionFairy._checkout(self)
  File "/home/airflow/.local/lib/python3.10/site-packages/sqlalchemy/pool/base.py", line 894, in _checkout
    fairy = _ConnectionRecord.checkout(pool)
  File "/home/airflow/.local/lib/python3.10/site-packages/sqlalchemy/pool/base.py", line 493, in checkout
    rec = pool._do_get()
  File "/home/airflow/.local/lib/python3.10/site-packages/sqlalchemy/pool/impl.py", line 256, in _do_get
    return self._create_connection()
  File "/home/airflow/.local/lib/python3.10/site-packages/sqlalchemy/pool/base.py", line 273, in _create_connection
    return _ConnectionRecord(self)
  File "/home/airflow/.local/lib/python3.10/site-packages/sqlalchemy/pool/base.py", line 388, in __init__
    self.__connect()
  File "/home/airflow/.local/lib/python3.10/site-packages/sqlalchemy/pool/base.py", line 690, in __connect
    with util.safe_reraise():
  File "/home/airflow/.local/lib/python3.10/site-packages/sqlalchemy/util/langhelpers.py", line 70, in __exit__
    compat.raise_(
  File "/home/airflow/.local/lib/python3.10/site-packages/sqlalchemy/util/compat.py", line 211, in raise_
    raise exception
  File "/home/airflow/.local/lib/python3.10/site-packages/sqlalchemy/pool/base.py", line 686, in __connect
    self.dbapi_connection = connection = pool._invoke_creator(self)
  File "/home/airflow/.local/lib/python3.10/site-packages/sqlalchemy/engine/create.py", line 574, in connect
    return dialect.connect(*cargs, **cparams)
  File "/home/airflow/.local/lib/python3.10/site-packages/sqlalchemy/engine/default.py", line 598, in connect
    return self.dbapi.connect(*cargs, **cparams)
  File "/home/airflow/.local/lib/python3.10/site-packages/psycopg2/__init__.py", line 122, in connect
    conn = _connect(dsn, connection_factory=connection_factory, **kwasync)
sqlalchemy.exc.OperationalError: (psycopg2.OperationalError) could not translate host name "postgres" to address: Temporary failure in name resolution

(Background on this error at: https://sqlalche.me/e/14/e3q8)
