[2025-08-31T04:30:51.066+0000] {taskinstance.py:1157} INFO - Dependencies all met for dep_context=non-requeueable deps ti=<TaskInstance: sparking_flow.python_job scheduled__2025-08-30T14:00:00+00:00 [queued]>
[2025-08-31T04:30:51.088+0000] {taskinstance.py:1157} INFO - Dependencies all met for dep_context=requeueable deps ti=<TaskInstance: sparking_flow.python_job scheduled__2025-08-30T14:00:00+00:00 [queued]>
[2025-08-31T04:30:51.094+0000] {taskinstance.py:1359} INFO - Starting attempt 1 of 1
[2025-08-31T04:30:51.186+0000] {taskinstance.py:1380} INFO - Executing <Task(SparkSubmitOperator): python_job> on 2025-08-30 14:00:00+00:00
[2025-08-31T04:30:51.257+0000] {standard_task_runner.py:57} INFO - Started process 504 to run task
[2025-08-31T04:30:51.276+0000] {standard_task_runner.py:84} INFO - Running: ['***', 'tasks', 'run', 'sparking_flow', 'python_job', 'scheduled__2025-08-30T14:00:00+00:00', '--job-id', '86', '--raw', '--subdir', 'DAGS_FOLDER/spark_***.py', '--cfg-path', '/tmp/tmpt56b6lq9']
[2025-08-31T04:30:51.312+0000] {standard_task_runner.py:85} INFO - Job 86: Subtask python_job
[2025-08-31T04:30:51.616+0000] {task_command.py:415} INFO - Running <TaskInstance: sparking_flow.python_job scheduled__2025-08-30T14:00:00+00:00 [running]> on host 81b7fe425a18
[2025-08-31T04:30:52.161+0000] {taskinstance.py:1660} INFO - Exporting env vars: AIRFLOW_CTX_DAG_OWNER='Kudzaishe Manyanya' AIRFLOW_CTX_DAG_ID='sparking_flow' AIRFLOW_CTX_TASK_ID='python_job' AIRFLOW_CTX_EXECUTION_DATE='2025-08-30T14:00:00+00:00' AIRFLOW_CTX_TRY_NUMBER='1' AIRFLOW_CTX_DAG_RUN_ID='scheduled__2025-08-30T14:00:00+00:00'
[2025-08-31T04:30:52.280+0000] {base.py:73} INFO - Using connection ID 'spark-conn' for task execution.
[2025-08-31T04:30:52.283+0000] {spark_submit.py:403} INFO - Spark-Submit cmd: spark-submit --master spark://spark-master:7077 --jars /opt/spark/external-jars/apache-spark-sql-connector.jar --name arrow-spark --deploy-mode client jobs/python/wordcountjob.py
[2025-08-31T04:31:08.453+0000] {spark_submit.py:579} INFO - WARNING: Using incubator modules: jdk.incubator.vector
[2025-08-31T04:31:53.137+0000] {spark_submit.py:579} INFO - 25/08/31 04:31:53 WARN NativeCodeLoader: Unable to load native-hadoop library for your platform... using builtin-java classes where applicable
[2025-08-31T04:33:11.145+0000] {spark_submit.py:579} INFO - Using Spark's default log4j profile: org/apache/spark/log4j2-defaults.properties
[2025-08-31T04:33:11.731+0000] {spark_submit.py:579} INFO - 25/08/31 04:33:11 INFO SparkContext: Running Spark version 4.0.0
[2025-08-31T04:33:11.743+0000] {spark_submit.py:579} INFO - 25/08/31 04:33:11 INFO SparkContext: OS info Linux, 6.6.87.2-microsoft-standard-WSL2, amd64
[2025-08-31T04:33:11.747+0000] {spark_submit.py:579} INFO - 25/08/31 04:33:11 INFO SparkContext: Java version 17.0.15
[2025-08-31T04:33:13.314+0000] {spark_submit.py:579} INFO - 25/08/31 04:33:13 INFO ResourceUtils: ==============================================================
[2025-08-31T04:33:13.335+0000] {spark_submit.py:579} INFO - 25/08/31 04:33:13 INFO ResourceUtils: No custom resources configured for spark.driver.
[2025-08-31T04:33:13.343+0000] {spark_submit.py:579} INFO - 25/08/31 04:33:13 INFO ResourceUtils: ==============================================================
[2025-08-31T04:33:13.344+0000] {spark_submit.py:579} INFO - 25/08/31 04:33:13 INFO SparkContext: Submitted application: PythonWordCount
[2025-08-31T04:33:13.906+0000] {spark_submit.py:579} INFO - 25/08/31 04:33:13 INFO ResourceProfile: Default ResourceProfile created, executor resources: Map(memory -> name: memory, amount: 1024, script: , vendor: , offHeap -> name: offHeap, amount: 0, script: , vendor: ), task resources: Map(cpus -> name: cpus, amount: 1.0)
[2025-08-31T04:33:13.954+0000] {spark_submit.py:579} INFO - 25/08/31 04:33:13 INFO ResourceProfile: Limiting resource is cpu
[2025-08-31T04:33:14.587+0000] {spark_submit.py:579} INFO - 25/08/31 04:33:14 INFO ResourceProfileManager: Added ResourceProfile id: 0
[2025-08-31T04:33:20.603+0000] {spark_submit.py:579} INFO - 25/08/31 04:33:20 INFO SecurityManager: Changing view acls to: ***
[2025-08-31T04:33:20.743+0000] {spark_submit.py:579} INFO - 25/08/31 04:33:20 INFO SecurityManager: Changing modify acls to: ***
[2025-08-31T04:33:20.745+0000] {spark_submit.py:579} INFO - 25/08/31 04:33:20 INFO SecurityManager: Changing view acls groups to: ***
[2025-08-31T04:33:20.751+0000] {spark_submit.py:579} INFO - 25/08/31 04:33:20 INFO SecurityManager: Changing modify acls groups to: ***
[2025-08-31T04:33:20.753+0000] {spark_submit.py:579} INFO - 25/08/31 04:33:20 INFO SecurityManager: SecurityManager: authentication disabled; ui acls disabled; users with view permissions: *** groups with view permissions: EMPTY; users with modify permissions: ***; groups with modify permissions: EMPTY; RPC SSL disabled
[2025-08-31T04:33:33.079+0000] {spark_submit.py:579} INFO - 25/08/31 04:33:32 INFO Utils: Successfully started service 'sparkDriver' on port 35229.
[2025-08-31T04:33:33.418+0000] {spark_submit.py:579} INFO - 25/08/31 04:33:33 INFO SparkEnv: Registering MapOutputTracker
[2025-08-31T04:33:33.642+0000] {spark_submit.py:579} INFO - 25/08/31 04:33:33 INFO SparkEnv: Registering BlockManagerMaster
[2025-08-31T04:33:33.931+0000] {spark_submit.py:579} INFO - 25/08/31 04:33:33 INFO BlockManagerMasterEndpoint: Using org.apache.spark.storage.DefaultTopologyMapper for getting topology information
[2025-08-31T04:33:33.947+0000] {spark_submit.py:579} INFO - 25/08/31 04:33:33 INFO BlockManagerMasterEndpoint: BlockManagerMasterEndpoint up
[2025-08-31T04:33:34.103+0000] {spark_submit.py:579} INFO - 25/08/31 04:33:34 INFO SparkEnv: Registering BlockManagerMasterHeartbeat
[2025-08-31T04:33:34.461+0000] {spark_submit.py:579} INFO - 25/08/31 04:33:34 INFO DiskBlockManager: Created local directory at /tmp/blockmgr-1590a6d8-8756-4182-9e6e-c8085908d7a0
[2025-08-31T04:33:34.782+0000] {spark_submit.py:579} INFO - 25/08/31 04:33:34 INFO SparkEnv: Registering OutputCommitCoordinator
[2025-08-31T04:33:37.120+0000] {spark_submit.py:579} INFO - 25/08/31 04:33:36 INFO JettyUtils: Start Jetty 0.0.0.0:4040 for SparkUI
[2025-08-31T04:33:40.043+0000] {spark_submit.py:579} INFO - 25/08/31 04:33:39 WARN Utils: Service 'SparkUI' could not bind on port 4040. Attempting port 4041.
[2025-08-31T04:33:40.139+0000] {spark_submit.py:579} INFO - 25/08/31 04:33:40 WARN Utils: Service 'SparkUI' could not bind on port 4041. Attempting port 4042.
[2025-08-31T04:33:40.183+0000] {spark_submit.py:579} INFO - 25/08/31 04:33:40 WARN Utils: Service 'SparkUI' could not bind on port 4042. Attempting port 4043.
[2025-08-31T04:33:40.563+0000] {spark_submit.py:579} INFO - 25/08/31 04:33:40 INFO Utils: Successfully started service 'SparkUI' on port 4043.
[2025-08-31T04:33:44.715+0000] {spark_submit.py:579} INFO - 25/08/31 04:33:44 INFO SparkContext: Added JAR file:///opt/spark/external-jars/apache-spark-sql-connector.jar at spark://81b7fe425a18:35229/jars/apache-spark-sql-connector.jar with timestamp 1756614790101
[2025-08-31T04:33:45.894+0000] {spark_submit.py:579} INFO - 25/08/31 04:33:45 INFO SecurityManager: Changing view acls to: ***
[2025-08-31T04:33:46.995+0000] {spark_submit.py:579} INFO - 25/08/31 04:33:45 INFO SecurityManager: Changing modify acls to: ***
[2025-08-31T04:33:47.030+0000] {spark_submit.py:579} INFO - 25/08/31 04:33:45 INFO SecurityManager: Changing view acls groups to: ***
[2025-08-31T04:33:47.033+0000] {spark_submit.py:579} INFO - 25/08/31 04:33:45 INFO SecurityManager: Changing modify acls groups to: ***
[2025-08-31T04:33:47.057+0000] {spark_submit.py:579} INFO - 25/08/31 04:33:46 INFO SecurityManager: SecurityManager: authentication disabled; ui acls disabled; users with view permissions: *** groups with view permissions: EMPTY; users with modify permissions: ***; groups with modify permissions: EMPTY; RPC SSL disabled
[2025-08-31T04:33:57.971+0000] {spark_submit.py:579} INFO - 25/08/31 04:33:57 INFO StandaloneAppClient$ClientEndpoint: Connecting to master spark://spark-master:7077...
[2025-08-31T04:34:04.497+0000] {spark_submit.py:579} INFO - 25/08/31 04:34:04 INFO TransportClientFactory: Successfully created connection to spark-master/172.18.0.2:7077 after 3187 ms (32 ms spent in bootstraps)
[2025-08-31T04:34:08.199+0000] {spark_submit.py:579} INFO - 25/08/31 04:34:08 INFO StandaloneSchedulerBackend: Connected to Spark cluster with app ID app-20250831043408-0009
[2025-08-31T04:34:08.396+0000] {spark_submit.py:579} INFO - 25/08/31 04:34:08 INFO Utils: Successfully started service 'org.apache.spark.network.netty.NettyBlockTransferService' on port 41121.
[2025-08-31T04:34:08.401+0000] {spark_submit.py:579} INFO - 25/08/31 04:34:08 INFO NettyBlockTransferService: Server created on 81b7fe425a18:41121
[2025-08-31T04:34:08.439+0000] {spark_submit.py:579} INFO - 25/08/31 04:34:08 INFO BlockManager: Using org.apache.spark.storage.RandomBlockReplicationPolicy for block replication policy
[2025-08-31T04:34:08.762+0000] {spark_submit.py:579} INFO - 25/08/31 04:34:08 INFO BlockManagerMaster: Registering BlockManager BlockManagerId(driver, 81b7fe425a18, 41121, None)
[2025-08-31T04:34:09.016+0000] {spark_submit.py:579} INFO - 25/08/31 04:34:08 INFO BlockManagerMasterEndpoint: Registering block manager 81b7fe425a18:41121 with 434.4 MiB RAM, BlockManagerId(driver, 81b7fe425a18, 41121, None)
[2025-08-31T04:34:09.049+0000] {spark_submit.py:579} INFO - 25/08/31 04:34:09 INFO BlockManagerMaster: Registered BlockManager BlockManagerId(driver, 81b7fe425a18, 41121, None)
[2025-08-31T04:34:09.063+0000] {spark_submit.py:579} INFO - 25/08/31 04:34:09 INFO BlockManager: Initialized BlockManager: BlockManagerId(driver, 81b7fe425a18, 41121, None)
[2025-08-31T04:35:11.660+0000] {job.py:219} ERROR - Job heartbeat got an exception
Traceback (most recent call last):
  File "/home/airflow/.local/lib/python3.10/site-packages/sqlalchemy/engine/base.py", line 3371, in _wrap_pool_connect
    return fn()
  File "/home/airflow/.local/lib/python3.10/site-packages/sqlalchemy/pool/base.py", line 327, in connect
    return _ConnectionFairy._checkout(self)
  File "/home/airflow/.local/lib/python3.10/site-packages/sqlalchemy/pool/base.py", line 894, in _checkout
    fairy = _ConnectionRecord.checkout(pool)
  File "/home/airflow/.local/lib/python3.10/site-packages/sqlalchemy/pool/base.py", line 493, in checkout
    rec = pool._do_get()
  File "/home/airflow/.local/lib/python3.10/site-packages/sqlalchemy/pool/impl.py", line 256, in _do_get
    return self._create_connection()
  File "/home/airflow/.local/lib/python3.10/site-packages/sqlalchemy/pool/base.py", line 273, in _create_connection
    return _ConnectionRecord(self)
  File "/home/airflow/.local/lib/python3.10/site-packages/sqlalchemy/pool/base.py", line 388, in __init__
    self.__connect()
  File "/home/airflow/.local/lib/python3.10/site-packages/sqlalchemy/pool/base.py", line 690, in __connect
    with util.safe_reraise():
  File "/home/airflow/.local/lib/python3.10/site-packages/sqlalchemy/util/langhelpers.py", line 70, in __exit__
    compat.raise_(
  File "/home/airflow/.local/lib/python3.10/site-packages/sqlalchemy/util/compat.py", line 211, in raise_
    raise exception
  File "/home/airflow/.local/lib/python3.10/site-packages/sqlalchemy/pool/base.py", line 686, in __connect
    self.dbapi_connection = connection = pool._invoke_creator(self)
  File "/home/airflow/.local/lib/python3.10/site-packages/sqlalchemy/engine/create.py", line 574, in connect
    return dialect.connect(*cargs, **cparams)
  File "/home/airflow/.local/lib/python3.10/site-packages/sqlalchemy/engine/default.py", line 598, in connect
    return self.dbapi.connect(*cargs, **cparams)
  File "/home/airflow/.local/lib/python3.10/site-packages/psycopg2/__init__.py", line 122, in connect
    conn = _connect(dsn, connection_factory=connection_factory, **kwasync)
psycopg2.OperationalError: could not translate host name "postgres" to address: Temporary failure in name resolution


The above exception was the direct cause of the following exception:

Traceback (most recent call last):
  File "/home/airflow/.local/lib/python3.10/site-packages/airflow/jobs/job.py", line 190, in heartbeat
    session.merge(self)
  File "/home/airflow/.local/lib/python3.10/site-packages/sqlalchemy/orm/session.py", line 3056, in merge
    return self._merge(
  File "/home/airflow/.local/lib/python3.10/site-packages/sqlalchemy/orm/session.py", line 3136, in _merge
    merged = self.get(
  File "/home/airflow/.local/lib/python3.10/site-packages/sqlalchemy/orm/session.py", line 2853, in get
    return self._get_impl(
  File "/home/airflow/.local/lib/python3.10/site-packages/sqlalchemy/orm/session.py", line 2975, in _get_impl
    return db_load_fn(
  File "/home/airflow/.local/lib/python3.10/site-packages/sqlalchemy/orm/loading.py", line 530, in load_on_pk_identity
    session.execute(
  File "/home/airflow/.local/lib/python3.10/site-packages/sqlalchemy/orm/session.py", line 1716, in execute
    conn = self._connection_for_bind(bind)
  File "/home/airflow/.local/lib/python3.10/site-packages/sqlalchemy/orm/session.py", line 1555, in _connection_for_bind
    return self._transaction._connection_for_bind(
  File "/home/airflow/.local/lib/python3.10/site-packages/sqlalchemy/orm/session.py", line 750, in _connection_for_bind
    conn = bind.connect()
  File "/home/airflow/.local/lib/python3.10/site-packages/sqlalchemy/future/engine.py", line 406, in connect
    return super(Engine, self).connect()
  File "/home/airflow/.local/lib/python3.10/site-packages/sqlalchemy/engine/base.py", line 3325, in connect
    return self._connection_cls(self, close_with_result=close_with_result)
  File "/home/airflow/.local/lib/python3.10/site-packages/sqlalchemy/engine/base.py", line 96, in __init__
    else engine.raw_connection()
  File "/home/airflow/.local/lib/python3.10/site-packages/sqlalchemy/engine/base.py", line 3404, in raw_connection
    return self._wrap_pool_connect(self.pool.connect, _connection)
  File "/home/airflow/.local/lib/python3.10/site-packages/sqlalchemy/engine/base.py", line 3374, in _wrap_pool_connect
    Connection._handle_dbapi_exception_noconnection(
  File "/home/airflow/.local/lib/python3.10/site-packages/sqlalchemy/engine/base.py", line 2208, in _handle_dbapi_exception_noconnection
    util.raise_(
  File "/home/airflow/.local/lib/python3.10/site-packages/sqlalchemy/util/compat.py", line 211, in raise_
    raise exception
  File "/home/airflow/.local/lib/python3.10/site-packages/sqlalchemy/engine/base.py", line 3371, in _wrap_pool_connect
    return fn()
  File "/home/airflow/.local/lib/python3.10/site-packages/sqlalchemy/pool/base.py", line 327, in connect
    return _ConnectionFairy._checkout(self)
  File "/home/airflow/.local/lib/python3.10/site-packages/sqlalchemy/pool/base.py", line 894, in _checkout
    fairy = _ConnectionRecord.checkout(pool)
  File "/home/airflow/.local/lib/python3.10/site-packages/sqlalchemy/pool/base.py", line 493, in checkout
    rec = pool._do_get()
  File "/home/airflow/.local/lib/python3.10/site-packages/sqlalchemy/pool/impl.py", line 256, in _do_get
    return self._create_connection()
  File "/home/airflow/.local/lib/python3.10/site-packages/sqlalchemy/pool/base.py", line 273, in _create_connection
    return _ConnectionRecord(self)
  File "/home/airflow/.local/lib/python3.10/site-packages/sqlalchemy/pool/base.py", line 388, in __init__
    self.__connect()
  File "/home/airflow/.local/lib/python3.10/site-packages/sqlalchemy/pool/base.py", line 690, in __connect
    with util.safe_reraise():
  File "/home/airflow/.local/lib/python3.10/site-packages/sqlalchemy/util/langhelpers.py", line 70, in __exit__
    compat.raise_(
  File "/home/airflow/.local/lib/python3.10/site-packages/sqlalchemy/util/compat.py", line 211, in raise_
    raise exception
  File "/home/airflow/.local/lib/python3.10/site-packages/sqlalchemy/pool/base.py", line 686, in __connect
    self.dbapi_connection = connection = pool._invoke_creator(self)
  File "/home/airflow/.local/lib/python3.10/site-packages/sqlalchemy/engine/create.py", line 574, in connect
    return dialect.connect(*cargs, **cparams)
  File "/home/airflow/.local/lib/python3.10/site-packages/sqlalchemy/engine/default.py", line 598, in connect
    return self.dbapi.connect(*cargs, **cparams)
  File "/home/airflow/.local/lib/python3.10/site-packages/psycopg2/__init__.py", line 122, in connect
    conn = _connect(dsn, connection_factory=connection_factory, **kwasync)
sqlalchemy.exc.OperationalError: (psycopg2.OperationalError) could not translate host name "postgres" to address: Temporary failure in name resolution

(Background on this error at: https://sqlalche.me/e/14/e3q8)
[2025-08-31T04:39:44.655+0000] {local_task_job_runner.py:205} ERROR - Heartbeat time limit exceeded!
[2025-08-31T04:39:47.941+0000] {process_utils.py:131} INFO - Sending 15 to group 504. PIDs of all processes in the group: [521, 1076, 504]
[2025-08-31T04:39:48.278+0000] {process_utils.py:86} INFO - Sending the signal 15 to group 504
[2025-08-31T04:39:48.470+0000] {process_utils.py:79} INFO - Process psutil.Process(pid=1076, status='terminated', started='04:31:54') (1076) terminated with exit code None
[2025-08-31T04:39:48.873+0000] {taskinstance.py:1630} ERROR - Received SIGTERM. Terminating subprocesses.
[2025-08-31T04:39:49.825+0000] {spark_submit.py:705} INFO - Sending kill signal to spark-submit
[2025-08-31T04:39:54.710+0000] {standard_task_runner.py:104} ERROR - Failed to execute job 86 for task python_job ((psycopg2.OperationalError) could not translate host name "postgres" to address: Temporary failure in name resolution

(Background on this error at: https://sqlalche.me/e/14/e3q8); 504)
[2025-08-31T04:39:54.867+0000] {process_utils.py:79} INFO - Process psutil.Process(pid=504, status='terminated', exitcode=1, started='04:30:50') (504) terminated with exit code 1
[2025-08-31T04:39:54.879+0000] {process_utils.py:79} INFO - Process psutil.Process(pid=521, status='terminated', started='04:30:51') (521) terminated with exit code None
[2025-08-31T05:06:41.032+0000] {taskinstance.py:1157} INFO - Dependencies all met for dep_context=non-requeueable deps ti=<TaskInstance: sparking_flow.python_job scheduled__2025-08-30T14:00:00+00:00 [queued]>
[2025-08-31T05:06:41.061+0000] {taskinstance.py:1157} INFO - Dependencies all met for dep_context=requeueable deps ti=<TaskInstance: sparking_flow.python_job scheduled__2025-08-30T14:00:00+00:00 [queued]>
[2025-08-31T05:06:41.063+0000] {taskinstance.py:1359} INFO - Starting attempt 1 of 1
[2025-08-31T05:06:41.115+0000] {taskinstance.py:1380} INFO - Executing <Task(SparkSubmitOperator): python_job> on 2025-08-30 14:00:00+00:00
[2025-08-31T05:06:41.129+0000] {standard_task_runner.py:57} INFO - Started process 346 to run task
[2025-08-31T05:06:41.138+0000] {standard_task_runner.py:84} INFO - Running: ['***', 'tasks', 'run', 'sparking_flow', 'python_job', 'scheduled__2025-08-30T14:00:00+00:00', '--job-id', '24', '--raw', '--subdir', 'DAGS_FOLDER/spark_***.py', '--cfg-path', '/tmp/tmpqgieeh1j']
[2025-08-31T05:06:41.150+0000] {standard_task_runner.py:85} INFO - Job 24: Subtask python_job
[2025-08-31T05:06:41.495+0000] {task_command.py:415} INFO - Running <TaskInstance: sparking_flow.python_job scheduled__2025-08-30T14:00:00+00:00 [running]> on host 80647ef95998
[2025-08-31T05:06:42.924+0000] {taskinstance.py:1660} INFO - Exporting env vars: AIRFLOW_CTX_DAG_OWNER='Kudzaishe Manyanya' AIRFLOW_CTX_DAG_ID='sparking_flow' AIRFLOW_CTX_TASK_ID='python_job' AIRFLOW_CTX_EXECUTION_DATE='2025-08-30T14:00:00+00:00' AIRFLOW_CTX_TRY_NUMBER='1' AIRFLOW_CTX_DAG_RUN_ID='scheduled__2025-08-30T14:00:00+00:00'
[2025-08-31T05:06:43.059+0000] {spark_submit.py:273} INFO - Could not load connection string spark-conn, defaulting to yarn
[2025-08-31T05:06:43.076+0000] {spark_submit.py:403} INFO - Spark-Submit cmd: spark-submit --master yarn --jars /opt/spark/external-jars/apache-spark-sql-connector.jar --name arrow-spark jobs/python/wordcountjob.py
[2025-08-31T05:06:45.912+0000] {spark_submit.py:579} INFO - WARNING: Using incubator modules: jdk.incubator.vector
[2025-08-31T05:06:55.402+0000] {spark_submit.py:579} INFO - Exception in thread "main" org.apache.spark.SparkException: When running with master 'yarn' either HADOOP_CONF_DIR or YARN_CONF_DIR must be set in the environment.
[2025-08-31T05:06:55.409+0000] {spark_submit.py:579} INFO - at org.apache.spark.deploy.SparkSubmitArguments.error(SparkSubmitArguments.scala:640)
[2025-08-31T05:06:55.410+0000] {spark_submit.py:579} INFO - at org.apache.spark.deploy.SparkSubmitArguments.validateSubmitArguments(SparkSubmitArguments.scala:287)
[2025-08-31T05:06:55.411+0000] {spark_submit.py:579} INFO - at org.apache.spark.deploy.SparkSubmitArguments.validateArguments(SparkSubmitArguments.scala:245)
[2025-08-31T05:06:55.411+0000] {spark_submit.py:579} INFO - at org.apache.spark.deploy.SparkSubmitArguments.<init>(SparkSubmitArguments.scala:104)
[2025-08-31T05:06:55.412+0000] {spark_submit.py:579} INFO - at org.apache.spark.deploy.SparkSubmit$$anon$2$$anon$3.<init>(SparkSubmit.scala:1101)
[2025-08-31T05:06:55.412+0000] {spark_submit.py:579} INFO - at org.apache.spark.deploy.SparkSubmit$$anon$2.parseArguments(SparkSubmit.scala:1101)
[2025-08-31T05:06:55.412+0000] {spark_submit.py:579} INFO - at org.apache.spark.deploy.SparkSubmit.doSubmit(SparkSubmit.scala:72)
[2025-08-31T05:06:55.413+0000] {spark_submit.py:579} INFO - at org.apache.spark.deploy.SparkSubmit$$anon$2.doSubmit(SparkSubmit.scala:1132)
[2025-08-31T05:06:55.414+0000] {spark_submit.py:579} INFO - at org.apache.spark.deploy.SparkSubmit$.main(SparkSubmit.scala:1141)
[2025-08-31T05:06:55.416+0000] {spark_submit.py:579} INFO - at org.apache.spark.deploy.SparkSubmit.main(SparkSubmit.scala)
[2025-08-31T05:06:55.630+0000] {taskinstance.py:1935} ERROR - Task failed with exception
Traceback (most recent call last):
  File "/home/airflow/.local/lib/python3.10/site-packages/airflow/providers/apache/spark/operators/spark_submit.py", line 174, in execute
    self._hook.submit(self.application)
  File "/home/airflow/.local/lib/python3.10/site-packages/airflow/providers/apache/spark/hooks/spark_submit.py", line 505, in submit
    raise AirflowException(
airflow.exceptions.AirflowException: Cannot execute: spark-submit --master yarn --jars /opt/spark/external-jars/apache-spark-sql-connector.jar --name arrow-spark jobs/python/wordcountjob.py. Error code is: 1.
[2025-08-31T05:06:55.665+0000] {taskinstance.py:1398} INFO - Marking task as FAILED. dag_id=sparking_flow, task_id=python_job, execution_date=20250830T140000, start_date=20250831T050641, end_date=20250831T050655
[2025-08-31T05:06:55.776+0000] {standard_task_runner.py:104} ERROR - Failed to execute job 24 for task python_job (Cannot execute: spark-submit --master yarn --jars /opt/spark/external-jars/apache-spark-sql-connector.jar --name arrow-spark jobs/python/wordcountjob.py. Error code is: 1.; 346)
[2025-08-31T05:06:55.822+0000] {local_task_job_runner.py:228} INFO - Task exited with return code 1
[2025-08-31T05:06:55.941+0000] {taskinstance.py:2776} INFO - 0 downstream tasks scheduled from follow-on schedule check
[2025-08-31T12:53:21.793+0000] {taskinstance.py:1157} INFO - Dependencies all met for dep_context=non-requeueable deps ti=<TaskInstance: sparking_flow.python_job scheduled__2025-08-30T14:00:00+00:00 [queued]>
[2025-08-31T12:53:21.806+0000] {taskinstance.py:1157} INFO - Dependencies all met for dep_context=requeueable deps ti=<TaskInstance: sparking_flow.python_job scheduled__2025-08-30T14:00:00+00:00 [queued]>
[2025-08-31T12:53:21.811+0000] {taskinstance.py:1359} INFO - Starting attempt 1 of 1
[2025-08-31T12:53:21.855+0000] {taskinstance.py:1380} INFO - Executing <Task(SparkSubmitOperator): python_job> on 2025-08-30 14:00:00+00:00
[2025-08-31T12:53:21.864+0000] {standard_task_runner.py:57} INFO - Started process 405 to run task
[2025-08-31T12:53:21.879+0000] {standard_task_runner.py:84} INFO - Running: ['***', 'tasks', 'run', 'sparking_flow', 'python_job', 'scheduled__2025-08-30T14:00:00+00:00', '--job-id', '29', '--raw', '--subdir', 'DAGS_FOLDER/spark_***.py', '--cfg-path', '/tmp/tmpqje1vjp8']
[2025-08-31T12:53:21.893+0000] {standard_task_runner.py:85} INFO - Job 29: Subtask python_job
[2025-08-31T12:53:22.315+0000] {task_command.py:415} INFO - Running <TaskInstance: sparking_flow.python_job scheduled__2025-08-30T14:00:00+00:00 [running]> on host f7da00c682c4
[2025-08-31T12:53:22.823+0000] {taskinstance.py:1660} INFO - Exporting env vars: AIRFLOW_CTX_DAG_OWNER='Kudzaishe Manyanya' AIRFLOW_CTX_DAG_ID='sparking_flow' AIRFLOW_CTX_TASK_ID='python_job' AIRFLOW_CTX_EXECUTION_DATE='2025-08-30T14:00:00+00:00' AIRFLOW_CTX_TRY_NUMBER='1' AIRFLOW_CTX_DAG_RUN_ID='scheduled__2025-08-30T14:00:00+00:00'
[2025-08-31T12:53:23.037+0000] {base.py:73} INFO - Using connection ID 'spark-conn' for task execution.
[2025-08-31T12:53:23.073+0000] {spark_submit.py:403} INFO - Spark-Submit cmd: spark-submit --master spark://spark-master:7077 --jars /opt/spark/external-jars/apache-spark-sql-connector.jar --name arrow-spark --deploy-mode client jobs/python/wordcountjob.py
[2025-08-31T12:53:25.974+0000] {spark_submit.py:579} INFO - WARNING: Using incubator modules: jdk.incubator.vector
[2025-08-31T12:53:42.937+0000] {spark_submit.py:579} INFO - 25/08/31 12:53:42 WARN NativeCodeLoader: Unable to load native-hadoop library for your platform... using builtin-java classes where applicable
[2025-08-31T12:54:11.176+0000] {job.py:219} ERROR - Job heartbeat got an exception
Traceback (most recent call last):
  File "/home/airflow/.local/lib/python3.10/site-packages/sqlalchemy/engine/base.py", line 3371, in _wrap_pool_connect
    return fn()
  File "/home/airflow/.local/lib/python3.10/site-packages/sqlalchemy/pool/base.py", line 327, in connect
    return _ConnectionFairy._checkout(self)
  File "/home/airflow/.local/lib/python3.10/site-packages/sqlalchemy/pool/base.py", line 894, in _checkout
    fairy = _ConnectionRecord.checkout(pool)
  File "/home/airflow/.local/lib/python3.10/site-packages/sqlalchemy/pool/base.py", line 493, in checkout
    rec = pool._do_get()
  File "/home/airflow/.local/lib/python3.10/site-packages/sqlalchemy/pool/impl.py", line 256, in _do_get
    return self._create_connection()
  File "/home/airflow/.local/lib/python3.10/site-packages/sqlalchemy/pool/base.py", line 273, in _create_connection
    return _ConnectionRecord(self)
  File "/home/airflow/.local/lib/python3.10/site-packages/sqlalchemy/pool/base.py", line 388, in __init__
    self.__connect()
  File "/home/airflow/.local/lib/python3.10/site-packages/sqlalchemy/pool/base.py", line 690, in __connect
    with util.safe_reraise():
  File "/home/airflow/.local/lib/python3.10/site-packages/sqlalchemy/util/langhelpers.py", line 70, in __exit__
    compat.raise_(
  File "/home/airflow/.local/lib/python3.10/site-packages/sqlalchemy/util/compat.py", line 211, in raise_
    raise exception
  File "/home/airflow/.local/lib/python3.10/site-packages/sqlalchemy/pool/base.py", line 686, in __connect
    self.dbapi_connection = connection = pool._invoke_creator(self)
  File "/home/airflow/.local/lib/python3.10/site-packages/sqlalchemy/engine/create.py", line 574, in connect
    return dialect.connect(*cargs, **cparams)
  File "/home/airflow/.local/lib/python3.10/site-packages/sqlalchemy/engine/default.py", line 598, in connect
    return self.dbapi.connect(*cargs, **cparams)
  File "/home/airflow/.local/lib/python3.10/site-packages/psycopg2/__init__.py", line 122, in connect
    conn = _connect(dsn, connection_factory=connection_factory, **kwasync)
psycopg2.OperationalError: could not translate host name "postgres" to address: Temporary failure in name resolution


The above exception was the direct cause of the following exception:

Traceback (most recent call last):
  File "/home/airflow/.local/lib/python3.10/site-packages/airflow/jobs/job.py", line 190, in heartbeat
    session.merge(self)
  File "/home/airflow/.local/lib/python3.10/site-packages/sqlalchemy/orm/session.py", line 3056, in merge
    return self._merge(
  File "/home/airflow/.local/lib/python3.10/site-packages/sqlalchemy/orm/session.py", line 3136, in _merge
    merged = self.get(
  File "/home/airflow/.local/lib/python3.10/site-packages/sqlalchemy/orm/session.py", line 2853, in get
    return self._get_impl(
  File "/home/airflow/.local/lib/python3.10/site-packages/sqlalchemy/orm/session.py", line 2975, in _get_impl
    return db_load_fn(
  File "/home/airflow/.local/lib/python3.10/site-packages/sqlalchemy/orm/loading.py", line 530, in load_on_pk_identity
    session.execute(
  File "/home/airflow/.local/lib/python3.10/site-packages/sqlalchemy/orm/session.py", line 1716, in execute
    conn = self._connection_for_bind(bind)
  File "/home/airflow/.local/lib/python3.10/site-packages/sqlalchemy/orm/session.py", line 1555, in _connection_for_bind
    return self._transaction._connection_for_bind(
  File "/home/airflow/.local/lib/python3.10/site-packages/sqlalchemy/orm/session.py", line 750, in _connection_for_bind
    conn = bind.connect()
  File "/home/airflow/.local/lib/python3.10/site-packages/sqlalchemy/future/engine.py", line 406, in connect
    return super(Engine, self).connect()
  File "/home/airflow/.local/lib/python3.10/site-packages/sqlalchemy/engine/base.py", line 3325, in connect
    return self._connection_cls(self, close_with_result=close_with_result)
  File "/home/airflow/.local/lib/python3.10/site-packages/sqlalchemy/engine/base.py", line 96, in __init__
    else engine.raw_connection()
  File "/home/airflow/.local/lib/python3.10/site-packages/sqlalchemy/engine/base.py", line 3404, in raw_connection
    return self._wrap_pool_connect(self.pool.connect, _connection)
  File "/home/airflow/.local/lib/python3.10/site-packages/sqlalchemy/engine/base.py", line 3374, in _wrap_pool_connect
    Connection._handle_dbapi_exception_noconnection(
  File "/home/airflow/.local/lib/python3.10/site-packages/sqlalchemy/engine/base.py", line 2208, in _handle_dbapi_exception_noconnection
    util.raise_(
  File "/home/airflow/.local/lib/python3.10/site-packages/sqlalchemy/util/compat.py", line 211, in raise_
    raise exception
  File "/home/airflow/.local/lib/python3.10/site-packages/sqlalchemy/engine/base.py", line 3371, in _wrap_pool_connect
    return fn()
  File "/home/airflow/.local/lib/python3.10/site-packages/sqlalchemy/pool/base.py", line 327, in connect
    return _ConnectionFairy._checkout(self)
  File "/home/airflow/.local/lib/python3.10/site-packages/sqlalchemy/pool/base.py", line 894, in _checkout
    fairy = _ConnectionRecord.checkout(pool)
  File "/home/airflow/.local/lib/python3.10/site-packages/sqlalchemy/pool/base.py", line 493, in checkout
    rec = pool._do_get()
  File "/home/airflow/.local/lib/python3.10/site-packages/sqlalchemy/pool/impl.py", line 256, in _do_get
    return self._create_connection()
  File "/home/airflow/.local/lib/python3.10/site-packages/sqlalchemy/pool/base.py", line 273, in _create_connection
    return _ConnectionRecord(self)
  File "/home/airflow/.local/lib/python3.10/site-packages/sqlalchemy/pool/base.py", line 388, in __init__
    self.__connect()
  File "/home/airflow/.local/lib/python3.10/site-packages/sqlalchemy/pool/base.py", line 690, in __connect
    with util.safe_reraise():
  File "/home/airflow/.local/lib/python3.10/site-packages/sqlalchemy/util/langhelpers.py", line 70, in __exit__
    compat.raise_(
  File "/home/airflow/.local/lib/python3.10/site-packages/sqlalchemy/util/compat.py", line 211, in raise_
    raise exception
  File "/home/airflow/.local/lib/python3.10/site-packages/sqlalchemy/pool/base.py", line 686, in __connect
    self.dbapi_connection = connection = pool._invoke_creator(self)
  File "/home/airflow/.local/lib/python3.10/site-packages/sqlalchemy/engine/create.py", line 574, in connect
    return dialect.connect(*cargs, **cparams)
  File "/home/airflow/.local/lib/python3.10/site-packages/sqlalchemy/engine/default.py", line 598, in connect
    return self.dbapi.connect(*cargs, **cparams)
  File "/home/airflow/.local/lib/python3.10/site-packages/psycopg2/__init__.py", line 122, in connect
    conn = _connect(dsn, connection_factory=connection_factory, **kwasync)
sqlalchemy.exc.OperationalError: (psycopg2.OperationalError) could not translate host name "postgres" to address: Temporary failure in name resolution

(Background on this error at: https://sqlalche.me/e/14/e3q8)
[2025-08-31T12:56:18.286+0000] {spark_submit.py:579} INFO - Using Spark's default log4j profile: org/apache/spark/log4j2-defaults.properties
[2025-08-31T12:56:49.451+0000] {job.py:219} ERROR - Job heartbeat got an exception
Traceback (most recent call last):
  File "/home/airflow/.local/lib/python3.10/site-packages/sqlalchemy/engine/base.py", line 3371, in _wrap_pool_connect
    return fn()
  File "/home/airflow/.local/lib/python3.10/site-packages/sqlalchemy/pool/base.py", line 327, in connect
    return _ConnectionFairy._checkout(self)
  File "/home/airflow/.local/lib/python3.10/site-packages/sqlalchemy/pool/base.py", line 894, in _checkout
    fairy = _ConnectionRecord.checkout(pool)
  File "/home/airflow/.local/lib/python3.10/site-packages/sqlalchemy/pool/base.py", line 493, in checkout
    rec = pool._do_get()
  File "/home/airflow/.local/lib/python3.10/site-packages/sqlalchemy/pool/impl.py", line 256, in _do_get
    return self._create_connection()
  File "/home/airflow/.local/lib/python3.10/site-packages/sqlalchemy/pool/base.py", line 273, in _create_connection
    return _ConnectionRecord(self)
  File "/home/airflow/.local/lib/python3.10/site-packages/sqlalchemy/pool/base.py", line 388, in __init__
    self.__connect()
  File "/home/airflow/.local/lib/python3.10/site-packages/sqlalchemy/pool/base.py", line 690, in __connect
    with util.safe_reraise():
  File "/home/airflow/.local/lib/python3.10/site-packages/sqlalchemy/util/langhelpers.py", line 70, in __exit__
    compat.raise_(
  File "/home/airflow/.local/lib/python3.10/site-packages/sqlalchemy/util/compat.py", line 211, in raise_
    raise exception
  File "/home/airflow/.local/lib/python3.10/site-packages/sqlalchemy/pool/base.py", line 686, in __connect
    self.dbapi_connection = connection = pool._invoke_creator(self)
  File "/home/airflow/.local/lib/python3.10/site-packages/sqlalchemy/engine/create.py", line 574, in connect
    return dialect.connect(*cargs, **cparams)
  File "/home/airflow/.local/lib/python3.10/site-packages/sqlalchemy/engine/default.py", line 598, in connect
    return self.dbapi.connect(*cargs, **cparams)
  File "/home/airflow/.local/lib/python3.10/site-packages/psycopg2/__init__.py", line 122, in connect
    conn = _connect(dsn, connection_factory=connection_factory, **kwasync)
psycopg2.OperationalError: could not translate host name "postgres" to address: Temporary failure in name resolution


The above exception was the direct cause of the following exception:

Traceback (most recent call last):
  File "/home/airflow/.local/lib/python3.10/site-packages/airflow/jobs/job.py", line 190, in heartbeat
    session.merge(self)
  File "/home/airflow/.local/lib/python3.10/site-packages/sqlalchemy/orm/session.py", line 3056, in merge
    return self._merge(
  File "/home/airflow/.local/lib/python3.10/site-packages/sqlalchemy/orm/session.py", line 3136, in _merge
    merged = self.get(
  File "/home/airflow/.local/lib/python3.10/site-packages/sqlalchemy/orm/session.py", line 2853, in get
    return self._get_impl(
  File "/home/airflow/.local/lib/python3.10/site-packages/sqlalchemy/orm/session.py", line 2975, in _get_impl
    return db_load_fn(
  File "/home/airflow/.local/lib/python3.10/site-packages/sqlalchemy/orm/loading.py", line 530, in load_on_pk_identity
    session.execute(
  File "/home/airflow/.local/lib/python3.10/site-packages/sqlalchemy/orm/session.py", line 1716, in execute
    conn = self._connection_for_bind(bind)
  File "/home/airflow/.local/lib/python3.10/site-packages/sqlalchemy/orm/session.py", line 1555, in _connection_for_bind
    return self._transaction._connection_for_bind(
  File "/home/airflow/.local/lib/python3.10/site-packages/sqlalchemy/orm/session.py", line 750, in _connection_for_bind
    conn = bind.connect()
  File "/home/airflow/.local/lib/python3.10/site-packages/sqlalchemy/future/engine.py", line 406, in connect
    return super(Engine, self).connect()
  File "/home/airflow/.local/lib/python3.10/site-packages/sqlalchemy/engine/base.py", line 3325, in connect
    return self._connection_cls(self, close_with_result=close_with_result)
  File "/home/airflow/.local/lib/python3.10/site-packages/sqlalchemy/engine/base.py", line 96, in __init__
    else engine.raw_connection()
  File "/home/airflow/.local/lib/python3.10/site-packages/sqlalchemy/engine/base.py", line 3404, in raw_connection
    return self._wrap_pool_connect(self.pool.connect, _connection)
  File "/home/airflow/.local/lib/python3.10/site-packages/sqlalchemy/engine/base.py", line 3374, in _wrap_pool_connect
    Connection._handle_dbapi_exception_noconnection(
  File "/home/airflow/.local/lib/python3.10/site-packages/sqlalchemy/engine/base.py", line 2208, in _handle_dbapi_exception_noconnection
    util.raise_(
  File "/home/airflow/.local/lib/python3.10/site-packages/sqlalchemy/util/compat.py", line 211, in raise_
    raise exception
  File "/home/airflow/.local/lib/python3.10/site-packages/sqlalchemy/engine/base.py", line 3371, in _wrap_pool_connect
    return fn()
  File "/home/airflow/.local/lib/python3.10/site-packages/sqlalchemy/pool/base.py", line 327, in connect
    return _ConnectionFairy._checkout(self)
  File "/home/airflow/.local/lib/python3.10/site-packages/sqlalchemy/pool/base.py", line 894, in _checkout
    fairy = _ConnectionRecord.checkout(pool)
  File "/home/airflow/.local/lib/python3.10/site-packages/sqlalchemy/pool/base.py", line 493, in checkout
    rec = pool._do_get()
  File "/home/airflow/.local/lib/python3.10/site-packages/sqlalchemy/pool/impl.py", line 256, in _do_get
    return self._create_connection()
  File "/home/airflow/.local/lib/python3.10/site-packages/sqlalchemy/pool/base.py", line 273, in _create_connection
    return _ConnectionRecord(self)
  File "/home/airflow/.local/lib/python3.10/site-packages/sqlalchemy/pool/base.py", line 388, in __init__
    self.__connect()
  File "/home/airflow/.local/lib/python3.10/site-packages/sqlalchemy/pool/base.py", line 690, in __connect
    with util.safe_reraise():
  File "/home/airflow/.local/lib/python3.10/site-packages/sqlalchemy/util/langhelpers.py", line 70, in __exit__
    compat.raise_(
  File "/home/airflow/.local/lib/python3.10/site-packages/sqlalchemy/util/compat.py", line 211, in raise_
    raise exception
  File "/home/airflow/.local/lib/python3.10/site-packages/sqlalchemy/pool/base.py", line 686, in __connect
    self.dbapi_connection = connection = pool._invoke_creator(self)
  File "/home/airflow/.local/lib/python3.10/site-packages/sqlalchemy/engine/create.py", line 574, in connect
    return dialect.connect(*cargs, **cparams)
  File "/home/airflow/.local/lib/python3.10/site-packages/sqlalchemy/engine/default.py", line 598, in connect
    return self.dbapi.connect(*cargs, **cparams)
  File "/home/airflow/.local/lib/python3.10/site-packages/psycopg2/__init__.py", line 122, in connect
    conn = _connect(dsn, connection_factory=connection_factory, **kwasync)
sqlalchemy.exc.OperationalError: (psycopg2.OperationalError) could not translate host name "postgres" to address: Temporary failure in name resolution

(Background on this error at: https://sqlalche.me/e/14/e3q8)
[2025-08-31T12:57:23.826+0000] {spark_submit.py:579} INFO - 25/08/31 12:57:21 INFO SparkContext: Running Spark version 4.0.0
[2025-08-31T13:01:34.048+0000] {spark_submit.py:579} INFO - 25/08/31 13:01:34 INFO SparkContext: OS info Linux, 6.6.87.2-microsoft-standard-WSL2, amd64
[2025-08-31T13:01:34.075+0000] {spark_submit.py:579} INFO - 25/08/31 13:01:34 INFO SparkContext: Java version 17.0.15
[2025-08-31T13:00:00.498+0000] {job.py:219} ERROR - Job heartbeat got an exception
Traceback (most recent call last):
  File "/home/airflow/.local/lib/python3.10/site-packages/sqlalchemy/engine/base.py", line 3371, in _wrap_pool_connect
    return fn()
  File "/home/airflow/.local/lib/python3.10/site-packages/sqlalchemy/pool/base.py", line 327, in connect
    return _ConnectionFairy._checkout(self)
  File "/home/airflow/.local/lib/python3.10/site-packages/sqlalchemy/pool/base.py", line 894, in _checkout
    fairy = _ConnectionRecord.checkout(pool)
  File "/home/airflow/.local/lib/python3.10/site-packages/sqlalchemy/pool/base.py", line 493, in checkout
    rec = pool._do_get()
  File "/home/airflow/.local/lib/python3.10/site-packages/sqlalchemy/pool/impl.py", line 256, in _do_get
    return self._create_connection()
  File "/home/airflow/.local/lib/python3.10/site-packages/sqlalchemy/pool/base.py", line 273, in _create_connection
    return _ConnectionRecord(self)
  File "/home/airflow/.local/lib/python3.10/site-packages/sqlalchemy/pool/base.py", line 388, in __init__
    self.__connect()
  File "/home/airflow/.local/lib/python3.10/site-packages/sqlalchemy/pool/base.py", line 690, in __connect
    with util.safe_reraise():
  File "/home/airflow/.local/lib/python3.10/site-packages/sqlalchemy/util/langhelpers.py", line 70, in __exit__
    compat.raise_(
  File "/home/airflow/.local/lib/python3.10/site-packages/sqlalchemy/util/compat.py", line 211, in raise_
    raise exception
  File "/home/airflow/.local/lib/python3.10/site-packages/sqlalchemy/pool/base.py", line 686, in __connect
    self.dbapi_connection = connection = pool._invoke_creator(self)
  File "/home/airflow/.local/lib/python3.10/site-packages/sqlalchemy/engine/create.py", line 574, in connect
    return dialect.connect(*cargs, **cparams)
  File "/home/airflow/.local/lib/python3.10/site-packages/sqlalchemy/engine/default.py", line 598, in connect
    return self.dbapi.connect(*cargs, **cparams)
  File "/home/airflow/.local/lib/python3.10/site-packages/psycopg2/__init__.py", line 122, in connect
    conn = _connect(dsn, connection_factory=connection_factory, **kwasync)
psycopg2.OperationalError: could not translate host name "postgres" to address: Temporary failure in name resolution


The above exception was the direct cause of the following exception:

Traceback (most recent call last):
  File "/home/airflow/.local/lib/python3.10/site-packages/airflow/jobs/job.py", line 190, in heartbeat
    session.merge(self)
  File "/home/airflow/.local/lib/python3.10/site-packages/sqlalchemy/orm/session.py", line 3056, in merge
    return self._merge(
  File "/home/airflow/.local/lib/python3.10/site-packages/sqlalchemy/orm/session.py", line 3136, in _merge
    merged = self.get(
  File "/home/airflow/.local/lib/python3.10/site-packages/sqlalchemy/orm/session.py", line 2853, in get
    return self._get_impl(
  File "/home/airflow/.local/lib/python3.10/site-packages/sqlalchemy/orm/session.py", line 2975, in _get_impl
    return db_load_fn(
  File "/home/airflow/.local/lib/python3.10/site-packages/sqlalchemy/orm/loading.py", line 530, in load_on_pk_identity
    session.execute(
  File "/home/airflow/.local/lib/python3.10/site-packages/sqlalchemy/orm/session.py", line 1716, in execute
    conn = self._connection_for_bind(bind)
  File "/home/airflow/.local/lib/python3.10/site-packages/sqlalchemy/orm/session.py", line 1555, in _connection_for_bind
    return self._transaction._connection_for_bind(
  File "/home/airflow/.local/lib/python3.10/site-packages/sqlalchemy/orm/session.py", line 750, in _connection_for_bind
    conn = bind.connect()
  File "/home/airflow/.local/lib/python3.10/site-packages/sqlalchemy/future/engine.py", line 406, in connect
    return super(Engine, self).connect()
  File "/home/airflow/.local/lib/python3.10/site-packages/sqlalchemy/engine/base.py", line 3325, in connect
    return self._connection_cls(self, close_with_result=close_with_result)
  File "/home/airflow/.local/lib/python3.10/site-packages/sqlalchemy/engine/base.py", line 96, in __init__
    else engine.raw_connection()
  File "/home/airflow/.local/lib/python3.10/site-packages/sqlalchemy/engine/base.py", line 3404, in raw_connection
    return self._wrap_pool_connect(self.pool.connect, _connection)
  File "/home/airflow/.local/lib/python3.10/site-packages/sqlalchemy/engine/base.py", line 3374, in _wrap_pool_connect
    Connection._handle_dbapi_exception_noconnection(
  File "/home/airflow/.local/lib/python3.10/site-packages/sqlalchemy/engine/base.py", line 2208, in _handle_dbapi_exception_noconnection
    util.raise_(
  File "/home/airflow/.local/lib/python3.10/site-packages/sqlalchemy/util/compat.py", line 211, in raise_
    raise exception
  File "/home/airflow/.local/lib/python3.10/site-packages/sqlalchemy/engine/base.py", line 3371, in _wrap_pool_connect
    return fn()
  File "/home/airflow/.local/lib/python3.10/site-packages/sqlalchemy/pool/base.py", line 327, in connect
    return _ConnectionFairy._checkout(self)
  File "/home/airflow/.local/lib/python3.10/site-packages/sqlalchemy/pool/base.py", line 894, in _checkout
    fairy = _ConnectionRecord.checkout(pool)
  File "/home/airflow/.local/lib/python3.10/site-packages/sqlalchemy/pool/base.py", line 493, in checkout
    rec = pool._do_get()
  File "/home/airflow/.local/lib/python3.10/site-packages/sqlalchemy/pool/impl.py", line 256, in _do_get
    return self._create_connection()
  File "/home/airflow/.local/lib/python3.10/site-packages/sqlalchemy/pool/base.py", line 273, in _create_connection
    return _ConnectionRecord(self)
  File "/home/airflow/.local/lib/python3.10/site-packages/sqlalchemy/pool/base.py", line 388, in __init__
    self.__connect()
  File "/home/airflow/.local/lib/python3.10/site-packages/sqlalchemy/pool/base.py", line 690, in __connect
    with util.safe_reraise():
  File "/home/airflow/.local/lib/python3.10/site-packages/sqlalchemy/util/langhelpers.py", line 70, in __exit__
    compat.raise_(
  File "/home/airflow/.local/lib/python3.10/site-packages/sqlalchemy/util/compat.py", line 211, in raise_
    raise exception
  File "/home/airflow/.local/lib/python3.10/site-packages/sqlalchemy/pool/base.py", line 686, in __connect
    self.dbapi_connection = connection = pool._invoke_creator(self)
  File "/home/airflow/.local/lib/python3.10/site-packages/sqlalchemy/engine/create.py", line 574, in connect
    return dialect.connect(*cargs, **cparams)
  File "/home/airflow/.local/lib/python3.10/site-packages/sqlalchemy/engine/default.py", line 598, in connect
    return self.dbapi.connect(*cargs, **cparams)
  File "/home/airflow/.local/lib/python3.10/site-packages/psycopg2/__init__.py", line 122, in connect
    conn = _connect(dsn, connection_factory=connection_factory, **kwasync)
sqlalchemy.exc.OperationalError: (psycopg2.OperationalError) could not translate host name "postgres" to address: Temporary failure in name resolution

(Background on this error at: https://sqlalche.me/e/14/e3q8)
[2025-08-31T13:01:34.197+0000] {local_task_job_runner.py:205} ERROR - Heartbeat time limit exceeded!
[2025-08-31T13:01:34.523+0000] {process_utils.py:131} INFO - Sending 15 to group 405. PIDs of all processes in the group: [465, 1424, 405]
[2025-08-31T13:01:34.575+0000] {process_utils.py:86} INFO - Sending the signal 15 to group 405
[2025-08-31T13:01:34.611+0000] {taskinstance.py:1630} ERROR - Received SIGTERM. Terminating subprocesses.
[2025-08-31T13:01:34.646+0000] {process_utils.py:79} INFO - Process psutil.Process(pid=1424, status='terminated', started='12:53:45') (1424) terminated with exit code None
[2025-08-31T13:01:34.680+0000] {spark_submit.py:705} INFO - Sending kill signal to spark-submit
[2025-08-31T13:01:35.510+0000] {taskinstance.py:1935} ERROR - Task failed with exception
Traceback (most recent call last):
  File "/home/airflow/.local/lib/python3.10/site-packages/airflow/providers/apache/spark/operators/spark_submit.py", line 174, in execute
    self._hook.submit(self.application)
  File "/home/airflow/.local/lib/python3.10/site-packages/airflow/providers/apache/spark/hooks/spark_submit.py", line 493, in submit
    self._process_spark_submit_log(iter(self._submit_sp.stdout))  # type: ignore
  File "/home/airflow/.local/lib/python3.10/site-packages/airflow/providers/apache/spark/hooks/spark_submit.py", line 542, in _process_spark_submit_log
    for line in itr:
  File "/home/airflow/.local/lib/python3.10/site-packages/airflow/models/taskinstance.py", line 1632, in signal_handler
    raise AirflowException("Task received SIGTERM signal")
airflow.exceptions.AirflowException: Task received SIGTERM signal
[2025-08-31T13:01:35.854+0000] {taskinstance.py:1398} INFO - Marking task as FAILED. dag_id=sparking_flow, task_id=python_job, execution_date=20250830T140000, start_date=20250831T125321, end_date=20250831T130135
[2025-08-31T13:01:36.145+0000] {standard_task_runner.py:104} ERROR - Failed to execute job 29 for task python_job (Task received SIGTERM signal; 405)
[2025-08-31T13:01:36.243+0000] {process_utils.py:79} INFO - Process psutil.Process(pid=465, status='terminated', started='12:53:22') (465) terminated with exit code None
[2025-08-31T13:01:36.247+0000] {process_utils.py:79} INFO - Process psutil.Process(pid=405, status='terminated', exitcode=1, started='12:53:21') (405) terminated with exit code 1
